Workbook

Sheet FinalTable
A1: Top 10 H. paniculata
A2: Rank (1 is best) | B2: Trademark.Cultivar | C2: Color | D2: Bloom Range | E2: Height (ft) | F2: Spread (ft) | G2: Sun | H2: Source | I2: Note
A3: 1 | B3: Pinky Winky | C3: Pink-white | D3: Jul - Sept | E3: 6 to 8 | F3: 5 to 6 | G3: Full sun to part shade | H3: https://www.missouribotanicalgarden.org
A4: 2 | B4: Quick Fire | C4: Pink | D4: Jul - Oct | E4: 6 to 8 | F4: 6 to 8 | G4: Sun to part shade | H4: https://www.petittigardencenter.com/quick-fire-a-panicle-hydrangea-variety-spotlight/ | I4: End bloom time wasn't available online; used our data for that
A5: 3 | B5: Dharuma | C5: White | D5: Jul - Sept | E5: 3 to 4 | F5: 3 to 4 | G5: Full sun to part shade | H5: https://www.northshoreplantclub.com/plant?id=7267
A6: 4 | B6: Green Spire | C6: Green-white | D6: Aug - Oct | E6: 6 to 10 | F6: 6 to 10 | G6: Full sun to part sun | H6: https://www.gardenia.net/plant/hydrangea-paniculata-greenspire | I6: Could not find a bloom time so used our own data for it
A7: 5 | B7: Kyushu | C7: White | D7: May - Oct | E7: 6 to 8 | F7: 6 to 8 | G7: Full sun to part shade | H7: https://www.chicagobotanic.org/plantcollections/plantfinder/hydrangea_paniculata_kyushu--kyushu_panicle_hydrangea and https://hydrangeasplus.com/products/hydrangea-paniculata-kyushu?srsltid=AfmBOoppDF-Qk1uw-TcabnNQSop8sVqaT7Z2uEnE51IyVpV1DF6uhEKi
A8: 6 | B8: Honey Comb | C8: White | D8: Jul - Oct | E8: 15 | F8: 7 | G8: Full sun to full shade | H8: http://plants.beechwood-gardens.com/12130013/Plant/16553/Honeycomb_Hydrangea/ | I8: Could not find exact bloom time, used our data
A9: 7 | B9: Brussels Lace | C9: White | D9: Jul - Oct | E9: 5 | F9: 6 | G9: Full sun to part shade | H9: https://www.chicagobotanic.org/plantcollections/plantfinder/hydrangea_paniculata_brussels_lace--brussels_lace_panicle_hydrangea
A10: 8 | B10: Pink Diamond | C10: Pink | D10: Jul - Sept | E10: 8 to 15 | F10: 8 to 15 | G10: Full sun to part shade | H10: https://www.missouribotanicalgarden.org
A11: 9 | B11: Great Star | C11: White | D11: Jul - Sept | E11: 6 to 7 | F11: 7 to 8 | G11: Full sun to part shade | H11: https://www.missouribotanicalgarden.org
A12: 10 | B12: Mega Pearl | C12: Pink-white | D12: Jul - Oct | E12: 6 to 8 | F12: 6 to 8 | G12: Full sun | H12: https://naturehills.com/products/hydrangea-mega-pearl?srsltid=AfmBOoqtkNbCaP9iB6-2A1Kswx4540onK_3L41O7YiUTRkcuVu7YItxr | I12: Could not find exact date so used our data
A14: Top 3 H. arborescens
A15: Rank (1 is best) | B15: Trademark.Cultivar | C15: Color | D15: Bloom Range | E15: Height (ft) | F15: Spread (ft) | G15: Sun | H15: Source | I15: Note
A16: 1 | B16: Haas Halo | C16: White | D16: Jun - July | E16: 7 | F16: 7 | G16: Full sun to full shade | H16: https://mtcubacenter.org/trials/wild-hydrangea-for-the-mid-atlantic-region/hydrangea-arborescens-haas-halo/
A17: 2 | B17: White Dome | C17: White | D17: Jun - Aug | E17: 3 to 5 | F17: 3 to 4 | G17: Part shade | H17: https://www.missouribotanicalgarden.org/PlantFinder/PlantFinderDetails.aspx?taxonid=264083&isprofile=0&
A18: 3 | B18: Incrediball | C18: White | D18: Jul - Aug | E18: 4 to 5 | F18: 4 to 5 | G18: Full sun to part sun | H18: https://www.thespruce.com/description-of-incrediball-hydrangeas-2132707 | I18: Could not find exact bloom time, used our data

Sheet TopVarieties
A1: Rank | B1: AvgTotal(LowerIsBetter) | C1: 2019_to_2021_TotalDayswInsectsRank | D1: 2019_to_2021_AvgSppRichnessRank | E1: TotalSppRichness/SeasonRank | F1: AvgInsectSppAbundanceRank | G1: shannon_index | H1: Trademark.Cultivar | I1: Species | J1: shannon_index (larger is better) | K1: Avg Insect Spp Abundance / plant / season | L1: Total Spp. Insect richness / season | M1: 2019_to_2021_AvgSppRichness | N1: 2019_to_2021_TotalDays_w_Insects | O1: Flower type | P1: Color | Q1: BloomStart | R1: BloomEnd | S1: Height (ft) | T1: Spread (ft) | U1: Sun | V1: Water | W1: Maintenance | X1: Source | Y1: Note
A2: 1 | B2: =SUM(C2:G2)/5 -> 3.2 | C2: 2 | D2: 3 | E2: 3 | F2: 6 | G2: 2 | H2: Pinky Winky | I2: Hydrangea paniculata | J2: 1.112 | K2: 40 | L2: 9 | M2: 3.7 | N2: 25 | O2: Lacy panicle | P2: Pink-white | Q2: 44013 | R2: 44075 | S2: 6 to 8 | T2: 5 to 6 | U2: Full sun to part shade | V2: Medium | W2: Medium | X2: https://www.missouribotanicalgarden.org
A3: 2 | B3: =SUM(C3:G3)/5 -> 3.4 | C3: 3 | D3: 3 | E3: 8 | F3: 1 | G3: 2 | H3: Green Spire | I3: Hydrangea paniculata | J3: 1.15 | K3: 80 | L3: 4 | M3: 3.52 | N3: 23 | O3: Lacy panicle | P3: Green-white | Q3: 44044 | R3: 44105 | S3: 6 to 10 | T3: 6 to 10 | U3: Full sun to part sun | V3: Medium | W3: Low | X3: https://www.gardenia.net/plant/hydrangea-paniculata-greenspire | Y3: Could not find a bloom time so used our own data for it
A4: 3 | B4: =SUM(C4:G4)/5 -> 4 | C4: 1 | D4: 3 | E4: 3 | F4: 11 | G4: 2 | H4: Quick Fire | I4: Hydrangea paniculata | J4: 1.423 | K4: 26 | L4: 9 | M4: 3.75 | N4: 33 | O4: Lacy panicle | P4: Pink | Q4: 44013 | R4: 44105 | S4: 6 to 8 | T4: 6 to 8 | U4: Sun to part shade | W4: N/A | X4: https://www.petittigardencenter.com/quick-fire-a-panicle-hydrangea-variety-spotlight/ | Y4: End bloom time wasn't available online; used our data for that
A5: 4 | B5: =SUM(C5:G5)/5 -> 4.2 | C5: 6 | D5: 3 | E5: 7 | F5: 3 | G5: 2 | H5: Kyushu | I5: Hydrangea paniculata | J5: 1.441 | K5: 54 | L5: 5 | M5: 3.52 | N5: 19 | O5: Lacy panicle | P5: White | Q5: 43952 | R5: 44105 | S5: 6 to 8 | T5: 6 to 8 | U5: Full sun to part shade | V5: Medium | W5: N/A | X5: https://www.chicagobotanic.org/plantcollections/plantfinder/hydrangea_paniculata_kyushu--kyushu_panicle_hydrangea and https://hydrangeasplus.com/products/hydrangea-paniculata-kyushu?srsltid=AfmBOoppDF-Qk1uw-TcabnNQSop8sVqaT7Z2uEnE51IyVpV1DF6uhEKi
A6: 5 | B6: =SUM(C6:G6)/2 -> 4.5 | C6: 6 | D6: 3 | E6: NA | F6: NA | G6: NA | H6: Late / Tardiva | I6: Hydrangea paniculata | J6: NA | M6: 3.56 | N6: 19 | O6: Lacy panicle | P6: White | Q6: 44013 | R6: 44075 | S6: 8 to 12 | T6: 7 to 10 | U6: Full sun to part shade | V6: Medium | W6: Medium | X6: https://www.missouribotanicalgarden.org/PlantFinder/PlantFinderDetails.aspx?kempercode=d360
A7: 6 | B7: =SUM(C7:G7)/5 -> 4.6 | C7: 6 | D7: 4 | E7: 7 | F7: 5 | G7: 1 | H7: Brussels Lace | I7: Hydrangea paniculata | J7: 1.58 | K7: 43 | L7: 5 | M7: 3.46 | N7: 19 | O7: Lacy panicle | P7: White | Q7: 44013 | R7: 44105 | S7: 5 | T7: 6 | U7: Full sun to part shade | V7: Medium high | W7: N/A | X7: https://www.chicagobotanic.org/plantcollections/plantfinder/hydrangea_paniculata_brussels_lace--brussels_lace_panicle_hydrangea
A8: 6 | B8: =SUM(C8:G8)/5 -> 4.6 | C8: 7 | D8: 5 | E8: 8 | F8: 2 | G8: 1 | H8: Pink Diamond | I8: Hydrangea paniculata | J8: 1.561 | K8: 66 | L8: 4 | M8: 2.9 | N8: 17 | O8: Lacy panicle | P8: Pink | Q8: 44013 | R8: 44075 | S8: 8 to 15 | T8: 8 to 15 | U8: Full sun to part shade | V8: Medium | W8: Medium | X8: https://www.missouribotanicalgarden.org
A9: 6 | B9: =SUM(C9:G9)/3 -> 4.6666667 | C9: NA | D9: NA | E9: 8 | F9: 3 | G9: 3 | H9: White Dome | I9: Hydrangea arborescens | J9: 0.753 | K9: 54 | L9: 4 | O9: Lacy | P9: White | Q9: 43983 | R9: 44044 | S9: 3 to 5 | T9: 3 to 4 | U9: Part shade | V9: Medium | W9: Low | X9: https://www.missouribotanicalgarden.org/PlantFinder/PlantFinderDetails.aspx?taxonid=264083&isprofile=0&
A10: 7 | B10: =SUM(C10:G10)/5 -> 4.8 | C10: 11 | D10: 1 | E10: 4 | F10: 5 | G10: 3 | H10: Dharuma | I10: Hydrangea paniculata | J10: =0.807 -> 0.807 | K10: 43 | L10: 8 | M10: 7.17 | N10: 12 | O10: Lacy panicle | P10: White | Q10: 44013 | R10: 44075 | S10: 3 to 4 | T10: 3 to 4 | U10: Full sun to part shade | V10: Medium | W10: N/A | X10: https://www.northshoreplantclub.com/plant?id=7267
A11: 8 | B11: =SUM(C11:G11)/5 -> 5.2 | C11: 8 | D11: 3 | E11: 8 | F11: 4 | G11: 3 | H11: Honey Comb | I11: Hydrangea paniculata | J11: 0.979 | K11: 50 | L11: 4 | M11: 3.76 | N11: 16 | O11: Lacy panicle | P11: White | Q11: 44013 | R11: 44105 | S11: 15 | T11: 7 | U11: Full sun to full shade | V11: N/A | W11: Medium | X11: http://plants.beechwood-gardens.com/12130013/Plant/16553/Honeycomb_Hydrangea/ | Y11: Could not find exact bloom time, used our data
A12: 9 | B12: =SUM(C12:G12)/3 -> 5.3333333 | C12: NA | D12: NA | E12: 5 | F12: 8 | G12: 3 | H12: Haas Halo | I12: Hydrangea arborescens | J12: 0.596 | K12: 36 | L12: 7 | O12: Lacy | P12: White | Q12: 43983 | R12: 44013 | S12: 7 | T12: 7 | U12: Full sun to full shade | V12: N/A | W12: N/A | X12: https://mtcubacenter.org/trials/wild-hydrangea-for-the-mid-atlantic-region/hydrangea-arborescens-haas-halo/
A13: 10 | B13: =SUM(C13:G13)/5 -> 5.6 | C13: 5 | D13: 4 | E13: 5 | F13: 12 | G13: 2 | H13: Great Star | I13: Hydrangea paniculata | J13: 1.15 | K13: 25.5 | L13: 7 | M13: 3.08 | N13: 20 | O13: Lacy panicle | P13: White | Q13: 44013 | R13: 44075 | S13: 6 to 7 | T13: 7 to 8 | U13: Full sun to part shade | V13: Medium | W13: Medium | X13: https://www.missouribotanicalgarden.org
A14: 11 | B14: =SUM(C14:G14)/5 -> 5.8 | C14: 9 | D14: 5 | E14: 4 | F14: 9 | G14: 2 | H14: Mega Pearl | I14: Hydrangea paniculata | J14: 1.156 | K14: 35 | L14: 8 | M14: 2.05 | N14: 14 | O14: Mop-like panicle | P14: Pink-white | Q14: 44013 | R14: 44105 | S14: 6 to 8 | T14: 6 to 8 | U14: Full sun | V14: Medium | W14: N/A | X14: https://naturehills.com/products/hydrangea-mega-pearl?srsltid=AfmBOoqtkNbCaP9iB6-2A1Kswx4540onK_3L41O7YiUTRkcuVu7YItxr | Y14: Could not find exact date so used our data
A15: 12 | B15: =SUM(C15:G15)/5 -> 6.4 | C15: 15 | D15: 6 | E15: 2 | F15: 7 | G15: 2 | H15: Strawberry Sundae | I15: Hydrangea paniculata | J15: 1.17 | K15: 37 | L15: 11 | M15: 1 | N15: 2 | O15: Mop-like panicle | P15: Pink-white | Q15: 44013 | R15: 44075 | S15: 4 to 5 | T15: 3 to 4 | U15: Full sun to part sun | V15: Medium | W15: N/A | X15: https://www.southernliving.com/garden/flowers/strawberry-sundae-hydrangea
A16: 13 | B16: =SUM(C16:G16)/5 -> 6.6 | C16: 6 | D16: 3 | E16: 8 | F16: 14 | G16: 2 | H16: Floribunda | I16: Hydrangea paniculata | J16: 1.03 | K16: 19 | L16: 4 | M16: 4 | N16: 19 | O16: Lacy panicle | P16: White | Q16: 44044 | R16: 44105 | S16: 8 to 13 | T16: 5 to 8 | U16: Full sun to part shade | V16: Moist but well-drained | W16: N/A | X16: https://www.rhs.org.uk/plants/98580/hydrangea-paniculata-floribunda/details | Y16: Could not find a bloom time so used our own data for it
A17: 14 | B17: =SUM(C17:G17)/5 -> 6.8 | C17: 4 | D17: 2 | E17: 9 | F17: 16 | G17: 3 | H17: Big Ben | I17: Hydrangea paniculata | J17: 0.928 | K17: 15 | L17: 1 | M17: 5.34 | N17: 22 | O17: Lacy panicle | P17: White | Q17: 44044 | R17: 44136 | S17: 19 | T17: 10 | U17: Full sun to full shade | V17: Medium | W17: Medium | X17: http://plants.beechwood-gardens.com/12130013/Plant/11837/Big_Ben_Hydrangea/
A18: 15 | B18: =SUM(C18:G18)/5 -> 7 | C18: 14 | D18: 6 | E18: 1 | F18: 12 | G18: 2 | H18: Fire Light | I18: Hydrangea paniculata | J18: 1.113 | K18: 25 | L18: 15 | M18: 1.33 | N18: 4 | O18: Mop-like panicle | P18: Pink | Q18: 44014 | R18: 44075 | S18: 6 to 8 | T18: 6 to 8 | U18: Sun to part shade | V18: N/A | W18: N/A | X18: https://www.whiteflowerfarm.com/63163-product.html
A19: 15 | B19: =SUM(C19:G19)/5 -> 7 | C19: 12 | D19: 5 | E19: 6 | F19: 10 | G19: 2 | H19: Ruby / Angel's Blush | I19: Hydrangea paniculata | J19: 1.214 | K19: 31.5 | L19: 6 | M19: 2.27 | N19: 11 | O19: Mop-like panicle | P19: Pink | Q19: 44013 | R19: 44105 | S19: 8 to 12 | T19: 6 to 10 | U19: Full sun to part sun | V19: N/A | W19: N/A | X19: https://www.monrovia.com/angels-blush-hydrangea.html?srsltid=AfmBOorQcKnkdvItwFKmF1ruxmKdZTR2EsF7335iSOcWRE1LpMs9XAxD | Y19: Exact dates weren't available so used our data
A20: 16 | B20: =SUM(C20:G20)/5 -> 7.2 | C20: 11 | D20: 4 | E20: 6 | F20: 13 | G20: 2 | H20: Little Quick Fire | I20: Hydrangea paniculata | J20: 1.202 | K20: 20.5 | L20: 6 | M20: 3.39 | N20: 12 | O20: Lacy panicle | P20: Pink | Q20: 44013 | R20: 44105 | S20: 3 to 5 | T20: 3 to 5 | U20: Full sun to part sun | V20: Medium | W20: N/A | X20: https://hydrangea.com/products/little-quick-fire-panicle-hydrangea?srsltid=AfmBOooNVO-RW1s19arvwHK3wJkCyUnjN03YejaKTVPZG5GIOhFAuDJd
A21: 16 | B21: =SUM(C21:G21)/5 -> 7.2 | C21: 13 | D21: 5 | E21: 4 | F21: 11 | G21: 3 | H21: Phantom | I21: Hydrangea paniculata | J21: 0.9 | K21: 26.5 | L21: 8 | M21: 2 | N21: 8 | O21: Mop-like panicle | P21: White | Q21: 44013 | R21: 44105 | S21: 6 | T21: 6 | U21: Full sun to part shade | V21: Medium | W21: N/A | X21: https://www.chicagobotanic.org/plantcollections/plantfinder/hydrangea_paniculata_phantom--phantom_panicle_hydrangea
A22: 17 | B22: =SUM(C22:G22)/3 -> 7.3333333 | C22: NA | D22: NA | E22: 4 | F22: 15 | G22: 3 | H22: Candy Apple | I22: Hydrangea paniculata | J22: 0.98 | K22: 16 | L22: 8 | O22: Mop-like panicle | P22: White | Q22: 43983 | R22: 44136 | S22: 5 | T22: 5 | U22: Full sun to full shade | W22: N/A | X22: https://www.gertens.com/candy-apple-hydrangea
A23: 18 | B23: =SUM(C23:G23)/3 -> 8.6666667 | C23: NA | D23: NA | E23: 4 | F23: 18 | G23: 4 | H23: Incrediball | I23: Hydrangea arborescens | J23: 0.419 | K23: 4 | L23: 8 | O23: Mop | P23: White | Q23: 44013 | R23: 44044 | S23: 4 to 5 | T23: 4 to 5 | U23: Full sun to part sun | V23: N/A | W23: N/A | X23: https://www.thespruce.com/description-of-incrediball-hydrangeas-2132707 | Y23: Could not find exact bloom time, used our data
A24: 19 | B24: =SUM(C24:G24)/5 -> 8.8 | C24: 10 | D24: 5 | E24: 8 | F24: 17 | G24: 4 | H24: Baby Lace | I24: Hydrangea paniculata | J24: 0.333 | K24: 14 | L24: 4 | M24: 2.2 | N24: =13 -> 13 | O24: Lacy panicle | P24: White | Q24: 44013 | R24: 44075 | S24: 3 to 4 | T24: 3 to 4 | U24: Full sun to part shade | V24: Medium | W24: Medium | X24: https://www.missouribotanicalgarden.org
A25: 19 | B25: =SUM(C25:G25)/5 -> 8.8 | C25: 16 | D25: 6 | E25: 3 | F25: 16 | G25: 3 | H25: Strawberry Shake | I25: Hydrangea paniculata | J25: 0.632 | K25: 15 | L25: 9 | M25: 1 | N25: 1 | O25: Mop-like panicle | P25: Pink-white | Q25: 44013 | R25: 44044 | S25: 4 to 5 | T25: 4 | U25: Full sun to part shade | V25: N/A | W25: N/A | X25: https://www.monrovia.com/strawberry-shake-hydrangea.html?srsltid=AfmBOorS12CObULKHM2qOzTYRexOuJVz_6ejDoI829IMDzQKGfBb2NOQ | Y25: Exact dates weren't available so used our data
I26: AVERAGE | J26: =AVERAGE(J2:J25) -> 1.0273478 | K26: =AVERAGE(K2:K25) -> 33.73913 | L26: =AVERAGE(L2:L25) -> 6.6956522 | M26: =AVERAGE(M2:M25) -> 3.15 | N26: =AVERAGE(N2:N25) -> 15.45

Sheet TopVarietiesforPCA
A1: Trademark.Cultivar | B1: shannon_index (larger is better) | C1: Avg Insect Spp Abundance / plant / season | D1: Total Spp. Insect richness / season | E1: 2019_to_2021_AvgSppRichness | F1: 2019_to_2021_TotalDays_w_Insects | G1: Flower type | H1: Color | I1: BloomStart | J1: BloomEnd | K1: Height (ft) | L1: Spread (ft) | M1: Sun | N1: Water | O1: Maintenance | P1: Source | Q1: Note
A2: Baby Lace | B2: 0.333 | C2: 14 | D2: 4 | E2: 2.2 | F2: =13 -> 13 | G2: Lacy panicle | H2: White | I2: 44013 | J2: 44075 | K2: 3 to 4 | L2: 3 to 4 | M2: Full sun to part shade | N2: Medium | O2: Medium | P2: https://www.missouribotanicalgarden.org
A3: Big Ben | B3: 0.928 | C3: 15 | D3: 1 | E3: 5.34 | F3: 22 | G3: Lacy panicle | H3: White | I3: 44044 | J3: 44136 | K3: 19 | L3: 10 | M3: Full sun to full shade | N3: Medium | O3: Medium | P3: http://plants.beechwood-gardens.com/12130013/Plant/11837/Big_Ben_Hydrangea/
A4: Brussels Lace | B4: 1.58 | C4: 43 | D4: 5 | E4: 3.46 | F4: 19 | G4: Lacy panicle | H4: White | I4: 44013 | J4: 44105 | K4: 5 | L4: 6 | M4: Full sun to part shade | N4: Medium high | O4: N/A | P4: https://www.chicagobotanic.org/plantcollections/plantfinder/hydrangea_paniculata_brussels_lace--brussels_lace_panicle_hydrangea
A5: Candy Apple | B5: 0.98 | C5: 16 | D5: 8 | E5: 3.425 | F5: 16.5 | G5: Mop-like panicle | H5: White | I5: 43983 | J5: 44136 | K5: 5 | L5: 5 | M5: Full sun to full shade | O5: N/A | P5: https://www.gertens.com/candy-apple-hydrangea
A6: Dharuma | B6: =0.807 -> 0.807 | C6: 43 | D6: 8 | E6: 7.17 | F6: 12 | G6: Lacy panicle | H6: White | I6: 44013 | J6: 44075 | K6: 3 to 4 | L6: 3 to 4 | M6: Full sun to part shade | N6: Medium | O6: N/A | P6: https://www.northshoreplantclub.com/plant?id=7267
A7: Fire Light | B7: 1.113 | C7: 25 | D7: 15 | E7: 1.33 | F7: 4 | G7: Mop-like panicle | H7: Pink | I7: 44014 | J7: 44075 | K7: 6 to 8 | L7: 6 to 8 | M7: Sun to part shade | N7: N/A | O7: N/A | P7: https://www.whiteflowerfarm.com/63163-product.html
A8: Floribunda | B8: 1.03 | C8: 19 | D8: 4 | E8: 4 | F8: 19 | G8: Lacy panicle | H8: White | I8: 44044 | J8: 44105 | K8: 8 to 13 | L8: 5 to 8 | M8: Full sun to part shade | N8: Moist but well-drained | O8: N/A | P8: https://www.rhs.org.uk/plants/98580/hydrangea-paniculata-floribunda/details | Q8: Could not find a bloom time so used our own data for it
A9: Great Star | B9: 1.15 | C9: 25.5 | D9: 7 | E9: 3.08 | F9: 20 | G9: Lacy panicle | H9: White | I9: 44013 | J9: 44075 | K9: 6 to 7 | L9: 7 to 8 | M9: Full sun to part shade | N9: Medium | O9: Medium | P9: https://www.missouribotanicalgarden.org
A10: Green Spire | B10: 1.15 | C10: 80 | D10: 4 | E10: 3.52 | F10: 23 | G10: Lacy panicle | H10: Green-white | I10: 44044 | J10: 44105 | K10: 6 to 10 | L10: 6 to 10 | M10: Full sun to part sun | N10: Medium | O10: Low | P10: https://www.gardenia.net/plant/hydrangea-paniculata-greenspire | Q10: Could not find a bloom time so used our own data for it
A11: Haas Halo | B11: 0.596 | C11: 36 | D11: 7 | E11: 3.425 | F11: 16.5 | G11: Lacy | H11: White | I11: 43983 | J11: 44013 | K11: 7 | L11: 7 | M11: Full sun to full shade | N11: N/A | O11: N/A | P11: https://mtcubacenter.org/trials/wild-hydrangea-for-the-mid-atlantic-region/hydrangea-arborescens-haas-halo/
A12: Honey Comb | B12: 0.979 | C12: 50 | D12: 4 | E12: 3.76 | F12: 16 | G12: Lacy panicle | H12: White | I12: 44013 | J12: 44105 | K12: 15 | L12: 7 | M12: Full sun to full shade | N12: N/A | O12: Medium | P12: http://plants.beechwood-gardens.com/12130013/Plant/16553/Honeycomb_Hydrangea/ | Q12: Could not find exact bloom time, used our data
A13: Incrediball | B13: 0.419 | C13: 4 | D13: 8 | E13: 3.425 | F13: 16.5 | G13: Mop | H13: White | I13: 44013 | J13: 44044 | K13: 4 to 5 | L13: 4 to 5 | M13: Full sun to part sun | N13: N/A | O13: N/A | P13: https://www.thespruce.com/description-of-incrediball-hydrangeas-2132707 | Q13: Could not find exact bloom time, used our data
A14: Kyushu | B14: 1.441 | C14: 54 | D14: 5 | E14: 3.52 | F14: 19 | G14: Lacy panicle | H14: White | I14: 43952 | J14: 44105 | K14: 6 to 8 | L14: 6 to 8 | M14: Full sun to part shade | N14: Medium | O14: N/A | P14: https://www.chicagobotanic.org/plantcollections/plantfinder/hydrangea_paniculata_kyushu--kyushu_panicle_hydrangea and https://hydrangeasplus.com/products/hydrangea-paniculata-kyushu?srsltid=AfmBOoppDF-Qk1uw-TcabnNQSop8sVqaT7Z2uEnE51IyVpV1DF6uhEKi
A15: Late / Tardiva | B15: 1.112 | C15: 31.5 | D15: 7 | E15: 3.56 | F15: 19 | G15: Lacy panicle | H15: White | I15: 44013 | J15: 44075 | K15: 8 to 12 | L15: 7 to 10 | M15: Full sun to part shade | N15: Medium | O15: Medium | P15: https://www.missouribotanicalgarden.org/PlantFinder/PlantFinderDetails.aspx?kempercode=d360
A16: Little Quick Fire | B16: 1.202 | C16: 20.5 | D16: 6 | E16: 3.39 | F16: 12 | G16: Lacy panicle | H16: Pink | I16: 44013 | J16: 44105 | K16: 3 to 5 | L16: 3 to 5 | M16: Full sun to part sun | N16: Medium | O16: N/A | P16: https://hydrangea.com/products/little-quick-fire-panicle-hydrangea?srsltid=AfmBOooNVO-RW1s19arvwHK3wJkCyUnjN03YejaKTVPZG5GIOhFAuDJd
A17: Mega Pearl | B17: 1.156 | C17: 35 | D17: 8 | E17: 2.05 | F17: 14 | G17: Mop-like panicle | H17: Pink-white | I17: 44013 | J17: 44105 | K17: 6 to 8 | L17: 6 to 8 | M17: Full sun | N17: Medium | O17: N/A | P17: https://naturehills.com/products/hydrangea-mega-pearl?srsltid=AfmBOoqtkNbCaP9iB6-2A1Kswx4540onK_3L41O7YiUTRkcuVu7YItxr | Q17: Could not find exact date so used our data
A18: Phantom | B18: 0.9 | C18: 26.5 | D18: 8 | E18: 2 | F18: 8 | G18: Mop-like panicle | H18: White | I18: 44013 | J18: 44105 | K18: 6 | L18: 6 | M18: Full sun to part shade | N18: Medium | O18: N/A | P18: https://www.chicagobotanic.org/plantcollections/plantfinder/hydrangea_paniculata_phantom--phantom_panicle_hydrangea
A19: Pink Diamond | B19: 1.561 | C19: 66 | D19: 4 | E19: 2.9 | F19: 17 | G19: Lacy panicle | H19: Pink | I19: 44013 | J19: 44075 | K19: 8 to 15 | L19: 8 to 15 | M19: Full sun to part shade | N19: Medium | O19: Medium | P19: https://www.missouribotanicalgarden.org
A20: Pinky Winky | B20: 1.112 | C20: 40 | D20: 9 | E20: 3.7 | F20: 25 | G20: Lacy panicle | H20: Pink-white | I20: 44013 | J20: 44075 | K20: 6 to 8 | L20: 5 to 6 | M20: Full sun to part shade | N20: Medium | O20: Medium | P20: https://www.missouribotanicalgarden.org
A21: Quick Fire | B21: 1.423 | C21: 26 | D21: 9 | E21: 3.75 | F21: 33 | G21: Lacy panicle | H21: Pink | I21: 44013 | J21: 44105 | K21: 6 to 8 | L21: 6 to 8 | M21: Sun to part shade | O21: N/A | P21: https://www.petittigardencenter.com/quick-fire-a-panicle-hydrangea-variety-spotlight/ | Q21: End bloom time wasn't available online; used our data for that
A22: Ruby / Angel's Blush | B22: 1.214 | C22: 31.5 | D22: 6 | E22: 2.27 | F22: 11 | G22: Mop-like panicle | H22: Pink | I22: 44013 | J22: 44105 | K22: 8 to 12 | L22: 6 to 10 | M22: Full sun to part sun | N22: N/A | O22: N/A | P22: https://www.monrovia.com/angels-blush-hydrangea.html?srsltid=AfmBOorQcKnkdvItwFKmF1ruxmKdZTR2EsF7335iSOcWRE1LpMs9XAxD | Q22: Exact dates weren't available so used our data
A23: Strawberry Shake | B23: 0.632 | C23: 15 | D23: 9 | E23: 1 | F23: 1 | G23: Mop-like panicle | H23: Pink-white | I23: 44013 | J23: 44044 | K23: 4 to 5 | L23: 4 | M23: Full sun to part shade | N23: N/A | O23: N/A | P23: https://www.monrovia.com/strawberry-shake-hydrangea.html?srsltid=AfmBOorS12CObULKHM2qOzTYRexOuJVz_6ejDoI829IMDzQKGfBb2NOQ | Q23: Exact dates weren't available so used our data
A24: Strawberry Sundae | B24: 1.17 | C24: 37 | D24: 11 | E24: 1 | F24: 2 | G24: Mop-like panicle | H24: Pink-white | I24: 44013 | J24: 44075 | K24: 4 to 5 | L24: 3 to 4 | M24: Full sun to part sun | N24: Medium | O24: N/A | P24: https://www.southernliving.com/garden/flowers/strawberry-sundae-hydrangea
A25: White Dome | B25: 0.753 | C25: 54 | D25: 4 | E25: 3.425 | F25: 16.5 | G25: Lacy | H25: White | I25: 43983 | J25: 44044 | K25: 3 to 5 | L25: 3 to 4 | M25: Part shade | N25: Medium | O25: Low | P25: https://www.missouribotanicalgarden.org/PlantFinder/PlantFinderDetails.aspx?taxonid=264083&isprofile=0&

Sheet AllVarieties
A1: Trademark.Cultivar | B1: shannon_index (larger is better) | C1: Avg Insect Spp Abundance / plant / season | D1: Total Spp. Insect richness / season | E1: 2019_TotalDays_w_Insects | F1: Flower type | G1: Color | H1: BloomStart | I1: BloomEnd | J1: BloomTime | K1: Height (ft) | L1: Spread (ft) | M1: Sun | N1: Water | O1: Maintenance | P1: Species | Q1: Note | R1: Source
A2: Annabelle | B2: 0.6931472 | C2: 4 | D2: 2 | E2: 3 | F2: Mop | G2: White | H2: 43983 | I2: 44075 | J2: June - Sept | K2: 3 to 5 | L2: 4 to 6 | M2: Part shade | O2: Low | P2: Hydrangea arborescens | Q2: Days blooming 2019 data not available; used median | R2: https://www.missouribotanicalgarden.org
A3: Baby Lace | B3: 0.3330448 | C3: 14 | D3: 4 | E3: 2 | F3: Lacy panicle | G3: White | H3: 44013 | I3: 44075 | J3: July - Sept | K3: 3 to 4 | L3: 3 to 4 | M3: Full sun to part shade | N3: Medium | O3: Medium | P3: Hydrangea paniculata | R3: https://www.missouribotanicalgarden.org
A4: Bella Anna | B4: 0 | C4: 2 | D4: 3 | E4: 3 | F4: Mop | G4: Pink | J4: July - Sept | K4: 2 to 3 | L4: 2 to 3 | M4: Part sun | N4: Medium | P4: Hydrangea arborescens | Q4: Days blooming 2019 data not available; used median | R4: https://www.missouribotanicalgarden.org/PlantFinder/PlantFinderDetails.aspx?taxonid=274487&isprofile=0&gen=Hydrangea%25&z=6
A5: Berry White | B5: 0.8958797 | C5: 5 | D5: 2 | E5: 3 | F5: Mop | G5: Pink | J5: July - Sept | K5: 4 to 5 | L5: 4 to 5 | M5: Sun to part shade | P5: Hydrangea paniculata | Q5: Days blooming 2019 data not available; used median
A6: Big Ben | B6: 0.9276173 | C6: 15 | D6: 1 | E6: 7 | F6: Lacy panicle | G6: White | H6: 44044 | I6: 44136 | J6: Aug - Oct | K6: 19 | L6: 10 | M6: Full sun to full shade | N6: Medium | O6: Medium | P6: Hydrangea paniculata | R6: http://plants.beechwood-gardens.com/12130013/Plant/11837/Big_Ben_Hydrangea/
A7: Bobo | B7: 1.0126113 | C7: 14 | D7: 5 | E7: 3 | F7: Mop-like panicle | G7: White | J7: Aug - Oct | K7: 2.5 - 3 | L7: 3 to 4 | M7: Sun to part sun | O7: Easy | P7: Hydrangea paniculata | Q7: Bloom time a guess; they just said midsummer to fall/ Days blooming 2019 data not available; used median | R7: https://www.provenwinners.com/plants/hydrangea/bobo-panicle-hydrangea-hydrangea-paniculata
A8: Bounty | B8: 0.6931472 | C8: 8 | D8: 3 | E8: 3 | F8: Mop | G8: Green-white | J8: June - July | K8: 5 | L8: 8 | M8: Sun to shade | O8: N/A | P8: Hydrangea arborescens | Q8: Days blooming 2019 data not available; used median | R8: https://mtcubacenter.org/trials/wild-hydrangea-for-the-mid-atlantic-region/hydrangea-arborescens-bounty/
A9: Brussels Lace | B9: 1.579459 | C9: 43 | D9: 5 | E9: 4 | F9: Lacy panicle | G9: White | H9: 44013 | I9: 44105 | J9: July - Oct | K9: 5 | L9: 6 | M9: Full sun to part shade | N9: Medium high | O9: N/A | P9: Hydrangea paniculata | R9: https://www.chicagobotanic.org/plantcollections/plantfinder/hydrangea_paniculata_brussels_lace--brussels_lace_panicle_hydrangea
A10: Candy Apple | B10: 0.9802899 | C10: 16 | D10: 8 | E10: 3 | F10: Mop-like panicle | G10: White | H10: 43983 | I10: 44136 | J10: June - Oct | K10: 5 | L10: 5 | M10: Full sun to full shade | O10: N/A | P10: Hydrangea paniculata | Q10: Days blooming 2019 data not available; used median | R10: https://www.gertens.com/candy-apple-hydrangea
A11: Daimond Rogue | B11: 0.6516739 | C11: 13 | D11: 4 | E11: 3 | F11: Mop-like panicle | G11: Pink-white | J11: Aug - Oct | K11: 4 to 5 | L11: 3 to 4 | M11: Full sun to part shade | O11: Easy | P11: Hydrangea paniculata | R11: https://firsteditionsplants.com/product/diamond-rouge-panicle-hydrangea/; https://www.gardenia.net/plant/hydrangea-paniculata-diamond-rouge
A12: Dharuma | B12: 0.8397249 | C12: 43 | D12: 8 | E12: 3 | F12: Lacy panicle | G12: White | H12: 44013 | I12: 44075 | J12: July - Sept | K12: 3 to 4 | L12: 3 to 4 | M12: Full sun to part shade | N12: Medium | O12: N/A | P12: Hydrangea paniculata | R12: https://www.northshoreplantclub.com/plant?id=7267
A13: Dolly | B13: 1.2569249 | C13: 25 | D13: 3 | E13: 1 | F13: Lacy panicle | G13: White | J13: Aug - Oct | K13: 5 to 8 | L13: 5 to 8 | M13: Full sun to partial shade | P13: Hydrangea paniculata | R13: https://www.rhs.org.uk/plants/177811/hydrangea-paniculata-dolly/details
A14: Early Evolution | B14: 0.1732868 | C14: 1.5 | D14: 4 | E14: 3 | F14: Lacy panicle | G14: Pink-white | J14: June - Nov | K14: 2 | L14: 2 | M14: Full sun to partial sun | N14: Moist but well-drained | O14: Easy | P14: Hydrangea paniculata | Q14: Days blooming 2019 data not available; used median | R14: https://www.waysidegardens.com/hydrangea-early-evolution-panicle-hydrangea-29895.html?srsltid=AfmBOoplMCVMM8O1mXoJVVWgNctuiqsXnHFi1Uw9h6XKAItY9-yi0uix
A15: Fire & Ice | B15: 1.8356357 | C15: 36 | D15: 3 | E15: 1 | F15: Lacy panicle | G15: Pink-white | J15: June - July | K15: 3 to 5 | L15: 3 to 4 | M15: Partial sun | O15: Easy | P15: Hydrangea paniculata | R15: https://www.ballseed.com/PlantInfo/?phid=034001085020985
A16: Fire Light | B16: 1.1404776 | C16: 25 | D16: 15 | E16: 1 | F16: Mop-like panicle | G16: Pink | H16: 44014 | I16: 44075 | J16: July - Sept | K16: 6 to 8 | L16: 6 to 8 | M16: Sun to part shade | N16: N/A | O16: N/A | P16: Hydrangea paniculata | R16: https://www.whiteflowerfarm.com/63163-product.html
A17: Floribunda | B17: 1.1065032 | C17: 19 | D17: 4 | E17: 5 | F17: Lacy panicle | G17: White | H17: 44044 | I17: 44105 | J17: Aug - Oct | K17: 8 to 13 | L17: 5 to 8 | M17: Full sun to part shade | N17: Moist but well-drained | O17: N/A | P17: Hydrangea paniculata | R17: https://www.rhs.org.uk/plants/98580/hydrangea-paniculata-floribunda/details
A18: Great Star | B18: 1.1731406 | C18: 25.5 | D18: 7 | E18: 7 | F18: Lacy panicle | G18: White | H18: 44013 | I18: 44075 | J18: July - Sept | K18: 6 to 7 | L18: 7 to 8 | M18: Full sun to part shade | N18: Medium | O18: Medium | P18: Hydrangea paniculata | R18: https://www.missouribotanicalgarden.org
A19: Green Spire | B19: 1.2637924 | C19: 80 | D19: 4 | E19: 3 | F19: Lacy panicle | G19: Green-white | H19: 44044 | I19: 44105 | J19: Aug - Oct | K19: 6 to 10 | L19: 6 to 10 | M19: Full sun to part sun | N19: Medium | O19: Low | P19: Hydrangea paniculata | Q19: Could not find a bloom time so used our own data for it | R19: https://www.gardenia.net/plant/hydrangea-paniculata-greenspire
A20: Haas Halo | B20: 0.5959298 | C20: 36 | D20: 7 | E20: 3 | F20: Lacy | G20: White | H20: 43983 | I20: 44013 | J20: June - July | K20: 7 | L20: 7 | M20: Full sun to full shade | N20: N/A | O20: N/A | P20: Hydrangea arborescens | Q20: Days blooming 2019 data not available; used median | R20: https://mtcubacenter.org/trials/wild-hydrangea-for-the-mid-atlantic-region/hydrangea-arborescens-haas-halo/
A21: Hayes Starburst | B21: 0 | C21: 2 | D21: 1 | E21: 3 | F21: Mop | G21: White | J21: June - Sept | K21: 2 to 4 | L21: 2 to 4 | M21: Part shade | N21: Medium | O21: Low | P21: Hydrangea arborescens | Q21: Days blooming 2019 data not available; used median | R21: https://www.missouribotanicalgarden.org/PlantFinder/PlantFinderDetails.aspx?taxonid=299175&isprofile=0&
A22: Honey Comb | B22: 0.9788602 | C22: 50 | D22: 4 | E22: 4 | F22: Lacy panicle | G22: White | H22: 44013 | I22: 44105 | J22: July - Oct | K22: 15 | L22: 7 | M22: Full sun to full shade | N22: N/A | O22: Medium | P22: Hydrangea paniculata | Q22: Could not find exact bloom time, used our data | R22: http://plants.beechwood-gardens.com/12130013/Plant/16553/Honeycomb_Hydrangea/
A23: Incrediball | B23: 0.4193734 | C23: 4 | D23: 8 | E23: 3 | F23: Mop | G23: White | H23: 44013 | I23: 44044 | J23: July - Aug | K23: 4 to 5 | L23: 4 to 5 | M23: Full sun to part sun | N23: N/A | O23: N/A | P23: Hydrangea arborescens | Q23: Could not find exact bloom time, used our data/ Days blooming 2019 data not available; used median | R23: https://www.thespruce.com/description-of-incrediball-hydrangeas-2132707
A24: Incredibelle Ruby | B24: 0.6648307 | C24: 6 | D24: 2 | E24: 3 | F24: Mop | G24: White | J24: June - Aug | K24: 4 to 5 | L24: 4 to 5 | M24: Full sun to part sun | N24: Medium | O24: Easy | P24: Hydrangea arborescens | Q24: Days blooming 2019 data not available; used median | R24: https://www.provenwinners.com/plants/hydrangea/incrediball-smooth-hydrangea-hydrangea-arborescens
A25: Invincibelle Mini Mauvette | B25: 0 | C25: 0 | D25: 1 | E25: 3 | F25: Mop | G25: Pink | J25: July - Sept | K25: 2.5 - 3 | L25: 2.5 - 3 | M25: Part sun to sun | N25: Medium | O25: Easy | P25: Hydrangea arborescens | Q25: Estimated days blooming based on 'summer to fall' | R25: https://www.provenwinners.com/plants/hydrangea/invincibelle-mini-mauvette-smooth-hydrangea-hydrangea-arborescens
A26: Invincibelle Spirit | B26: 0.2772589 | C26: 2.5 | D26: 5 | E26: 3 | F26: Mop | G26: Pink | J26: July - Sept | K26: 3.5 - 4 | L26: 3.5 - 4 | M26: Part sun to sun | N26: Medium | O26: Easy | P26: Hydrangea arborescens | Q26: Days blooming 2019 data not available; used median | R26: https://www.provenwinners.com/plants/hydrangea/invincibelle-spirit-ii-smooth-hydrangea-hydrangea-arborescens
A27: Invincibelle Wee White | B27: 0 | C27: 0 | D27: 1 | E27: 3 | F27: Mop | G27: White | J27: July - Sept | K27: 1 - 2.5 | L27: 1-2.5 | M27: Part sun to sun | N27: Average | O27: Easy | P27: Hydrangea arborescens | Q27: Estimated days blooming based on 'summer to fall' | R27: https://www.provenwinners.com/plants/hydrangea/invincibelle-wee-white-smooth-hydrangea-hydrangea-arborescens
A28: Kyushu | B28: 1.4416311 | C28: 54 | D28: 5 | E28: 5 | F28: Lacy panicle | G28: White | H28: 43952 | I28: 44105 | J28: May - Oct | K28: 6 to 8 | L28: 6 to 8 | M28: Full sun to part shade | N28: Medium | O28: N/A | P28: Hydrangea paniculata | R28: https://www.chicagobotanic.org/plantcollections/plantfinder/hydrangea_paniculata_kyushu--kyushu_panicle_hydrangea and https://hydrangeasplus.com/products/hydrangea-paniculata-kyushu?srsltid=AfmBOoppDF-Qk1uw-TcabnNQSop8sVqaT7Z2uEnE51IyVpV1DF6uhEKi
A29: Lime Rickey | B29: 0 | C29: 0 | D29: 3 | E29: 3 | F29: Mop | G29: Green | J29: July - Oct | K29: 4 to 5 | L29: 4 to 5 | M29: Full sun to part sun | N29: Medium | O29: Easy | P29: Hydrangea arborescens | R29: https://www.provenwinners.com/plants/hydrangea/lime-rickey-smooth-hydrangea-hydrangea-arborescens
A30: Limelight | B30: 1.0741606 | C30: 22.5 | D30: 6 | E30: 1 | F30: Mop-like panicle | G30: Green-white | J30: Aug - Oct | K30: 6 to 8 | L30: 6 to 8 | M30: Full sun to part sun | N30: Medium | O30: Easy | P30: Hydrangea paniculata | Q30: Days estimated by season | R30: https://www.provenwinners.com/plants/hydrangea/limelight-panicle-hydrangea-hydrangea-paniculata
A31: Limelight Prime | B31: 0.4925454 | C31: 11 | D31: 4 | E31: 3 | F31: Mop-like panicle | G31: Green | J31: June - Aug | K31: 4 to 6 | L31: 4 to 5 | M31: Full sun to part sun | N31: Medium | O31: Easy | P31: Hydrangea paniculata | Q31: Days blooming 2019 data not available; used median | R31: https://www.provenwinners.com/plants/hydrangea/limelight-prime-panicle-hydrangea-hydrangea-paniculata
A32: Little Lamb | B32: 1.4686503 | C32: 23 | D32: 4 | E32: 2 | F32: Mop-like panicle | G32: White | J32: July - Sept | K32: 4 to 6 | L32: 4 to 6 | M32: Full sun to part sun | N32: Medium | O32: Easy | P32: Hydrangea paniculata | Q32: Days estimated by season | R32: https://www.provenwinners.com/plants/hydrangea/little-lamb-panicle-hydrangea-hydrangea-paniculata
A33: Little Lime | B33: 0.8440066 | C33: 6 | D33: 5 | E33: 3 | F33: Mop-like panicle | G33: Green-white | J33: June - Aug | K33: 3 to 5 | L33: 3 to 5 | M33: Full sun to part sun | N33: Medium | O33: Easy | P33: Hydrangea paniculata | Q33: Days blooming 2019 data not available; used median
A34: Little Lime Punch | B34: 0.2502012 | C34: 6 | D34: 2 | E34: 3 | F34: Mop-like panicle | G34: Pink-white | J34: June - Aug | K34: 3 to 5 | L34: 3 to 5 | M34: Full sun to part sun | N34: Medium | O34: Moderate | P34: Hydrangea paniculata | Q34: Days blooming 2019 data not available; used median
A35: Little Quick Fire | B35: 1.2018749 | C35: 20.5 | D35: 6 | E35: 3 | F35: Lacy panicle | G35: Pink | H35: 44013 | I35: 44105 | J35: July - Oct | K35: 3 to 5 | L35: 3 to 5 | M35: Full sun to part sun | N35: Medium | O35: N/A | P35: Hydrangea paniculata | Q35: Based on actual days blooming data | R35: https://hydrangea.com/products/little-quick-fire-panicle-hydrangea?srsltid=AfmBOooNVO-RW1s19arvwHK3wJkCyUnjN03YejaKTVPZG5GIOhFAuDJd
A36: Mega Pearl | B36: 1.1663076 | C36: 35 | D36: 8 | E36: 4 | F36: Mop-like panicle | G36: Pink-white | H36: 44013 | I36: 44105 | J36: July - Oct | K36: 6 to 8 | L36: 6 to 8 | M36: Full sun | N36: Medium | O36: N/A | P36: Hydrangea paniculata | Q36: Could not find exact date so used our data | R36: https://naturehills.com/products/hydrangea-mega-pearl?srsltid=AfmBOoqtkNbCaP9iB6-2A1Kswx4540onK_3L41O7YiUTRkcuVu7YItxr
A37: Phantom | B37: 0.8995531 | C37: 26.5 | D37: 8 | E37: 2 | F37: Mop-like panicle | G37: White | H37: 44013 | I37: 44105 | J37: July - Sept | K37: 6 | L37: 6 | M37: Full sun to part shade | N37: Medium | O37: N/A | P37: Hydrangea paniculata | R37: https://www.chicagobotanic.org/plantcollections/plantfinder/hydrangea_paniculata_phantom--phantom_panicle_hydrangea; https://www.whiteflowerfarm.com/hydrangea-paniculata-phantom?srsltid=AfmBOoqN-6A_rH-qscaxYDmDo3F1gWv86VJUmwzuu6xPmHCuVASD09b9
A38: Pillow Talk | B38: 0.5493061 | C38: 4 | D38: 2 | E38: 3 | F38: Mop-like panicle | G38: Pink-white | J38: July - Sept | K38: 6 to 8 | L38: 6 to 8 | M38: Full sun to part sun | N38: Medium | O38: N/A | P38: Hydrangea paniculata | Q38: Days blooming 2019 data not available; used median | R38: https://www.bluestoneperennials.com/HYPT.html?srsltid=AfmBOopYXn8coQlzKXiXbK0TBf2_gvYPUJKAD4PVaOm2cjzKmRdmForX
A39: Pink Diamond | B39: 1.561319 | C39: 66 | D39: 4 | E39: 2 | F39: Lacy panicle | G39: Pink | H39: 44013 | I39: 44075 | J39: July - Sept | K39: 8 to 15 | L39: 8 to 15 | M39: Full sun to part shade | N39: Medium | O39: Medium | P39: Hydrangea paniculata | R39: https://www.missouribotanicalgarden.org
A40: Pink Lady | B40: 1.0919433 | C40: 18.5 | D40: 6 | E40: 3 | F40: Mop-like panicle | G40: Pink-white | J40: June - Aug | K40: 5 to 8 | L40: 5 to 8 | M40: Full sun to part shade | N40: Moist but well-drained | P40: Hydrangea paniculata | Q40: Days blooming 2019 data not available; used median | R40: https://www.rhs.org.uk/plants/177821/hydrangea-paniculata-pink-lady/details
...

Sheet StandardizedScores
A1: Trademark.Cultivar | B1: 2019-2021 photo insect count | C1: Quantile photo data | D1: Adjustment weight (+/- 12.5% of insect abundance weight per rank difference) | E1: shannon_index (larger is better) | F1: Quartile Shannon score | G1: Weighted Quantile | H1: Avg Insect Spp Abundance / plant / season | I1: Quantile Abundance 2024 data | J1: Weighted Quantile | K1: Total Spp. Insect richness / season | L1: Quantile Richness | M1: Weighted richness | N1: 2019_TotalDays_w_Insects | O1: Quantile Days | P1: Weighted Richness | Q1: Total | R1: Star Score | S1: Flower type | T1: Color | U1: BloomStart | V1: BloomEnd | W1: BloomTime | X1: Height (ft) | Y1: Spread (ft) | Z1: Sun | AA1: Water | AB1: Maintenance | AC1: Species | AD1: Note | AE1: Source
A2: Annabelle | B2: NA | E2: 0.6931472 | F2: =IF(AND($E2 >= Quartiles1!$A$1, $E2 <= Quartiles1!$A$2), 1, IF(AND($E2 > Quartiles1!$A$2, $E2 <= Quartiles1!$A$3), 2, IF(AND($E2 > Quartiles1!$A$3, $E2 <= Quartiles1!$A$4), 3, 4))) -> 2 | G2: =F2*PCAWeights!$E$21 -> 0.38472903 | H2: 4 | I2: =IF(AND($H2 >= Quartiles1!B$1, $H2 <= Quartiles1!$B$2), 1, IF(AND($H2 > Quartiles1!$B$2, $H2 <= Quartiles1!$B$3), 2, IF(AND($H2 > Quartiles1!$B$3, $H2 <= Quartiles1!$B$4), 3, 4))) -> 1 | J2: =I2*PCAWeights!$E$22 -> 0.20821322 | K2: 2 | L2: =IF(AND($K2 >= Quartiles1!$C$1, $K2 <= Quartiles1!$C$2), 1, IF(AND($K2 > Quartiles1!$C$2, $K2 <= Quartiles1!$C$3), 2, IF(AND($K2 > Quartiles1!$C$3, $K2 <= Quartiles1!$C$4), 3, 4))) -> 1 | M2: =L2*PCAWeights!$E$23 -> 0.24775757 | N2: 3 | O2: 2 | P2: =O2*PCAWeights!$E$24 -> 0.49985061 | Q2: =$D2+$G2+$J2+$M2+$P2 -> 1.3405504 | R2: =VLOOKUP($A2,'Star Score'!$A$2:$C$60,2,FALSE) -> 1 | S2: Mop | T2: White | U2: 43983 | V2: 44075 | W2: June - Sept | X2: 3 to 5 | Y2: 4 to 6 | Z2: Part shade | AB2: Low | AC2: Hydrangea arborescens | AD2: Days blooming 2019 data not available; used median | AE2: https://www.missouribotanicalgarden.org
A3: Baby Lace | B3: 82 | C3: =IF(AND($B3 >= Quartiles1!$E$1, $B3 <= Quartiles1!$E$2), 1, IF(AND($B3 > Quartiles1!$E$2, $B3 <= Quartiles1!$E$3), 2, IF(AND($B3 > Quartiles1!$E$3, $B3 <= Quartiles1!$E$4), 3, 4))) -> 3 | D3: =$J$61*0.125 -> 0.063963806 | E3: 0.3330448 | F3: =IF(AND($E3 >= Quartiles1!$A$1, $E3 <= Quartiles1!$A$2), 1, IF(AND($E3 > Quartiles1!$A$2, $E3 <= Quartiles1!$A$3), 2, IF(AND($E3 > Quartiles1!$A$3, $E3 <= Quartiles1!$A$4), 3, 4))) -> 1 | G3: =F3*PCAWeights!$E$21 -> 0.19236451 | H3: 14 | I3: =IF(AND($H3 >= Quartiles1!B$1, $H3 <= Quartiles1!$B$2), 1, IF(AND($H3 > Quartiles1!$B$2, $H3 <= Quartiles1!$B$3), 2, IF(AND($H3 > Quartiles1!$B$3, $H3 <= Quartiles1!$B$4), 3, 4))) -> 2 | J3: =I3*PCAWeights!$E$22 -> 0.41642643 | K3: 4 | L3: =IF(AND($K3 >= Quartiles1!$C$1, $K3 <= Quartiles1!$C$2), 1, IF(AND($K3 > Quartiles1!$C$2, $K3 <= Quartiles1!$C$3), 2, IF(AND($K3 > Quartiles1!$C$3, $K3 <= Quartiles1!$C$4), 3, 4))) -> 2 | M3: =L3*PCAWeights!$E$23 -> 0.49551513 | N3: 2 | O3: 1 | P3: =O3*PCAWeights!$E$24 -> 0.2499253 | Q3: =$D3+$G3+$J3+$M3+$P3 -> 1.4181952 | R3: =VLOOKUP($A3,'Star Score'!$A$2:$C$60,2,FALSE) -> 2 | S3: Lacy panicle | T3: White | U3: 44013 | V3: 44075 | W3: July - Sept | X3: 3 to 4 | Y3: 3 to 4 | Z3: Full sun to part shade | AA3: Medium | AB3: Medium | AC3: Hydrangea paniculata | AE3: https://www.missouribotanicalgarden.org
A4: Bella Anna | B4: NA | E4: 0 | F4: =IF(AND($E4 >= Quartiles1!$A$1, $E4 <= Quartiles1!$A$2), 1, IF(AND($E4 > Quartiles1!$A$2, $E4 <= Quartiles1!$A$3), 2, IF(AND($E4 > Quartiles1!$A$3, $E4 <= Quartiles1!$A$4), 3, 4))) -> 1 | G4: =F4*PCAWeights!$E$21 -> 0.19236451 | H4: 2 | I4: =IF(AND($H4 >= Quartiles1!B$1, $H4 <= Quartiles1!$B$2), 1, IF(AND($H4 > Quartiles1!$B$2, $H4 <= Quartiles1!$B$3), 2, IF(AND($H4 > Quartiles1!$B$3, $H4 <= Quartiles1!$B$4), 3, 4))) -> 1 | J4: =I4*PCAWeights!$E$22 -> 0.20821322 | K4: 3 | L4: =IF(AND($K4 >= Quartiles1!$C$1, $K4 <= Quartiles1!$C$2), 1, IF(AND($K4 > Quartiles1!$C$2, $K4 <= Quartiles1!$C$3), 2, IF(AND($K4 > Quartiles1!$C$3, $K4 <= Quartiles1!$C$4), 3, 4))) -> 1 | M4: =L4*PCAWeights!$E$23 -> 0.24775757 | N4: 3 | O4: 2 | P4: =O4*PCAWeights!$E$24 -> 0.49985061 | Q4: =$D4+$G4+$J4+$M4+$P4 -> 1.1481859 | R4: =VLOOKUP($A4,'Star Score'!$A$2:$C$60,2,FALSE) -> 1 | S4: Mop | T4: Pink | W4: July - Sept | X4: 2 to 3 | Y4: 2 to 3 | Z4: Part sun | AA4: Medium | AC4: Hydrangea arborescens | AD4: Days blooming 2019 data not available; used median | AE4: https://www.missouribotanicalgarden.org/PlantFinder/PlantFinderDetails.aspx?taxonid=274487&isprofile=0&gen=Hydrangea%25&z=6
A5: Berry White | B5: NA | E5: 0.8958797 | F5: =IF(AND($E5 >= Quartiles1!$A$1, $E5 <= Quartiles1!$A$2), 1, IF(AND($E5 > Quartiles1!$A$2, $E5 <= Quartiles1!$A$3), 2, IF(AND($E5 > Quartiles1!$A$3, $E5 <= Quartiles1!$A$4), 3, 4))) -> 2 | G5: =F5*PCAWeights!$E$21 -> 0.38472903 | H5: 5 | I5: =IF(AND($H5 >= Quartiles1!B$1, $H5 <= Quartiles1!$B$2), 1, IF(AND($H5 > Quartiles1!$B$2, $H5 <= Quartiles1!$B$3), 2, IF(AND($H5 > Quartiles1!$B$3, $H5 <= Quartiles1!$B$4), 3, 4))) -> 1 | J5: =I5*PCAWeights!$E$22 -> 0.20821322 | K5: 2 | L5: =IF(AND($K5 >= Quartiles1!$C$1, $K5 <= Quartiles1!$C$2), 1, IF(AND($K5 > Quartiles1!$C$2, $K5 <= Quartiles1!$C$3), 2, IF(AND($K5 > Quartiles1!$C$3, $K5 <= Quartiles1!$C$4), 3, 4))) -> 1 | M5: =L5*PCAWeights!$E$23 -> 0.24775757 | N5: 3 | O5: 2 | P5: =O5*PCAWeights!$E$24 -> 0.49985061 | Q5: =$D5+$G5+$J5+$M5+$P5 -> 1.3405504 | R5: =VLOOKUP($A5,'Star Score'!$A$2:$C$60,2,FALSE) -> 1 | S5: Mop | T5: Pink | W5: July - Sept | X5: 4 to 5 | Y5: 4 to 5 | Z5: Sun to part shade | AC5: Hydrangea paniculata | AD5: Days blooming 2019 data not available; used median
A6: Big Ben | B6: 521 | C6: =IF(AND($B6 >= Quartiles1!$E$1, $B6 <= Quartiles1!$E$2), 1, IF(AND($B6 > Quartiles1!$E$2, $B6 <= Quartiles1!$E$3), 2, IF(AND($B6 > Quartiles1!$E$3, $B6 <= Quartiles1!$E$4), 3, 4))) -> 4 | D6: =-$J$61*0.125*2 -> -0.12792761 | E6: 0.9276173 | F6: =IF(AND($E6 >= Quartiles1!$A$1, $E6 <= Quartiles1!$A$2), 1, IF(AND($E6 > Quartiles1!$A$2, $E6 <= Quartiles1!$A$3), 2, IF(AND($E6 > Quartiles1!$A$3, $E6 <= Quartiles1!$A$4), 3, 4))) -> 3 | G6: =F6*PCAWeights!$E$21 -> 0.57709354 | H6: 15 | I6: =IF(AND($H6 >= Quartiles1!B$1, $H6 <= Quartiles1!$B$2), 1, IF(AND($H6 > Quartiles1!$B$2, $H6 <= Quartiles1!$B$3), 2, IF(AND($H6 > Quartiles1!$B$3, $H6 <= Quartiles1!$B$4), 3, 4))) -> 2 | J6: =I6*PCAWeights!$E$22 -> 0.41642643 | K6: 1 | L6: =IF(AND($K6 >= Quartiles1!$C$1, $K6 <= Quartiles1!$C$2), 1, IF(AND($K6 > Quartiles1!$C$2, $K6 <= Quartiles1!$C$3), 2, IF(AND($K6 > Quartiles1!$C$3, $K6 <= Quartiles1!$C$4), 3, 4))) -> 1 | M6: =L6*PCAWeights!$E$23 -> 0.24775757 | N6: 7 | O6: 4 | P6: =O6*PCAWeights!$E$24 -> 0.99970122 | Q6: =$D6+$G6+$J6+$M6+$P6 -> 2.1130511 | R6: =VLOOKUP($A6,'Star Score'!$A$2:$C$60,2,FALSE) -> 3 | S6: Lacy panicle | T6: White | U6: 44044 | V6: 44136 | W6: Aug - Oct | X6: 19 | Y6: 10 | Z6: Full sun to full shade | AA6: Medium | AB6: Medium | AC6: Hydrangea paniculata | AE6: http://plants.beechwood-gardens.com/12130013/Plant/11837/Big_Ben_Hydrangea/
A7: Bobo | B7: NA | E7: 1.0126113 | F7: =IF(AND($E7 >= Quartiles1!$A$1, $E7 <= Quartiles1!$A$2), 1, IF(AND($E7 > Quartiles1!$A$2, $E7 <= Quartiles1!$A$3), 2, IF(AND($E7 > Quartiles1!$A$3, $E7 <= Quartiles1!$A$4), 3, 4))) -> 3 | G7: =F7*PCAWeights!$E$21 -> 0.57709354 | H7: 14 | I7: =IF(AND($H7 >= Quartiles1!B$1, $H7 <= Quartiles1!$B$2), 1, IF(AND($H7 > Quartiles1!$B$2, $H7 <= Quartiles1!$B$3), 2, IF(AND($H7 > Quartiles1!$B$3, $H7 <= Quartiles1!$B$4), 3, 4))) -> 2 | J7: =I7*PCAWeights!$E$22 -> 0.41642643 | K7: 5 | L7: =IF(AND($K7 >= Quartiles1!$C$1, $K7 <= Quartiles1!$C$2), 1, IF(AND($K7 > Quartiles1!$C$2, $K7 <= Quartiles1!$C$3), 2, IF(AND($K7 > Quartiles1!$C$3, $K7 <= Quartiles1!$C$4), 3, 4))) -> 3 | M7: =L7*PCAWeights!$E$23 -> 0.7432727 | N7: 3 | O7: 2 | P7: =O7*PCAWeights!$E$24 -> 0.49985061 | Q7: =$D7+$G7+$J7+$M7+$P7 -> 2.2366433 | R7: =VLOOKUP($A7,'Star Score'!$A$2:$C$60,2,FALSE) -> 3 | S7: Mop-like panicle | T7: White | W7: Aug - Oct | X7: 2.5 - 3 | Y7: 3 to 4 | Z7: Sun to part sun | AB7: Easy | AC7: Hydrangea paniculata | AD7: Bloom time a guess; they just said midsummer to fall/ Days blooming 2019 data not available; used median | AE7: https://www.provenwinners.com/plants/hydrangea/bobo-panicle-hydrangea-hydrangea-paniculata
A8: Bounty | B8: NA | E8: 0.6931472 | F8: =IF(AND($E8 >= Quartiles1!$A$1, $E8 <= Quartiles1!$A$2), 1, IF(AND($E8 > Quartiles1!$A$2, $E8 <= Quartiles1!$A$3), 2, IF(AND($E8 > Quartiles1!$A$3, $E8 <= Quartiles1!$A$4), 3, 4))) -> 2 | G8: =F8*PCAWeights!$E$21 -> 0.38472903 | H8: 8 | I8: =IF(AND($H8 >= Quartiles1!B$1, $H8 <= Quartiles1!$B$2), 1, IF(AND($H8 > Quartiles1!$B$2, $H8 <= Quartiles1!$B$3), 2, IF(AND($H8 > Quartiles1!$B$3, $H8 <= Quartiles1!$B$4), 3, 4))) -> 2 | J8: =I8*PCAWeights!$E$22 -> 0.41642643 | K8: 3 | L8: =IF(AND($K8 >= Quartiles1!$C$1, $K8 <= Quartiles1!$C$2), 1, IF(AND($K8 > Quartiles1!$C$2, $K8 <= Quartiles1!$C$3), 2, IF(AND($K8 > Quartiles1!$C$3, $K8 <= Quartiles1!$C$4), 3, 4))) -> 1 | M8: =L8*PCAWeights!$E$23 -> 0.24775757 | N8: 3 | O8: 2 | P8: =O8*PCAWeights!$E$24 -> 0.49985061 | Q8: =$D8+$G8+$J8+$M8+$P8 -> 1.5487636 | R8: =VLOOKUP($A8,'Star Score'!$A$2:$C$60,2,FALSE) -> 2 | S8: Mop | T8: Green-white | W8: June - July | X8: 5 | Y8: 8 | Z8: Sun to shade | AB8: N/A | AC8: Hydrangea arborescens | AD8: Days blooming 2019 data not available; used median | AE8: https://mtcubacenter.org/trials/wild-hydrangea-for-the-mid-atlantic-region/hydrangea-arborescens-bounty/
A9: Brussels Lace | B9: 287 | C9: =IF(AND($B9 >= Quartiles1!$E$1, $B9 <= Quartiles1!$E$2), 1, IF(AND($B9 > Quartiles1!$E$2, $B9 <= Quartiles1!$E$3), 2, IF(AND($B9 > Quartiles1!$E$3, $B9 <= Quartiles1!$E$4), 3, 4))) -> 4 | D9: 0 | E9: 1.579459 | F9: =IF(AND($E9 >= Quartiles1!$A$1, $E9 <= Quartiles1!$A$2), 1, IF(AND($E9 > Quartiles1!$A$2, $E9 <= Quartiles1!$A$3), 2, IF(AND($E9 > Quartiles1!$A$3, $E9 <= Quartiles1!$A$4), 3, 4))) -> 4 | G9: =F9*PCAWeights!$E$21 -> 0.76945805 | H9: 43 | I9: =IF(AND($H9 >= Quartiles1!B$1, $H9 <= Quartiles1!$B$2), 1, IF(AND($H9 > Quartiles1!$B$2, $H9 <= Quartiles1!$B$3), 2, IF(AND($H9 > Quartiles1!$B$3, $H9 <= Quartiles1!$B$4), 3, 4))) -> 4 | J9: =I9*PCAWeights!$E$22 -> 0.83285286 | K9: 5 | L9: =IF(AND($K9 >= Quartiles1!$C$1, $K9 <= Quartiles1!$C$2), 1, IF(AND($K9 > Quartiles1!$C$2, $K9 <= Quartiles1!$C$3), 2, IF(AND($K9 > Quartiles1!$C$3, $K9 <= Quartiles1!$C$4), 3, 4))) -> 3 | M9: =L9*PCAWeights!$E$23 -> 0.7432727 | N9: 4 | O9: 4 | P9: =O9*PCAWeights!$E$24 -> 0.99970122 | Q9: =$D9+$G9+$J9+$M9+$P9 -> 3.3452848 | R9: =VLOOKUP($A9,'Star Score'!$A$2:$C$60,2,FALSE) -> 5 | S9: Lacy panicle | T9: White | U9: 44013 | V9: 44105 | W9: July - Oct | X9: 5 | Y9: 6 | Z9: Full sun to part shade | AA9: Medium high | AB9: N/A | AC9: Hydrangea paniculata | AE9: https://www.chicagobotanic.org/plantcollections/plantfinder/hydrangea_paniculata_brussels_lace--brussels_lace_panicle_hydrangea
A10: Candy Apple | B10: NA | E10: 0.9802899 | F10: =IF(AND($E10 >= Quartiles1!$A$1, $E10 <= Quartiles1!$A$2), 1, IF(AND($E10 > Quartiles1!$A$2, $E10 <= Quartiles1!$A$3), 2, IF(AND($E10 > Quartiles1!$A$3, $E10 <= Quartiles1!$A$4), 3, 4))) -> 3 | G10: =F10*PCAWeights!$E$21 -> 0.57709354 | H10: 16 | I10: =IF(AND($H10 >= Quartiles1!B$1, $H10 <= Quartiles1!$B$2), 1, IF(AND($H10 > Quartiles1!$B$2, $H10 <= Quartiles1!$B$3), 2, IF(AND($H10 > Quartiles1!$B$3, $H10 <= Quartiles1!$B$4), 3, 4))) -> 2 | J10: =I10*PCAWeights!$E$22 -> 0.41642643 | K10: 8 | L10: =IF(AND($K10 >= Quartiles1!$C$1, $K10 <= Quartiles1!$C$2), 1, IF(AND($K10 > Quartiles1!$C$2, $K10 <= Quartiles1!$C$3), 2, IF(AND($K10 > Quartiles1!$C$3, $K10 <= Quartiles1!$C$4), 3, 4))) -> 4 | M10: =L10*PCAWeights!$E$23 -> 0.99103027 | N10: 3 | O10: 2 | P10: =O10*PCAWeights!$E$24 -> 0.49985061 | Q10: =$D10+$G10+$J10+$M10+$P10 -> 2.4844009 | R10: =VLOOKUP($A10,'Star Score'!$A$2:$C$60,2,FALSE) -> 4 | S10: Mop-like panicle | T10: White | U10: 43983 | V10: 44136 | W10: June - Oct | X10: 5 | Y10: 5 | Z10: Full sun to full shade | AB10: N/A | AC10: Hydrangea paniculata | AD10: Days blooming 2019 data not available; used median | AE10: https://www.gertens.com/candy-apple-hydrangea
A11: Daimond Rogue | B11: 58 | C11: =IF(AND($B11 >= Quartiles1!$E$1, $B11 <= Quartiles1!$E$2), 1, IF(AND($B11 > Quartiles1!$E$2, $B11 <= Quartiles1!$E$3), 2, IF(AND($B11 > Quartiles1!$E$3, $B11 <= Quartiles1!$E$4), 3, 4))) -> 2 | D11: 0 | E11: 0.6516739 | F11: =IF(AND($E11 >= Quartiles1!$A$1, $E11 <= Quartiles1!$A$2), 1, IF(AND($E11 > Quartiles1!$A$2, $E11 <= Quartiles1!$A$3), 2, IF(AND($E11 > Quartiles1!$A$3, $E11 <= Quartiles1!$A$4), 3, 4))) -> 2 | G11: =F11*PCAWeights!$E$21 -> 0.38472903 | H11: 13 | I11: =IF(AND($H11 >= Quartiles1!B$1, $H11 <= Quartiles1!$B$2), 1, IF(AND($H11 > Quartiles1!$B$2, $H11 <= Quartiles1!$B$3), 2, IF(AND($H11 > Quartiles1!$B$3, $H11 <= Quartiles1!$B$4), 3, 4))) -> 2 | J11: =I11*PCAWeights!$E$22 -> 0.41642643 | K11: 4 | L11: =IF(AND($K11 >= Quartiles1!$C$1, $K11 <= Quartiles1!$C$2), 1, IF(AND($K11 > Quartiles1!$C$2, $K11 <= Quartiles1!$C$3), 2, IF(AND($K11 > Quartiles1!$C$3, $K11 <= Quartiles1!$C$4), 3, 4))) -> 2 | M11: =L11*PCAWeights!$E$23 -> 0.49551513 | N11: 3 | O11: 2 | P11: =O11*PCAWeights!$E$24 -> 0.49985061 | Q11: =$D11+$G11+$J11+$M11+$P11 -> 1.7965212 | R11: =VLOOKUP($A11,'Star Score'!$A$2:$C$60,2,FALSE) -> 2 | S11: Mop-like panicle | T11: Pink-white | W11: Aug - Oct | X11: 4 to 5 | Y11: 3 to 4 | Z11: Full sun to part shade | AB11: Easy | AC11: Hydrangea paniculata | AE11: https://firsteditionsplants.com/product/diamond-rouge-panicle-hydrangea/; https://www.gardenia.net/plant/hydrangea-paniculata-diamond-rouge
A12: Dharuma | B12: 458 | C12: =IF(AND($B12 >= Quartiles1!$E$1, $B12 <= Quartiles1!$E$2), 1, IF(AND($B12 > Quartiles1!$E$2, $B12 <= Quartiles1!$E$3), 2, IF(AND($B12 > Quartiles1!$E$3, $B12 <= Quartiles1!$E$4), 3, 4))) -> 4 | D12: 0 | E12: 0.8397249 | F12: =IF(AND($E12 >= Quartiles1!$A$1, $E12 <= Quartiles1!$A$2), 1, IF(AND($E12 > Quartiles1!$A$2, $E12 <= Quartiles1!$A$3), 2, IF(AND($E12 > Quartiles1!$A$3, $E12 <= Quartiles1!$A$4), 3, 4))) -> 2 | G12: =F12*PCAWeights!$E$21 -> 0.38472903 | H12: 43 | I12: =IF(AND($H12 >= Quartiles1!B$1, $H12 <= Quartiles1!$B$2), 1, IF(AND($H12 > Quartiles1!$B$2, $H12 <= Quartiles1!$B$3), 2, IF(AND($H12 > Quartiles1!$B$3, $H12 <= Quartiles1!$B$4), 3, 4))) -> 4 | J12: =I12*PCAWeights!$E$22 -> 0.83285286 | K12: 8 | L12: =IF(AND($K12 >= Quartiles1!$C$1, $K12 <= Quartiles1!$C$2), 1, IF(AND($K12 > Quartiles1!$C$2, $K12 <= Quartiles1!$C$3), 2, IF(AND($K12 > Quartiles1!$C$3, $K12 <= Quartiles1!$C$4), 3, 4))) -> 4 | M12: =L12*PCAWeights!$E$23 -> 0.99103027 | N12: 3 | O12: 2 | P12: =O12*PCAWeights!$E$24 -> 0.49985061 | Q12: =$D12+$G12+$J12+$M12+$P12 -> 2.7084628 | R12: =VLOOKUP($A12,'Star Score'!$A$2:$C$60,2,FALSE) -> 5 | S12: Lacy panicle | T12: White | U12: 44013 | V12: 44075 | W12: July - Sept | X12: 3 to 4 | Y12: 3 to 4 | Z12: Full sun to part shade | AA12: Medium | AB12: N/A | AC12: Hydrangea paniculata | AE12: https://www.northshoreplantclub.com/plant?id=7267
A13: Dolly | B13: 23 | C13: =IF(AND($B13 >= Quartiles1!$E$1, $B13 <= Quartiles1!$E$2), 1, IF(AND($B13 > Quartiles1!$E$2, $B13 <= Quartiles1!$E$3), 2, IF(AND($B13 > Quartiles1!$E$3, $B13 <= Quartiles1!$E$4), 3, 4))) -> 1 | D13: =-$J$61*0.125*2 -> -0.12792761 | E13: 1.2569249 | F13: =IF(AND($E13 >= Quartiles1!$A$1, $E13 <= Quartiles1!$A$2), 1, IF(AND($E13 > Quartiles1!$A$2, $E13 <= Quartiles1!$A$3), 2, IF(AND($E13 > Quartiles1!$A$3, $E13 <= Quartiles1!$A$4), 3, 4))) -> 4 | G13: =F13*PCAWeights!$E$21 -> 0.76945805 | H13: 25 | I13: =IF(AND($H13 >= Quartiles1!B$1, $H13 <= Quartiles1!$B$2), 1, IF(AND($H13 > Quartiles1!$B$2, $H13 <= Quartiles1!$B$3), 2, IF(AND($H13 > Quartiles1!$B$3, $H13 <= Quartiles1!$B$4), 3, 4))) -> 3 | J13: =I13*PCAWeights!$E$22 -> 0.62463965 | K13: 3 | L13: =IF(AND($K13 >= Quartiles1!$C$1, $K13 <= Quartiles1!$C$2), 1, IF(AND($K13 > Quartiles1!$C$2, $K13 <= Quartiles1!$C$3), 2, IF(AND($K13 > Quartiles1!$C$3, $K13 <= Quartiles1!$C$4), 3, 4))) -> 1 | M13: =L13*PCAWeights!$E$23 -> 0.24775757 | N13: 1 | O13: 1 | P13: =O13*PCAWeights!$E$24 -> 0.2499253 | Q13: =$D13+$G13+$J13+$M13+$P13 -> 1.763853 | R13: =VLOOKUP($A13,'Star Score'!$A$2:$C$60,2,FALSE) -> 2 | S13: Lacy panicle | T13: White | W13: Aug - Oct | X13: 5 to 8 | Y13: 5 to 8 | Z13: Full sun to partial shade | AC13: Hydrangea paniculata | AE13: https://www.rhs.org.uk/plants/177811/hydrangea-paniculata-dolly/details
A14: Early Evolution | B14: NA | E14: 0.1732868 | F14: =IF(AND($E14 >= Quartiles1!$A$1, $E14 <= Quartiles1!$A$2), 1, IF(AND($E14 > Quartiles1!$A$2, $E14 <= Quartiles1!$A$3), 2, IF(AND($E14 > Quartiles1!$A$3, $E14 <= Quartiles1!$A$4), 3, 4))) -> 1 | G14: =F14*PCAWeights!$E$21 -> 0.19236451 | H14: 1.5 | I14: =IF(AND($H14 >= Quartiles1!B$1, $H14 <= Quartiles1!$B$2), 1, IF(AND($H14 > Quartiles1!$B$2, $H14 <= Quartiles1!$B$3), 2, IF(AND($H14 > Quartiles1!$B$3, $H14 <= Quartiles1!$B$4), 3, 4))) -> 1 | J14: =I14*PCAWeights!$E$22 -> 0.20821322 | K14: 4 | L14: =IF(AND($K14 >= Quartiles1!$C$1, $K14 <= Quartiles1!$C$2), 1, IF(AND($K14 > Quartiles1!$C$2, $K14 <= Quartiles1!$C$3), 2, IF(AND($K14 > Quartiles1!$C$3, $K14 <= Quartiles1!$C$4), 3, 4))) -> 2 | M14: =L14*PCAWeights!$E$23 -> 0.49551513 | N14: 3 | O14: 2 | P14: =O14*PCAWeights!$E$24 -> 0.49985061 | Q14: =$D14+$G14+$J14+$M14+$P14 -> 1.3959435 | R14: =VLOOKUP($A14,'Star Score'!$A$2:$C$60,2,FALSE) -> 2 | S14: Lacy panicle | T14: Pink-white | W14: June - Nov | X14: 2 | Y14: 2 | Z14: Full sun to partial sun | AA14: Moist but well-drained | AB14: Easy | AC14: Hydrangea paniculata | AD14: Days blooming 2019 data not available; used median | AE14: https://www.waysidegardens.com/hydrangea-early-evolution-panicle-hydrangea-29895.html?srsltid=AfmBOoplMCVMM8O1mXoJVVWgNctuiqsXnHFi1Uw9h6XKAItY9-yi0uix
A15: Fire & Ice | B15: 129 | C15: =IF(AND($B15 >= Quartiles1!$E$1, $B15 <= Quartiles1!$E$2), 1, IF(AND($B15 > Quartiles1!$E$2, $B15 <= Quartiles1!$E$3), 2, IF(AND($B15 > Quartiles1!$E$3, $B15 <= Quartiles1!$E$4), 3, 4))) -> 3 | D15: =-$J$61*0.125*1 -> -0.063963806 | E15: 1.8356357 | F15: =IF(AND($E15 >= Quartiles1!$A$1, $E15 <= Quartiles1!$A$2), 1, IF(AND($E15 > Quartiles1!$A$2, $E15 <= Quartiles1!$A$3), 2, IF(AND($E15 > Quartiles1!$A$3, $E15 <= Quartiles1!$A$4), 3, 4))) -> 4 | G15: =F15*PCAWeights!$E$21 -> 0.76945805 | H15: 36 | I15: =IF(AND($H15 >= Quartiles1!B$1, $H15 <= Quartiles1!$B$2), 1, IF(AND($H15 > Quartiles1!$B$2, $H15 <= Quartiles1!$B$3), 2, IF(AND($H15 > Quartiles1!$B$3, $H15 <= Quartiles1!$B$4), 3, 4))) -> 4 | J15: =I15*PCAWeights!$E$22 -> 0.83285286 | K15: 3 | L15: =IF(AND($K15 >= Quartiles1!$C$1, $K15 <= Quartiles1!$C$2), 1, IF(AND($K15 > Quartiles1!$C$2, $K15 <= Quartiles1!$C$3), 2, IF(AND($K15 > Quartiles1!$C$3, $K15 <= Quartiles1!$C$4), 3, 4))) -> 1 | M15: =L15*PCAWeights!$E$23 -> 0.24775757 | N15: 1 | O15: 1 | P15: =O15*PCAWeights!$E$24 -> 0.2499253 | Q15: =$D15+$G15+$J15+$M15+$P15 -> 2.03603 | R15: =VLOOKUP($A15,'Star Score'!$A$2:$C$60,2,FALSE) -> 3 | S15: Lacy panicle | T15: Pink-white | W15: June - July | X15: 3 to 5 | Y15: 3 to 4 | Z15: Partial sun | AB15: Easy | AC15: Hydrangea paniculata | AE15: https://www.ballseed.com/PlantInfo/?phid=034001085020985
A16: Fire Light | B16: 19 | C16: =IF(AND($B16 >= Quartiles1!$E$1, $B16 <= Quartiles1!$E$2), 1, IF(AND($B16 > Quartiles1!$E$2, $B16 <= Quartiles1!$E$3), 2, IF(AND($B16 > Quartiles1!$E$3, $B16 <= Quartiles1!$E$4), 3, 4))) -> 1 | D16: =-$J$61*0.125*2 -> -0.12792761 | E16: 1.1404776 | F16: =IF(AND($E16 >= Quartiles1!$A$1, $E16 <= Quartiles1!$A$2), 1, IF(AND($E16 > Quartiles1!$A$2, $E16 <= Quartiles1!$A$3), 2, IF(AND($E16 > Quartiles1!$A$3, $E16 <= Quartiles1!$A$4), 3, 4))) -> 3 | G16: =F16*PCAWeights!$E$21 -> 0.57709354 | H16: 25 | I16: =IF(AND($H16 >= Quartiles1!B$1, $H16 <= Quartiles1!$B$2), 1, IF(AND($H16 > Quartiles1!$B$2, $H16 <= Quartiles1!$B$3), 2, IF(AND($H16 > Quartiles1!$B$3, $H16 <= Quartiles1!$B$4), 3, 4))) -> 3 | J16: =I16*PCAWeights!$E$22 -> 0.62463965 | K16: 15 | L16: =IF(AND($K16 >= Quartiles1!$C$1, $K16 <= Quartiles1!$C$2), 1, IF(AND($K16 > Quartiles1!$C$2, $K16 <= Quartiles1!$C$3), 2, IF(AND($K16 > Quartiles1!$C$3, $K16 <= Quartiles1!$C$4), 3, 4))) -> 4 | M16: =L16*PCAWeights!$E$23 -> 0.99103027 | N16: 1 | O16: 1 | P16: =O16*PCAWeights!$E$24 -> 0.2499253 | Q16: =$D16+$G16+$J16+$M16+$P16 -> 2.3147611 | R16: =VLOOKUP($A16,'Star Score'!$A$2:$C$60,2,FALSE) -> 4 | S16: Mop-like panicle | T16: Pink | U16: 44014 | V16: 44075 | W16: July - Sept | X16: 6 to 8 | Y16: 6 to 8 | Z16: Sun to part shade | AA16: N/A | AB16: N/A | AC16: Hydrangea paniculata | AE16: https://www.whiteflowerfarm.com/63163-product.html
A17: Floribunda | B17: 286 | C17: =IF(AND($B17 >= Quartiles1!$E$1, $B17 <= Quartiles1!$E$2), 1, IF(AND($B17 > Quartiles1!$E$2, $B17 <= Quartiles1!$E$3), 2, IF(AND($B17 > Quartiles1!$E$3, $B17 <= Quartiles1!$E$4), 3, 4))) -> 4 | D17: =-$J$61*0.125*1 -> -0.063963806 | E17: 1.1065032 | F17: =IF(AND($E17 >= Quartiles1!$A$1, $E17 <= Quartiles1!$A$2), 1, IF(AND($E17 > Quartiles1!$A$2, $E17 <= Quartiles1!$A$3), 2, IF(AND($E17 > Quartiles1!$A$3, $E17 <= Quartiles1!$A$4), 3, 4))) -> 3 | G17: =F17*PCAWeights!$E$21 -> 0.57709354 | H17: 19 | I17: =IF(AND($H17 >= Quartiles1!B$1, $H17 <= Quartiles1!$B$2), 1, IF(AND($H17 > Quartiles1!$B$2, $H17 <= Quartiles1!$B$3), 2, IF(AND($H17 > Quartiles1!$B$3, $H17 <= Quartiles1!$B$4), 3, 4))) -> 3 | J17: =I17*PCAWeights!$E$22 -> 0.62463965 | K17: 4 | L17: =IF(AND($K17 >= Quartiles1!$C$1, $K17 <= Quartiles1!$C$2), 1, IF(AND($K17 > Quartiles1!$C$2, $K17 <= Quartiles1!$C$3), 2, IF(AND($K17 > Quartiles1!$C$3, $K17 <= Quartiles1!$C$4), 3, 4))) -> 2 | M17: =L17*PCAWeights!$E$23 -> 0.49551513 | N17: 5 | O17: 4 | P17: =O17*PCAWeights!$E$24 -> 0.99970122 | Q17: =$D17+$G17+$J17+$M17+$P17 -> 2.6329857 | R17: =VLOOKUP($A17,'Star Score'!$A$2:$C$60,2,FALSE) -> 4 | S17: Lacy panicle | T17: White | U17: 44044 | V17: 44105 | W17: Aug - Oct | X17: 8 to 13 | Y17: 5 to 8 | Z17: Full sun to part shade | AA17: Moist but well-drained | AB17: N/A | AC17: Hydrangea paniculata | AE17: https://www.rhs.org.uk/plants/98580/hydrangea-paniculata-floribunda/details
