Workbook

Sheet README
A1: This is from the zero and one vacuumed cleaned richness page in Final Combined Dataset 3.xlsx
A2: We realized that though we could account for multiple individual plants of the same cultivar for abundance and diversity, richness doesn't work because plants with more individuals will have an unfair advantage.
A3: So I picked the most rigorous of each cultivar and removed duplicates so taht each cultivar was only shown by one plant
A5: Sheets Explained
A6: "Raw data duplicates removed" is the same raw data used originally for richness, but in this case we removed duplicate cultivars
A7: "Tracking duplicates sheet" tracks which individual plants were picked to represent
A8: "pivot table" is the pivot table of the raw data duplicates removed by individual plant (each representing one cultivar)
A9: "pivto table values" is the same pivot table but copied and pasted as values
A10: "present absent pivot table" is the pivot table converted into presence and absence instead of numbers using the "pivot table values" sheet
B11: I also summed the number of unique types of species or genera per plant in a column to get richness for that plant during htat season
A12: Vlookup | B12: base info on cultivar tags and details so that I can call in those details in the "present absent pivot table"
A13: "Keeping Track" keeps track of which individual plants were selected to be examples. When I had multiple plants in the same cultivar, I picked the healthiest-seeming one

Sheet DAgg4B
A1: Row Labels | B1: Cultivar | C1: Species | D1: Flower Type | E1: Inflorescence Type | F1: Insect Richness | G1: Sum of Dendryphantini (jumping spiders) | H1: Sum of Thomisidae | I1: Sum of Chauliognathus | J1: Sum of Cerambycidae | K1: Sum of Chrysomelidae | L1: Sum of Curculionidae | M1: Sum of Lampyridae | N1: Sum of Mordellidae | O1: Sum of Scarabaeoidea | P1: Sum of Diptera | Q1: Sum of Anthomyiidae | R1: Sum of Bombyliidae | S1: Sum of Calliphoridae | T1: Sum of Conopidae | U1: Sum of Cecidomyiidae | V1: Sum of Culicidae | W1: Sum of Dolichopodidae | X1: Sum of Drosophilidae | Y1: Sum of Empididae | Z1: Sum of Lonchaeidae | AA1: Sum of Muscidae | AB1: Sum of Polleniidae | AC1: Sum of Syrphidae (total) | AD1: Sum of Allograpta | AE1: Sum of Helophilus | AF1: Sum of Ocyptamus | AG1: Sum of Orthonevra | AH1: Sum of Parhelophilus | AI1: Sum of Parhelophilus integer | AJ1: Sum of Syrphidae | AK1: Sum of Syrphini | AL1: Sum of Syrphus | AM1: Sum of Toxomerus | AN1: Sum of Tachinidae | AO1: Sum of Tipulidae | AP1: Sum of Ulidiidae | AQ1: Sum of Hemiptera | AR1: Sum of Aphidinae | AS1: Sum of Cicadellidae | AT1: Sum of Miridae | AU1: Sum of Reduviidae | AV1: Sum of Hymenoptera | AW1: Sum of Andrena | AX1: Sum of Pseudopanurgus | AY1: Sum of Apis | AZ1: Sum of Ceratina | BA1: Sum of Melissodes | BB1: Sum of Triepeolus | BC1: Sum of Astata | BD1: Sum of Elampus | BE1: Sum of Hylaeus | BF1: Sum of Oxybelus | BG1: Sum of Halictidae | BH1: Sum of Agapostemon | BI1: Sum of Augochloropsis | BJ1: Sum of Augochlora OR Augochlorella | BK1: Sum of Augochlora | BL1: Sum of Augochlorella | BM1: Sum of Halictus | BN1: Sum of Lasioglossum | BO1: Sum of Symmorphus | BP1: Sum of Eurytoma | BQ1: Sum of Braconidae | BR1: Sum of Ichneumonidae | BS1: Sum of Scolia | BT1: Sum of Sphex pensylvanicus | BU1: Sum of Vespidae | BV1: Sum of Ancistrocerus | BW1: Sum of Dolichovespula | BX1: Sum of Polistes | BY1: Sum of Hesperiidae | BZ1: Sum of Limniphilidae
A2: 10C | B2: =VLOOKUP($A2,Vlookup!$A$2:$E$62,2,FALSE) -> Fire Light | C2: =VLOOKUP($A2,Vlookup!$A$2:$E$62,3,FALSE) -> Hydrangea paniculata | D2: =VLOOKUP($A2,Vlookup!$A$2:$E$62,4,FALSE) -> Mop-like panicle | E2: =VLOOKUP($A2,Vlookup!$A$2:$E$62,5,FALSE) -> Dense | F2: =SUM(G2:BZ2) -> 5 | G2: =IF('Pivot table values'!B2>0,1,0) -> 0 | H2: =IF('Pivot table values'!C2>0,1,0) -> 0 | I2: =IF('Pivot table values'!D2>0,1,0) -> 0 | J2: =IF('Pivot table values'!E2>0,1,0) -> 0 | K2: =IF('Pivot table values'!F2>0,1,0) -> 0 | L2: =IF('Pivot table values'!G2>0,1,0) -> 0 | M2: =IF('Pivot table values'!H2>0,1,0) -> 0 | N2: =IF('Pivot table values'!I2>0,1,0) -> 0 | ... BZ2: =IF('Pivot table values'!BU2>0,1,0) -> 0
A3: 10D | B3: =VLOOKUP($A3,Vlookup!$A$2:$E$62,2,FALSE) -> Daimond Rogue | C3: =VLOOKUP($A3,Vlookup!$A$2:$E$62,3,FALSE) -> Hydrangea paniculata | D3: =VLOOKUP($A3,Vlookup!$A$2:$E$62,4,FALSE) -> Mop-like panicle | E3: =VLOOKUP($A3,Vlookup!$A$2:$E$62,5,FALSE) -> Half-open | F3: =SUM(G3:BZ3) -> 7 | G3: =IF('Pivot table values'!B3>0,1,0) -> 0 | H3: =IF('Pivot table values'!C3>0,1,0) -> 0 | I3: =IF('Pivot table values'!D3>0,1,0) -> 0 | J3: =IF('Pivot table values'!E3>0,1,0) -> 0 | K3: =IF('Pivot table values'!F3>0,1,0) -> 0 | L3: =IF('Pivot table values'!G3>0,1,0) -> 0 | M3: =IF('Pivot table values'!H3>0,1,0) -> 0 | N3: =IF('Pivot table values'!I3>0,1,0) -> 0 | ... BZ3: =IF('Pivot table values'!BU3>0,1,0) -> 0
A4: 11C | B4: =VLOOKUP($A4,Vlookup!$A$2:$E$62,2,FALSE) -> Little Quick Fire | C4: =VLOOKUP($A4,Vlookup!$A$2:$E$62,3,FALSE) -> Hydrangea paniculata | D4: =VLOOKUP($A4,Vlookup!$A$2:$E$62,4,FALSE) -> Lacy panicle | E4: =VLOOKUP($A4,Vlookup!$A$2:$E$62,5,FALSE) -> Open | F4: =SUM(G4:BZ4) -> 7 | G4: =IF('Pivot table values'!B4>0,1,0) -> 0 | H4: =IF('Pivot table values'!C4>0,1,0) -> 0 | I4: =IF('Pivot table values'!D4>0,1,0) -> 0 | J4: =IF('Pivot table values'!E4>0,1,0) -> 0 | K4: =IF('Pivot table values'!F4>0,1,0) -> 0 | L4: =IF('Pivot table values'!G4>0,1,0) -> 0 | M4: =IF('Pivot table values'!H4>0,1,0) -> 0 | N4: =IF('Pivot table values'!I4>0,1,0) -> 0 | ... BZ4: =IF('Pivot table values'!BU4>0,1,0) -> 0
A5: 11D | B5: =VLOOKUP($A5,Vlookup!$A$2:$E$62,2,FALSE) -> Kyushu | C5: =VLOOKUP($A5,Vlookup!$A$2:$E$62,3,FALSE) -> Hydrangea paniculata | D5: =VLOOKUP($A5,Vlookup!$A$2:$E$62,4,FALSE) -> Lacy panicle | E5: =VLOOKUP($A5,Vlookup!$A$2:$E$62,5,FALSE) -> Open | F5: =SUM(G5:BZ5) -> 10 | G5: =IF('Pivot table values'!B5>0,1,0) -> 0 | H5: =IF('Pivot table values'!C5>0,1,0) -> 0 | I5: =IF('Pivot table values'!D5>0,1,0) -> 0 | J5: =IF('Pivot table values'!E5>0,1,0) -> 0 | K5: =IF('Pivot table values'!F5>0,1,0) -> 0 | L5: =IF('Pivot table values'!G5>0,1,0) -> 0 | M5: =IF('Pivot table values'!H5>0,1,0) -> 0 | N5: =IF('Pivot table values'!I5>0,1,0) -> 0 | ... BZ5: =IF('Pivot table values'!BU5>0,1,0) -> 0
A6: 11E | B6: =VLOOKUP($A6,Vlookup!$A$2:$E$62,2,FALSE) -> Seaside Serenade Bar Harbor | C6: =VLOOKUP($A6,Vlookup!$A$2:$E$62,3,FALSE) -> Hydrangea arborescens | D6: =VLOOKUP($A6,Vlookup!$A$2:$E$62,4,FALSE) -> Mop | E6: =VLOOKUP($A6,Vlookup!$A$2:$E$62,5,FALSE) -> Dense | F6: =SUM(G6:BZ6) -> 4 | G6: =IF('Pivot table values'!B6>0,1,0) -> 0 | H6: =IF('Pivot table values'!C6>0,1,0) -> 0 | I6: =IF('Pivot table values'!D6>0,1,0) -> 0 | J6: =IF('Pivot table values'!E6>0,1,0) -> 0 | K6: =IF('Pivot table values'!F6>0,1,0) -> 0 | L6: =IF('Pivot table values'!G6>0,1,0) -> 0 | M6: =IF('Pivot table values'!H6>0,1,0) -> 0 | N6: =IF('Pivot table values'!I6>0,1,0) -> 0 | ... BZ6: =IF('Pivot table values'!BU6>0,1,0) -> 0
A7: 11F | B7: =VLOOKUP($A7,Vlookup!$A$2:$E$62,2,FALSE) -> Invincibelle Ruby | C7: =VLOOKUP($A7,Vlookup!$A$2:$E$62,3,FALSE) -> Hydrangea arborescens | D7: =VLOOKUP($A7,Vlookup!$A$2:$E$62,4,FALSE) -> Mop | E7: =VLOOKUP($A7,Vlookup!$A$2:$E$62,5,FALSE) -> Very dense | F7: =SUM(G7:BZ7) -> 5 | G7: =IF('Pivot table values'!B7>0,1,0) -> 0 | H7: =IF('Pivot table values'!C7>0,1,0) -> 0 | I7: =IF('Pivot table values'!D7>0,1,0) -> 0 | J7: =IF('Pivot table values'!E7>0,1,0) -> 0 | K7: =IF('Pivot table values'!F7>0,1,0) -> 0 | L7: =IF('Pivot table values'!G7>0,1,0) -> 0 | M7: =IF('Pivot table values'!H7>0,1,0) -> 0 | N7: =IF('Pivot table values'!I7>0,1,0) -> 0 | ... BZ7: =IF('Pivot table values'!BU7>0,1,0) -> 0
A8: 12A | B8: =VLOOKUP($A8,Vlookup!$A$2:$E$62,2,FALSE) -> Candy Apple | C8: =VLOOKUP($A8,Vlookup!$A$2:$E$62,3,FALSE) -> Hydrangea paniculata | D8: =VLOOKUP($A8,Vlookup!$A$2:$E$62,4,FALSE) -> Mop-like panicle | E8: =VLOOKUP($A8,Vlookup!$A$2:$E$62,5,FALSE) -> Dense | F8: =SUM(G8:BZ8) -> 8 | G8: =IF('Pivot table values'!B8>0,1,0) -> 0 | H8: =IF('Pivot table values'!C8>0,1,0) -> 0 | I8: =IF('Pivot table values'!D8>0,1,0) -> 0 | J8: =IF('Pivot table values'!E8>0,1,0) -> 0 | K8: =IF('Pivot table values'!F8>0,1,0) -> 0 | L8: =IF('Pivot table values'!G8>0,1,0) -> 0 | M8: =IF('Pivot table values'!H8>0,1,0) -> 0 | N8: =IF('Pivot table values'!I8>0,1,0) -> 1 | ... BZ8: =IF('Pivot table values'!BU8>0,1,0) -> 0
A9: 12C | B9: =VLOOKUP($A9,Vlookup!$A$2:$E$62,2,FALSE) -> Polar Ball | C9: =VLOOKUP($A9,Vlookup!$A$2:$E$62,3,FALSE) -> Hydrangea paniculata | D9: =VLOOKUP($A9,Vlookup!$A$2:$E$62,4,FALSE) -> Mop-like panicle | E9: =VLOOKUP($A9,Vlookup!$A$2:$E$62,5,FALSE) -> Very dense | F9: =SUM(G9:BZ9) -> 8 | G9: =IF('Pivot table values'!B9>0,1,0) -> 0 | H9: =IF('Pivot table values'!C9>0,1,0) -> 0 | I9: =IF('Pivot table values'!D9>0,1,0) -> 0 | J9: =IF('Pivot table values'!E9>0,1,0) -> 0 | K9: =IF('Pivot table values'!F9>0,1,0) -> 0 | L9: =IF('Pivot table values'!G9>0,1,0) -> 0 | M9: =IF('Pivot table values'!H9>0,1,0) -> 0 | N9: =IF('Pivot table values'!I9>0,1,0) -> 0 | ... BZ9: =IF('Pivot table values'!BU9>0,1,0) -> 0
A10: 12D | B10: =VLOOKUP($A10,Vlookup!$A$2:$E$62,2,FALSE) -> Phantom | C10: =VLOOKUP($A10,Vlookup!$A$2:$E$62,3,FALSE) -> Hydrangea paniculata | D10: =VLOOKUP($A10,Vlookup!$A$2:$E$62,4,FALSE) -> Mop-like panicle | E10: =VLOOKUP($A10,Vlookup!$A$2:$E$62,5,FALSE) -> Half-open | F10: =SUM(G10:BZ10) -> 7 | G10: =IF('Pivot table values'!B10>0,1,0) -> 0 | H10: =IF('Pivot table values'!C10>0,1,0) -> 0 | I10: =IF('Pivot table values'!D10>0,1,0) -> 0 | J10: =IF('Pivot table values'!E10>0,1,0) -> 0 | K10: =IF('Pivot table values'!F10>0,1,0) -> 0 | L10: =IF('Pivot table values'!G10>0,1,0) -> 0 | M10: =IF('Pivot table values'!H10>0,1,0) -> 0 | N10: =IF('Pivot table values'!I10>0,1,0) -> 0 | ... BZ10: =IF('Pivot table values'!BU10>0,1,0) -> 0
A11: 12E | B11: =VLOOKUP($A11,Vlookup!$A$2:$E$62,2,FALSE) -> Invincibelle Mini Mauvette | C11: =VLOOKUP($A11,Vlookup!$A$2:$E$62,3,FALSE) -> Hydrangea arborescens | D11: =VLOOKUP($A11,Vlookup!$A$2:$E$62,4,FALSE) -> Mop | E11: =VLOOKUP($A11,Vlookup!$A$2:$E$62,5,FALSE) -> Dense | F11: =SUM(G11:BZ11) -> 2 | G11: =IF('Pivot table values'!B11>0,1,0) -> 0 | H11: =IF('Pivot table values'!C11>0,1,0) -> 0 | I11: =IF('Pivot table values'!D11>0,1,0) -> 0 | J11: =IF('Pivot table values'!E11>0,1,0) -> 0 | K11: =IF('Pivot table values'!F11>0,1,0) -> 0 | L11: =IF('Pivot table values'!G11>0,1,0) -> 0 | M11: =IF('Pivot table values'!H11>0,1,0) -> 0 | N11: =IF('Pivot table values'!I11>0,1,0) -> 0 | ... BZ11: =IF('Pivot table values'!BU11>0,1,0) -> 0
A12: 12F | B12: =VLOOKUP($A12,Vlookup!$A$2:$E$62,2,FALSE) -> White Dome | C12: =VLOOKUP($A12,Vlookup!$A$2:$E$62,3,FALSE) -> Hydrangea arborescens | D12: =VLOOKUP($A12,Vlookup!$A$2:$E$62,4,FALSE) -> Lacy | E12: =VLOOKUP($A12,Vlookup!$A$2:$E$62,5,FALSE) -> Open | F12: =SUM(G12:BZ12) -> 11 | G12: =IF('Pivot table values'!B12>0,1,0) -> 0 | H12: =IF('Pivot table values'!C12>0,1,0) -> 0 | I12: =IF('Pivot table values'!D12>0,1,0) -> 0 | J12: =IF('Pivot table values'!E12>0,1,0) -> 0 | K12: =IF('Pivot table values'!F12>0,1,0) -> 0 | L12: =IF('Pivot table values'!G12>0,1,0) -> 0 | M12: =IF('Pivot table values'!H12>0,1,0) -> 0 | N12: =IF('Pivot table values'!I12>0,1,0) -> 1 | ... BZ12: =IF('Pivot table values'!BU12>0,1,0) -> 0
A13: 13B | B13: =VLOOKUP($A13,Vlookup!$A$2:$E$62,2,FALSE) -> Pinky Winky | C13: =VLOOKUP($A13,Vlookup!$A$2:$E$62,3,FALSE) -> Hydrangea paniculata | D13: =VLOOKUP($A13,Vlookup!$A$2:$E$62,4,FALSE) -> Lacy panicle | E13: =VLOOKUP($A13,Vlookup!$A$2:$E$62,5,FALSE) -> Half-open | F13: =SUM(G13:BZ13) -> 5 | G13: =IF('Pivot table values'!B13>0,1,0) -> 0 | H13: =IF('Pivot table values'!C13>0,1,0) -> 0 | I13: =IF('Pivot table values'!D13>0,1,0) -> 0 | J13: =IF('Pivot table values'!E13>0,1,0) -> 0 | K13: =IF('Pivot table values'!F13>0,1,0) -> 0 | L13: =IF('Pivot table values'!G13>0,1,0) -> 0 | M13: =IF('Pivot table values'!H13>0,1,0) -> 0 | N13: =IF('Pivot table values'!I13>0,1,0) -> 0 | ... BZ13: =IF('Pivot table values'!BU13>0,1,0) -> 0
A14: 13D | B14: =VLOOKUP($A14,Vlookup!$A$2:$E$62,2,FALSE) -> Ruby | C14: =VLOOKUP($A14,Vlookup!$A$2:$E$62,3,FALSE) -> Hydrangea paniculata | D14: =VLOOKUP($A14,Vlookup!$A$2:$E$62,4,FALSE) -> Mop-like panicle | E14: =VLOOKUP($A14,Vlookup!$A$2:$E$62,5,FALSE) -> Half-open | F14: =SUM(G14:BZ14) -> 11 | G14: =IF('Pivot table values'!B15>0,1,0) -> 0 | H14: =IF('Pivot table values'!C15>0,1,0) -> 0 | I14: =IF('Pivot table values'!D15>0,1,0) -> 0 | J14: =IF('Pivot table values'!E15>0,1,0) -> 0 | K14: =IF('Pivot table values'!F15>0,1,0) -> 0 | L14: =IF('Pivot table values'!G15>0,1,0) -> 0 | M14: =IF('Pivot table values'!H15>0,1,0) -> 0 | N14: =IF('Pivot table values'!I15>0,1,0) -> 0 | ... BZ14: =IF('Pivot table values'!BU15>0,1,0) -> 0
A15: 15B | B15: =VLOOKUP($A15,Vlookup!$A$2:$E$62,2,FALSE) -> Zinfin Doll | C15: =VLOOKUP($A15,Vlookup!$A$2:$E$62,3,FALSE) -> Hydrangea paniculata | D15: =VLOOKUP($A15,Vlookup!$A$2:$E$62,4,FALSE) -> Mop-like panicle | E15: =VLOOKUP($A15,Vlookup!$A$2:$E$62,5,FALSE) -> Half-open | F15: =SUM(G15:BZ15) -> 5 | G15: =IF('Pivot table values'!B16>0,1,0) -> 0 | H15: =IF('Pivot table values'!C16>0,1,0) -> 0 | I15: =IF('Pivot table values'!D16>0,1,0) -> 0 | J15: =IF('Pivot table values'!E16>0,1,0) -> 0 | K15: =IF('Pivot table values'!F16>0,1,0) -> 0 | L15: =IF('Pivot table values'!G16>0,1,0) -> 0 | M15: =IF('Pivot table values'!H16>0,1,0) -> 0 | N15: =IF('Pivot table values'!I16>0,1,0) -> 0 | ... BZ15: =IF('Pivot table values'!BU16>0,1,0) -> 0
A16: 16B | B16: =VLOOKUP($A16,Vlookup!$A$2:$E$62,2,FALSE) -> Dolly | C16: =VLOOKUP($A16,Vlookup!$A$2:$E$62,3,FALSE) -> Hydrangea paniculata | D16: =VLOOKUP($A16,Vlookup!$A$2:$E$62,4,FALSE) -> Lacy panicle | E16: =VLOOKUP($A16,Vlookup!$A$2:$E$62,5,FALSE) -> Dense | F16: =SUM(G16:BZ16) -> 9 | G16: =IF('Pivot table values'!B17>0,1,0) -> 0 | H16: =IF('Pivot table values'!C17>0,1,0) -> 0 | I16: =IF('Pivot table values'!D17>0,1,0) -> 0 | J16: =IF('Pivot table values'!E17>0,1,0) -> 0 | K16: =IF('Pivot table values'!F17>0,1,0) -> 0 | L16: =IF('Pivot table values'!G17>0,1,0) -> 0 | M16: =IF('Pivot table values'!H17>0,1,0) -> 0 | N16: =IF('Pivot table values'!I17>0,1,0) -> 0 | ... BZ16: =IF('Pivot table values'!BU17>0,1,0) -> 0
A17: 16D | B17: =VLOOKUP($A17,Vlookup!$A$2:$E$62,2,FALSE) -> Green Spire | C17: =VLOOKUP($A17,Vlookup!$A$2:$E$62,3,FALSE) -> Hydrangea paniculata | D17: =VLOOKUP($A17,Vlookup!$A$2:$E$62,4,FALSE) -> Lacy panicle | E17: =VLOOKUP($A17,Vlookup!$A$2:$E$62,5,FALSE) -> Open | F17: =SUM(G17:BZ17) -> 4 | G17: =IF('Pivot table values'!B19>0,1,0) -> 0 | H17: =IF('Pivot table values'!C19>0,1,0) -> 0 | I17: =IF('Pivot table values'!D19>0,1,0) -> 0 | J17: =IF('Pivot table values'!E19>0,1,0) -> 0 | K17: =IF('Pivot table values'!F19>0,1,0) -> 0 | L17: =IF('Pivot table values'!G19>0,1,0) -> 0 | M17: =IF('Pivot table values'!H19>0,1,0) -> 0 | N17: =IF('Pivot table values'!I19>0,1,0) -> 0 | ... BZ17: =IF('Pivot table values'!BU19>0,1,0) -> 0
A18: 17D | B18: =VLOOKUP($A18,Vlookup!$A$2:$E$62,2,FALSE) -> Pink Lady | C18: =VLOOKUP($A18,Vlookup!$A$2:$E$62,3,FALSE) -> Hydrangea paniculata | D18: =VLOOKUP($A18,Vlookup!$A$2:$E$62,4,FALSE) -> Mop-like panicle | E18: =VLOOKUP($A18,Vlookup!$A$2:$E$62,5,FALSE) -> Dense | F18: =SUM(G18:BZ18) -> 8 | G18: =IF('Pivot table values'!B20>0,1,0) -> 0 | H18: =IF('Pivot table values'!C20>0,1,0) -> 0 | I18: =IF('Pivot table values'!D20>0,1,0) -> 0 | J18: =IF('Pivot table values'!E20>0,1,0) -> 0 | K18: =IF('Pivot table values'!F20>0,1,0) -> 0 | L18: =IF('Pivot table values'!G20>0,1,0) -> 0 | M18: =IF('Pivot table values'!H20>0,1,0) -> 0 | N18: =IF('Pivot table values'!I20>0,1,0) -> 0 | ... BZ18: =IF('Pivot table values'!BU20>0,1,0) -> 0
A19: 18D | B19: =VLOOKUP($A19,Vlookup!$A$2:$E$62,2,FALSE) -> Bobo | C19: =VLOOKUP($A19,Vlookup!$A$2:$E$62,3,FALSE) -> Hydrangea paniculata | D19: =VLOOKUP($A19,Vlookup!$A$2:$E$62,4,FALSE) -> Mop-like panicle | E19: =VLOOKUP($A19,Vlookup!$A$2:$E$62,5,FALSE) -> Half-open | F19: =SUM(G19:BZ19) -> 10 | G19: =IF('Pivot table values'!B21>0,1,0) -> 0 | H19: =IF('Pivot table values'!C21>0,1,0) -> 0 | I19: =IF('Pivot table values'!D21>0,1,0) -> 0 | J19: =IF('Pivot table values'!E21>0,1,0) -> 0 | K19: =IF('Pivot table values'!F21>0,1,0) -> 0 | L19: =IF('Pivot table values'!G21>0,1,0) -> 0 | M19: =IF('Pivot table values'!H21>0,1,0) -> 0 | N19: =IF('Pivot table values'!I21>0,1,0) -> 1 | ... BZ19: =IF('Pivot table values'!BU21>0,1,0) -> 0
A20: 19D | B20: =VLOOKUP($A20,Vlookup!$A$2:$E$62,2,FALSE) -> Puffer Fish | C20: =VLOOKUP($A20,Vlookup!$A$2:$E$62,3,FALSE) -> Hydrangea paniculata | D20: =VLOOKUP($A20,Vlookup!$A$2:$E$62,4,FALSE) -> Mop-like panicle | E20: =VLOOKUP($A20,Vlookup!$A$2:$E$62,5,FALSE) -> Half-open | F20: =SUM(G20:BZ20) -> 10 | G20: =IF('Pivot table values'!B22>0,1,0) -> 0 | H20: =IF('Pivot table values'!C22>0,1,0) -> 0 | I20: =IF('Pivot table values'!D22>0,1,0) -> 0 | J20: =IF('Pivot table values'!E22>0,1,0) -> 0 | K20: =IF('Pivot table values'!F22>0,1,0) -> 0 | L20: =IF('Pivot table values'!G22>0,1,0) -> 0 | M20: =IF('Pivot table values'!H22>0,1,0) -> 0 | N20: =IF('Pivot table values'!I22>0,1,0) -> 0 | ... BZ20: =IF('Pivot table values'!BU22>0,1,0) -> 0
A21: 1A | B21: =VLOOKUP($A21,Vlookup!$A$2:$E$62,2,FALSE) -> Strawberry Shake | C21: =VLOOKUP($A21,Vlookup!$A$2:$E$62,3,FALSE) -> Hydrangea paniculata | D21: =VLOOKUP($A21,Vlookup!$A$2:$E$62,4,FALSE) -> Mop-like panicle | E21: =VLOOKUP($A21,Vlookup!$A$2:$E$62,5,FALSE) -> Very dense | F21: =SUM(G21:BZ21) -> 9 | G21: =IF('Pivot table values'!B23>0,1,0) -> 0 | H21: =IF('Pivot table values'!C23>0,1,0) -> 0 | I21: =IF('Pivot table values'!D23>0,1,0) -> 0 | J21: =IF('Pivot table values'!E23>0,1,0) -> 0 | K21: =IF('Pivot table values'!F23>0,1,0) -> 0 | L21: =IF('Pivot table values'!G23>0,1,0) -> 0 | M21: =IF('Pivot table values'!H23>0,1,0) -> 0 | N21: =IF('Pivot table values'!I23>0,1,0) -> 0 | ... BZ21: =IF('Pivot table values'!BU23>0,1,0) -> 0
A22: 1C | B22: =VLOOKUP($A22,Vlookup!$A$2:$E$62,2,FALSE) -> Angel's Blush | C22: =VLOOKUP($A22,Vlookup!$A$2:$E$62,3,FALSE) -> Hydrangea paniculata | D22: =VLOOKUP($A22,Vlookup!$A$2:$E$62,4,FALSE) -> Lacy panicle | E22: =VLOOKUP($A22,Vlookup!$A$2:$E$62,5,FALSE) -> Unknown | F22: =SUM(G22:BZ22) -> 5 | G22: =IF('Pivot table values'!B24>0,1,0) -> 0 | H22: =IF('Pivot table values'!C24>0,1,0) -> 0 | I22: =IF('Pivot table values'!D24>0,1,0) -> 0 | J22: =IF('Pivot table values'!E24>0,1,0) -> 0 | K22: =IF('Pivot table values'!F24>0,1,0) -> 0 | L22: =IF('Pivot table values'!G24>0,1,0) -> 0 | M22: =IF('Pivot table values'!H24>0,1,0) -> 0 | N22: =IF('Pivot table values'!I24>0,1,0) -> 0 | ... BZ22: =IF('Pivot table values'!BU24>0,1,0) -> 0
A23: 1D | B23: =VLOOKUP($A23,Vlookup!$A$2:$E$62,2,FALSE) -> Floribunda | C23: =VLOOKUP($A23,Vlookup!$A$2:$E$62,3,FALSE) -> Hydrangea paniculata | D23: =VLOOKUP($A23,Vlookup!$A$2:$E$62,4,FALSE) -> Lacy panicle | E23: =VLOOKUP($A23,Vlookup!$A$2:$E$62,5,FALSE) -> Open | F23: =SUM(G23:BZ23) -> 7 | G23: =IF('Pivot table values'!B25>0,1,0) -> 0 | H23: =IF('Pivot table values'!C25>0,1,0) -> 0 | I23: =IF('Pivot table values'!D25>0,1,0) -> 1 | J23: =IF('Pivot table values'!E25>0,1,0) -> 0 | K23: =IF('Pivot table values'!F25>0,1,0) -> 0 | L23: =IF('Pivot table values'!G25>0,1,0) -> 1 | M23: =IF('Pivot table values'!H25>0,1,0) -> 0 | N23: =IF('Pivot table values'!I25>0,1,0) -> 0 | ... BZ23: =IF('Pivot table values'!BU25>0,1,0) -> 0
A24: 20D | B24: =VLOOKUP($A24,Vlookup!$A$2:$E$62,2,FALSE) -> Early Evolution | C24: =VLOOKUP($A24,Vlookup!$A$2:$E$62,3,FALSE) -> Hydrangea paniculata | D24: =VLOOKUP($A24,Vlookup!$A$2:$E$62,4,FALSE) -> Lacy panicle | E24: =VLOOKUP($A24,Vlookup!$A$2:$E$62,5,FALSE) -> Dense | F24: =SUM(G24:BZ24) -> 2 | G24: =IF('Pivot table values'!B26>0,1,0) -> 0 | H24: =IF('Pivot table values'!C26>0,1,0) -> 0 | I24: =IF('Pivot table values'!D26>0,1,0) -> 0 | J24: =IF('Pivot table values'!E26>0,1,0) -> 0 | K24: =IF('Pivot table values'!F26>0,1,0) -> 0 | L24: =IF('Pivot table values'!G26>0,1,0) -> 0 | M24: =IF('Pivot table values'!H26>0,1,0) -> 0 | N24: =IF('Pivot table values'!I26>0,1,0) -> 0 | ... BZ24: =IF('Pivot table values'!BU26>0,1,0) -> 0
A25: 22B | B25: =VLOOKUP($A25,Vlookup!$A$2:$E$62,2,FALSE) -> Limelight Prime | C25: =VLOOKUP($A25,Vlookup!$A$2:$E$62,3,FALSE) -> Hydrangea paniculata | D25: =VLOOKUP($A25,Vlookup!$A$2:$E$62,4,FALSE) -> Mop-like panicle | E25: =VLOOKUP($A25,Vlookup!$A$2:$E$62,5,FALSE) -> Half-open | F25: =SUM(G25:BZ25) -> 5 | G25: =IF('Pivot table values'!B27>0,1,0) -> 0 | H25: =IF('Pivot table values'!C27>0,1,0) -> 0 | I25: =IF('Pivot table values'!D27>0,1,0) -> 0 | J25: =IF('Pivot table values'!E27>0,1,0) -> 0 | K25: =IF('Pivot table values'!F27>0,1,0) -> 0 | L25: =IF('Pivot table values'!G27>0,1,0) -> 0 | M25: =IF('Pivot table values'!H27>0,1,0) -> 0 | N25: =IF('Pivot table values'!I27>0,1,0) -> 0 | ... BZ25: =IF('Pivot table values'!BU27>0,1,0) -> 0
A26: 26B | B26: =VLOOKUP($A26,Vlookup!$A$2:$E$62,2,FALSE) -> Berry White | C26: =VLOOKUP($A26,Vlookup!$A$2:$E$62,3,FALSE) -> Hydrangea paniculata | D26: =VLOOKUP($A26,Vlookup!$A$2:$E$62,4,FALSE) -> Mop-like panicle | E26: =VLOOKUP($A26,Vlookup!$A$2:$E$62,5,FALSE) -> Half-open | F26: =SUM(G26:BZ26) -> 6 | G26: =IF('Pivot table values'!B28>0,1,0) -> 0 | H26: =IF('Pivot table values'!C28>0,1,0) -> 0 | I26: =IF('Pivot table values'!D28>0,1,0) -> 0 | J26: =IF('Pivot table values'!E28>0,1,0) -> 0 | K26: =IF('Pivot table values'!F28>0,1,0) -> 0 | L26: =IF('Pivot table values'!G28>0,1,0) -> 0 | M26: =IF('Pivot table values'!H28>0,1,0) -> 0 | N26: =IF('Pivot table values'!I28>0,1,0) -> 0 | ... BZ26: =IF('Pivot table values'!BU28>0,1,0) -> 0
A27: 2A | B27: =VLOOKUP($A27,Vlookup!$A$2:$E$62,2,FALSE) -> Baby Lace | C27: =VLOOKUP($A27,Vlookup!$A$2:$E$62,3,FALSE) -> Hydrangea paniculata | D27: =VLOOKUP($A27,Vlookup!$A$2:$E$62,4,FALSE) -> Lacy panicle | E27: =VLOOKUP($A27,Vlookup!$A$2:$E$62,5,FALSE) -> Open | F27: =SUM(G27:BZ27) -> 2 | G27: =IF('Pivot table values'!B30>0,1,0) -> 0 | H27: =IF('Pivot table values'!C30>0,1,0) -> 0 | I27: =IF('Pivot table values'!D30>0,1,0) -> 0 | J27: =IF('Pivot table values'!E30>0,1,0) -> 0 | K27: =IF('Pivot table values'!F30>0,1,0) -> 0 | L27: =IF('Pivot table values'!G30>0,1,0) -> 0 | M27: =IF('Pivot table values'!H30>0,1,0) -> 0 | N27: =IF('Pivot table values'!I30>0,1,0) -> 0 | ... BZ27: =IF('Pivot table values'!BU30>0,1,0) -> 0
A28: 2D | B28: =VLOOKUP($A28,Vlookup!$A$2:$E$62,2,FALSE) -> Little Lime | C28: =VLOOKUP($A28,Vlookup!$A$2:$E$62,3,FALSE) -> Hydrangea paniculata | D28: =VLOOKUP($A28,Vlookup!$A$2:$E$62,4,FALSE) -> Mop-like panicle | E28: =VLOOKUP($A28,Vlookup!$A$2:$E$62,5,FALSE) -> Very dense | F28: =SUM(G28:BZ28) -> 5 | G28: =IF('Pivot table values'!B31>0,1,0) -> 0 | H28: =IF('Pivot table values'!C31>0,1,0) -> 0 | I28: =IF('Pivot table values'!D31>0,1,0) -> 0 | J28: =IF('Pivot table values'!E31>0,1,0) -> 0 | K28: =IF('Pivot table values'!F31>0,1,0) -> 1 | L28: =IF('Pivot table values'!G31>0,1,0) -> 1 | M28: =IF('Pivot table values'!H31>0,1,0) -> 0 | N28: =IF('Pivot table values'!I31>0,1,0) -> 0 | ... BZ28: =IF('Pivot table values'!BU31>0,1,0) -> 0
A29: 2F | B29: =VLOOKUP($A29,Vlookup!$A$2:$E$62,2,FALSE) -> Silver Leaf | C29: =VLOOKUP($A29,Vlookup!$A$2:$E$62,3,FALSE) -> Hydrangea arborescens | D29: =VLOOKUP($A29,Vlookup!$A$2:$E$62,4,FALSE) -> Lacy | E29: =VLOOKUP($A29,Vlookup!$A$2:$E$62,5,FALSE) -> Open | F29: =SUM(G29:BZ29) -> 13 | G29: =IF('Pivot table values'!B32>0,1,0) -> 0 | H29: =IF('Pivot table values'!C32>0,1,0) -> 0 | I29: =IF('Pivot table values'!D32>0,1,0) -> 0 | J29: =IF('Pivot table values'!E32>0,1,0) -> 0 | K29: =IF('Pivot table values'!F32>0,1,0) -> 0 | L29: =IF('Pivot table values'!G32>0,1,0) -> 0 | M29: =IF('Pivot table values'!H32>0,1,0) -> 1 | N29: =IF('Pivot table values'!I32>0,1,0) -> 1 | ... BZ29: =IF('Pivot table values'!BU32>0,1,0) -> 0
A30: 3A | B30: =VLOOKUP($A30,Vlookup!$A$2:$E$62,2,FALSE) -> Sweet Summer | C30: =VLOOKUP($A30,Vlookup!$A$2:$E$62,3,FALSE) -> Hydrangea paniculata | D30: =VLOOKUP($A30,Vlookup!$A$2:$E$62,4,FALSE) -> Mop-like panicle | E30: =VLOOKUP($A30,Vlookup!$A$2:$E$62,5,FALSE) -> Dense | F30: =SUM(G30:BZ30) -> 13 | G30: =IF('Pivot table values'!B33>0,1,0) -> 0 | H30: =IF('Pivot table values'!C33>0,1,0) -> 0 | I30: =IF('Pivot table values'!D33>0,1,0) -> 0 | J30: =IF('Pivot table values'!E33>0,1,0) -> 0 | K30: =IF('Pivot table values'!F33>0,1,0) -> 0 | L30: =IF('Pivot table values'!G33>0,1,0) -> 0 | M30: =IF('Pivot table values'!H33>0,1,0) -> 0 | N30: =IF('Pivot table values'!I33>0,1,0) -> 0 | ... BZ30: =IF('Pivot table values'!BU33>0,1,0) -> 1
A31: 3D | B31: =VLOOKUP($A31,Vlookup!$A$2:$E$62,2,FALSE) -> Vanilla Strawberry | C31: =VLOOKUP($A31,Vlookup!$A$2:$E$62,3,FALSE) -> Hydrangea paniculata | D31: =VLOOKUP($A31,Vlookup!$A$2:$E$62,4,FALSE) -> Mop-like panicle | E31: =VLOOKUP($A31,Vlookup!$A$2:$E$62,5,FALSE) -> Dense | F31: =SUM(G31:BZ31) -> 19 | G31: =IF('Pivot table values'!B34>0,1,0) -> 1 | H31: =IF('Pivot table values'!C34>0,1,0) -> 0 | I31: =IF('Pivot table values'!D34>0,1,0) -> 1 | J31: =IF('Pivot table values'!E34>0,1,0) -> 0 | K31: =IF('Pivot table values'!F34>0,1,0) -> 1 | L31: =IF('Pivot table values'!G34>0,1,0) -> 1 | M31: =IF('Pivot table values'!H34>0,1,0) -> 0 | N31: =IF('Pivot table values'!I34>0,1,0) -> 0 | ... BZ31: =IF('Pivot table values'!BU34>0,1,0) -> 0
A32: 3E | B32: =VLOOKUP($A32,Vlookup!$A$2:$E$62,2,FALSE) -> Bounty | C32: =VLOOKUP($A32,Vlookup!$A$2:$E$62,3,FALSE) -> Hydrangea arborescens | D32: =VLOOKUP($A32,Vlookup!$A$2:$E$62,4,FALSE) -> Mop | E32: =VLOOKUP($A32,Vlookup!$A$2:$E$62,5,FALSE) -> Half-open | F32: =SUM(G32:BZ32) -> 4 | G32: =IF('Pivot table values'!B35>0,1,0) -> 0 | H32: =IF('Pivot table values'!C35>0,1,0) -> 0 | I32: =IF('Pivot table values'!D35>0,1,0) -> 0 | J32: =IF('Pivot table values'!E35>0,1,0) -> 0 | K32: =IF('Pivot table values'!F35>0,1,0) -> 0 | L32: =IF('Pivot table values'!G35>0,1,0) -> 0 | M32: =IF('Pivot table values'!H35>0,1,0) -> 0 | N32: =IF('Pivot table values'!I35>0,1,0) -> 0 | ... BZ32: =IF('Pivot table values'!BU35>0,1,0) -> 0
A33: 4A | B33: =VLOOKUP($A33,Vlookup!$A$2:$E$62,2,FALSE) -> White Diamonds | C33: =VLOOKUP($A33,Vlookup!$A$2:$E$62,3,FALSE) -> Hydrangea paniculata | D33: =VLOOKUP($A33,Vlookup!$A$2:$E$62,4,FALSE) -> Mop-like panicle | E33: =VLOOKUP($A33,Vlookup!$A$2:$E$62,5,FALSE) -> Half-open | F33: =SUM(G33:BZ33) -> 15 | G33: =IF('Pivot table values'!B36>0,1,0) -> 0 | H33: =IF('Pivot table values'!C36>0,1,0) -> 0 | I33: =IF('Pivot table values'!D36>0,1,0) -> 0 | J33: =IF('Pivot table values'!E36>0,1,0) -> 0 | K33: =IF('Pivot table values'!F36>0,1,0) -> 1 | L33: =IF('Pivot table values'!G36>0,1,0) -> 0 | M33: =IF('Pivot table values'!H36>0,1,0) -> 0 | N33: =IF('Pivot table values'!I36>0,1,0) -> 1 | ... BZ33: =IF('Pivot table values'!BU36>0,1,0) -> 0
A34: 4C | B34: =VLOOKUP($A34,Vlookup!$A$2:$E$62,2,FALSE) -> Little Lamb | C34: =VLOOKUP($A34,Vlookup!$A$2:$E$62,3,FALSE) -> Hydrangea paniculata | D34: =VLOOKUP($A34,Vlookup!$A$2:$E$62,4,FALSE) -> Mop-like panicle | E34: =VLOOKUP($A34,Vlookup!$A$2:$E$62,5,FALSE) -> Very dense | F34: =SUM(G34:BZ34) -> 9 | G34: =IF('Pivot table values'!B37>0,1,0) -> 0 | H34: =IF('Pivot table values'!C37>0,1,0) -> 0 | I34: =IF('Pivot table values'!D37>0,1,0) -> 0 | J34: =IF('Pivot table values'!E37>0,1,0) -> 0 | K34: =IF('Pivot table values'!F37>0,1,0) -> 0 | L34: =IF('Pivot table values'!G37>0,1,0) -> 0 | M34: =IF('Pivot table values'!H37>0,1,0) -> 0 | N34: =IF('Pivot table values'!I37>0,1,0) -> 0 | ... BZ34: =IF('Pivot table values'!BU37>0,1,0) -> 0
A35: 4D | B35: =VLOOKUP($A35,Vlookup!$A$2:$E$62,2,FALSE) -> Great Star | C35: =VLOOKUP($A35,Vlookup!$A$2:$E$62,3,FALSE) -> Hydrangea paniculata | D35: =VLOOKUP($A35,Vlookup!$A$2:$E$62,4,FALSE) -> Lacy panicle | E35: =VLOOKUP($A35,Vlookup!$A$2:$E$62,5,FALSE) -> Very dense | F35: =SUM(G35:BZ35) -> 6 | G35: =IF('Pivot table values'!B38>0,1,0) -> 0 | H35: =IF('Pivot table values'!C38>0,1,0) -> 0 | I35: =IF('Pivot table values'!D38>0,1,0) -> 0 | J35: =IF('Pivot table values'!E38>0,1,0) -> 0 | K35: =IF('Pivot table values'!F38>0,1,0) -> 0 | L35: =IF('Pivot table values'!G38>0,1,0) -> 0 | M35: =IF('Pivot table values'!H38>0,1,0) -> 0 | N35: =IF('Pivot table values'!I38>0,1,0) -> 0 | ... BZ35: =IF('Pivot table values'!BU38>0,1,0) -> 0
A36: 4E | B36: =VLOOKUP($A36,Vlookup!$A$2:$E$62,2,FALSE) -> Hayes Starburst | C36: =VLOOKUP($A36,Vlookup!$A$2:$E$62,3,FALSE) -> Hydrangea arborescens | D36: =VLOOKUP($A36,Vlookup!$A$2:$E$62,4,FALSE) -> Mop | E36: =VLOOKUP($A36,Vlookup!$A$2:$E$62,5,FALSE) -> Very dense | F36: =SUM(G36:BZ36) -> 1 | G36: =IF('Pivot table values'!B39>0,1,0) -> 0 | H36: =IF('Pivot table values'!C39>0,1,0) -> 0 | I36: =IF('Pivot table values'!D39>0,1,0) -> 0 | J36: =IF('Pivot table values'!E39>0,1,0) -> 0 | K36: =IF('Pivot table values'!F39>0,1,0) -> 0 | L36: =IF('Pivot table values'!G39>0,1,0) -> 0 | M36: =IF('Pivot table values'!H39>0,1,0) -> 0 | N36: =IF('Pivot table values'!I39>0,1,0) -> 0 | ... BZ36: =IF('Pivot table values'!BU39>0,1,0) -> 0
A37: 4F | B37: =VLOOKUP($A37,Vlookup!$A$2:$E$62,2,FALSE) -> Haas Halo | C37: =VLOOKUP($A37,Vlookup!$A$2:$E$62,3,FALSE) -> Hydrangea arborescens | D37: =VLOOKUP($A37,Vlookup!$A$2:$E$62,4,FALSE) -> Lacy | E37: =VLOOKUP($A37,Vlookup!$A$2:$E$62,5,FALSE) -> Open | F37: =SUM(G37:BZ37) -> 11 | G37: =IF('Pivot table values'!B40>0,1,0) -> 0 | H37: =IF('Pivot table values'!C40>0,1,0) -> 0 | I37: =IF('Pivot table values'!D40>0,1,0) -> 1 | J37: =IF('Pivot table values'!E40>0,1,0) -> 1 | K37: =IF('Pivot table values'!F40>0,1,0) -> 0 | L37: =IF('Pivot table values'!G40>0,1,0) -> 0 | M37: =IF('Pivot table values'!H40>0,1,0) -> 0 | N37: =IF('Pivot table values'!I40>0,1,0) -> 0 | ... BZ37: =IF('Pivot table values'!BU40>0,1,0) -> 0
A38: 5A | B38: =VLOOKUP($A38,Vlookup!$A$2:$E$62,2,FALSE) -> Quick Fire | C38: =VLOOKUP($A38,Vlookup!$A$2:$E$62,3,FALSE) -> Hydrangea paniculata | D38: =VLOOKUP($A38,Vlookup!$A$2:$E$62,4,FALSE) -> Lacy panicle | E38: =VLOOKUP($A38,Vlookup!$A$2:$E$62,5,FALSE) -> Open | F38: =SUM(G38:BZ38) -> 11 | G38: =IF('Pivot table values'!B41>0,1,0) -> 0 | H38: =IF('Pivot table values'!C41>0,1,0) -> 0 | I38: =IF('Pivot table values'!D41>0,1,0) -> 0 | J38: =IF('Pivot table values'!E41>0,1,0) -> 0 | K38: =IF('Pivot table values'!F41>0,1,0) -> 0 | L38: =IF('Pivot table values'!G41>0,1,0) -> 0 | M38: =IF('Pivot table values'!H41>0,1,0) -> 0 | N38: =IF('Pivot table values'!I41>0,1,0) -> 0 | ... BZ38: =IF('Pivot table values'!BU41>0,1,0) -> 0
... A54: 9F | B54: =VLOOKUP($A54,Vlookup!$A$2:$E$62,2,FALSE) -> Incrediball | C54: =VLOOKUP($A54,Vlookup!$A$2:$E$62,3,FALSE) -> Hydrangea arborescens | D54: =VLOOKUP($A54,Vlookup!$A$2:$E$62,4,FALSE) -> Mop | E54: =VLOOKUP($A54,Vlookup!$A$2:$E$62,5,FALSE) -> Dense | F54: =SUM(G54:BZ54) -> 5 | G54: =IF('Pivot table values'!B57>0,1,0) -> 0 | H54: =IF('Pivot table values'!C57>0,1,0) -> 0 | I54: =IF('Pivot table values'!D57>0,1,0) -> 0 | J54: =IF('Pivot table values'!E57>0,1,0) -> 0 | K54: =IF('Pivot table values'!F57>0,1,0) -> 0 | L54: =IF('Pivot table values'!G57>0,1,0) -> 0 | M54: =IF('Pivot table values'!H57>0,1,0) -> 0 | N54: =IF('Pivot table values'!I57>0,1,0) -> 0 | ... BZ54: =IF('Pivot table values'!BU57>0,1,0) -> 0
A55: (blank) | F55: =SUM(G55:BZ55) -> 0 | G55: =IF('Pivot table values'!B59>0,1,0) -> 0 | H55: =IF('Pivot table values'!C59>0,1,0) -> 0 | I55: =IF('Pivot table values'!D59>0,1,0) -> 0 | J55: =IF('Pivot table values'!E59>0,1,0) -> 0 | K55: =IF('Pivot table values'!F59>0,1,0) -> 0 | L55: =IF('Pivot table values'!G59>0,1,0) -> 0 | M55: =IF('Pivot table values'!H59>0,1,0) -> 0 | N55: =IF('Pivot table values'!I59>0,1,0) -> 0 | ... BZ55: =IF('Pivot table values'!BU59>0,1,0) -> 0
...

Sheet Vlookup
A1: Tag number | B1: Cultivar | C1: Species | D1: Flower Type | E1: Inflorescence Type
A2: 5E | B2: Annabelle | C2: Hydrangea arborescens | D2: Mop | E2: Dense
A3: 1C | B3: Angel's Blush | C3: Hydrangea paniculata | D3: Lacy panicle | E3: Unknown
A4: 2A | B4: Baby Lace | C4: Hydrangea paniculata | D4: Lacy panicle | E4: Open
A5: 5F | B5: Bella Anna | C5: Hydrangea arborescens | D5: Mop | E5: Half-open
A6: 26B | B6: Berry White | C6: Hydrangea paniculata | D6: Mop-like panicle | E6: Half-open
A7: 18B | B7: Big Ben | C7: Hydrangea paniculata | D7: Lacy panicle | E7: Dense
A8: 18D | B8: Bobo | C8: Hydrangea paniculata | D8: Mop-like panicle | E8: Half-open
A9: 3E | B9: Bounty | C9: Hydrangea arborescens | D9: Mop | E9: Half-open
A10: 5D | B10: Brussels Lace | C10: Hydrangea paniculata | D10: Lacy panicle | E10: Open
A11: 12A | B11: Candy Apple | C11: Hydrangea paniculata | D11: Mop-like panicle | E11: Dense
A12: 10D | B12: Daimond Rogue | C12: Hydrangea paniculata | D12: Mop-like panicle | E12: Half-open
... A62: 8D | B62: Lime Light | C62: Hydrangea paniculata | D62: Mop-like panicle | E62: Unknown

Sheet Pivot table
A1: Row Labels | B1: Sum of Dendryphantini (jumping spiders) | C1: Sum of Thomisidae | D1: Sum of Chauliognathus | E1: Sum of Cerambycidae | F1: Sum of Chrysomelidae | G1: Sum of Curculionidae | H1: Sum of Lampyridae | I1: Sum of Mordellidae | J1: Sum of Scarabaeoidea | K1: Sum of Diptera | L1: Sum of Anthomyiidae | M1: Sum of Bombyliidae | N1: Sum of Calliphoridae | O1: Sum of Conopidae | P1: Sum of Cecidomyiidae | Q1: Sum of Culicidae | R1: Sum of Dolichopodidae | S1: Sum of Drosophilidae | T1: Sum of Empididae | U1: Sum of Lonchaeidae | V1: Sum of Muscidae | W1: Sum of Polleniidae | X1: Sum of Syrphidae (total) | Y1: Sum of Allograpta | Z1: Sum of Helophilus | AA1: Sum of Ocyptamus | AB1: Sum of Orthonevra | AC1: Sum of Parhelophilus | AD1: Sum of Parhelophilus integer | AE1: Sum of Syrphidae | AF1: Sum of Syrphini | AG1: Sum of Syrphus | AH1: Sum of Toxomerus | AI1: Sum of Tachinidae | AJ1: Sum of Tipulidae | AK1: Sum of Ulidiidae | AL1: Sum of Hemiptera | AM1: Sum of Aphidinae | AN1: Sum of Cicadellidae | AO1: Sum of Miridae | AP1: Sum of Reduviidae | AQ1: Sum of Hymenoptera | AR1: Sum of Andrena | AS1: Sum of Pseudopanurgus | AT1: Sum of Apis | AU1: Sum of Ceratina | AV1: Sum of Melissodes | AW1: Sum of Triepeolus | AX1: Sum of Astata | AY1: Sum of Elampus | AZ1: Sum of Hylaeus | BA1: Sum of Oxybelus | BB1: Sum of Halictidae | BC1: Sum of Agapostemon | BD1: Sum of Augochloropsis | BE1: Sum of Augochlora OR Augochlorella | BF1: Sum of Augochlora | BG1: Sum of Augochlorella | BH1: Sum of Halictus | BI1: Sum of Lasioglossum | BJ1: Sum of Symmorphus | BK1: Sum of Eurytoma | BL1: Sum of Braconidae | BM1: Sum of Ichneumonidae | BN1: Sum of Scolia | BO1: Sum of Sphex pensylvanicus | BP1: Sum of Vespidae | BQ1: Sum of Ancistrocerus | BR1: Sum of Dolichovespula | BS1: Sum of Polistes | BT1: Sum of Hesperiidae | BU1: Sum of Limniphilidae
A2: 10C | B2: 0 | C2: 0 | D2: 0 | E2: 0 | F2: 0 | G2: 0 | H2: 0 | I2: 0 | J2: 0 | K2: 0 | L2: 0 | M2: 0 | N2: 0 | O2: 0 | P2: 0 | Q2: 0 | R2: 0 | S2: 0 | T2: 0 | U2: 0 | V2: 0 | W2: 0 | X2: 1 | Y2: 0 | Z2: 0 | AA2: 0 | AB2: 0 | AC2: 0 | AD2: 1 | AE2: 0 | AF2: 0 | AG2: 0 | AH2: 0 | AI2: 2 | AJ2: 0 | AK2: 0 | AL2: 0 | AM2: 1 | AN2: 0 | AO2: 0 | AP2: 0 | AQ2: 0 | AR2: 0 | AS2: 0 | AT2: 0 | AU2: 0 | AV2: 0 | AW2: 0 | AX2: 0 | AY2: 0 | AZ2: 0 | BA2: 0 | BB2: 0 | BC2: 0 | BD2: 0 | BE2: 0 | BF2: 0 | BG2: 0 | BH2: 0 | BI2: 2 | BJ2: 0 | BK2: 0 | BL2: 0 | BM2: 0 | BN2: 0 | BO2: 0 | BP2: 0 | BQ2: 0 | BR2: 0 | BS2: 0 | BT2: 0 | BU2: 0
A3: 10D | B3: 0 | C3: 0 | D3: 0 | E3: 0 | F3: 0 | G3: 0 | H3: 0 | I3: 0 | J3: 0 | K3: 0 | L3: 0 | M3: 0 | N3: 0 | O3: 0 | P3: 0 | Q3: 0 | R3: 0 | S3: 0 | T3: 0 | U3: 0 | V3: 0 | W3: 0 | X3: 3 | Y3: 0 | Z3: 0 | AA3: 0 | AB3: 0 | AC3: 2 | AD3: 0 | AE3: 0 | AF3: 0 | AG3: 0 | AH3: 1 | AI3: 1 | AJ3: 0 | AK3: 0 | AL3: 0 | AM3: 0 | AN3: 0 | AO3: 0 | AP3: 0 | AQ3: 0 | AR3: 0 | AS3: 0 | AT3: 0 | AU3: 0 | AV3: 0 | AW3: 0 | AX3: 0 | AY3: 0 | AZ3: 1 | BA3: 0 | BB3: 0 | BC3: 0 | BD3: 0 | BE3: 0 | BF3: 1 | BG3: 0 | BH3: 0 | BI3: 1 | BJ3: 0 | BK3: 0 | BL3: 0 | BM3: 0 | BN3: 0 | BO3: 0 | BP3: 0 | BQ3: 0 | BR3: 0 | BS3: 0 | BT3: 0 | BU3: 0
A4: 11C | B4: 0 | C4: 0 | D4: 0 | E4: 0 | F4: 0 | G4: 0 | H4: 0 | I4: 0 | J4: 0 | K4: 0 | L4: 0 | M4: 0 | N4: 0 | O4: 0 | P4: 0 | Q4: 0 | R4: 0 | S4: 0 | T4: 0 | U4: 0 | V4: 1 | W4: 0 | X4: 1 | Y4: 0 | Z4: 0 | AA4: 0 | AB4: 0 | AC4: 0 | AD4: 0 | AE4: 0 | AF4: 0 | AG4: 0 | AH4: 1 | AI4: 5 | AJ4: 0 | AK4: 0 | AL4: 0 | AM4: 0 | AN4: 0 | AO4: 0 | AP4: 0 | AQ4: 0 | AR4: 0 | AS4: 0 | AT4: 0 | AU4: 0 | AV4: 0 | AW4: 0 | AX4: 0 | AY4: 0 | AZ4: 0 | BA4: 0 | BB4: 0 | BC4: 0 | BD4: 0 | BE4: 0 | BF4: 0 | BG4: 0 | BH4: 1 | BI4: 6 | BJ4: 0 | BK4: 0 | BL4: 0 | BM4: 0 | BN4: 0 | BO4: 0 | BP4: 0 | BQ4: 0 | BR4: 0 | BS4: 1 | BT4: 0 | BU4: 0
A5: 11D | B5: 0 | C5: 0 | D5: 0 | E5: 0 | F5: 0 | G5: 0 | H5: 0 | I5: 0 | J5: 0 | K5: 0 | L5: 0 | M5: 0 | N5: 2 | O5: 1 | P5: 0 | Q5: 1 | R5: 0 | S5: 0 | T5: 0 | U5: 0 | V5: 2 | W5: 0 | X5: 6 | Y5: 0 | Z5: 0 | AA5: 0 | AB5: 0 | AC5: 0 | AD5: 0 | AE5: 1 | AF5: 0 | AG5: 0 | AH5: 5 | AI5: 1 | AJ5: 0 | AK5: 0 | AL5: 0 | AM5: 0 | AN5: 0 | AO5: 0 | AP5: 0 | AQ5: 0 | AR5: 0 | AS5: 0 | AT5: 0 | AU5: 0 | AV5: 0 | AW5: 0 | AX5: 0 | AY5: 0 | AZ5: 2 | BA5: 0 | BB5: 0 | BC5: 0 | BD5: 0 | BE5: 0 | BF5: 0 | BG5: 0 | BH5: 0 | BI5: 4 | BJ5: 0 | BK5: 0 | BL5: 0 | BM5: 0 | BN5: 0 | BO5: 0 | BP5: 0 | BQ5: 0 | BR5: 0 | BS5: 0 | BT5: 0 | BU5: 0
A6: 11E | B6: 0 | C6: 0 | D6: 0 | E6: 0 | F6: 0 | G6: 0 | H6: 0 | I6: 0 | J6: 0 | K6: 0 | L6: 0 | M6: 0 | N6: 0 | O6: 0 | P6: 0 | Q6: 0 | R6: 0 | S6: 0 | T6: 0 | U6: 0 | V6: 0 | W6: 0 | X6: 1 | Y6: 0 | Z6: 0 | AA6: 0 | AB6: 0 | AC6: 0 | AD6: 0 | AE6: 1 | AF6: 0 | AG6: 0 | AH6: 0 | AI6: 1 | AJ6: 0 | AK6: 0 | AL6: 0 | AM6: 0 | AN6: 0 | AO6: 0 | AP6: 0 | AQ6: 0 | AR6: 0 | AS6: 0 | AT6: 0 | AU6: 0 | AV6: 0 | AW6: 0 | AX6: 0 | AY6: 0 | AZ6: 0 | BA6: 0 | BB6: 0 | BC6: 0 | BD6: 0 | BE6: 0 | BF6: 0 | BG6: 0 | BH6: 0 | BI6: 9 | BJ6: 0 | BK6: 0 | BL6: 0 | BM6: 0 | BN6: 0 | BO6: 0 | BP6: 0 | BQ6: 0 | BR6: 0 | BS6: 0 | BT6: 0 | BU6: 0
A7: 11F | B7: 0 | C7: 0 | D7: 0 | E7: 0 | F7: 0 | G7: 0 | H7: 0 | I7: 0 | J7: 0 | K7: 0 | L7: 0 | M7: 0 | N7: 0 | O7: 0 | P7: 0 | Q7: 1 | R7: 2 | S7: 0 | T7: 0 | U7: 0 | V7: 0 | W7: 0 | X7: 1 | Y7: 0 | Z7: 0 | AA7: 1 | AB7: 0 | AC7: 0 | AD7: 0 | AE7: 0 | AF7: 0 | AG7: 0 | AH7: 0 | AI7: 0 | AJ7: 0 | AK7: 0 | AL7: 0 | AM7: 0 | AN7: 0 | AO7: 0 | AP7: 0 | AQ7: 0 | AR7: 0 | AS7: 0 | AT7: 0 | AU7: 0 | AV7: 0 | AW7: 0 | AX7: 0 | AY7: 0 | AZ7: 0 | BA7: 0 | BB7: 0 | BC7: 0 | BD7: 0 | BE7: 0 | BF7: 0 | BG7: 0 | BH7: 0 | BI7: 2 | BJ7: 0 | BK7: 0 | BL7: 0 | BM7: 0 | BN7: 0 | BO7: 0 | BP7: 0 | BQ7: 0 | BR7: 0 | BS7: 0 | BT7: 0 | BU7: 0
A8: 12A | B8: 0 | C8: 0 | D8: 0 | E8: 0 | F8: 0 | G8: 0 | H8: 0 | I8: 3 | J8: 0 | K8: 0 | L8: 0 | M8: 0 | N8: 0 | O8: 0 | P8: 0 | Q8: 0 | R8: 0 | S8: 0 | T8: 0 | U8: 0 | V8: 1 | W8: 0 | X8: 3 | Y8: 0 | Z8: 0 | AA8: 0 | AB8: 0 | AC8: 0 | AD8: 0 | AE8: 1 | AF8: 0 | AG8: 0 | AH8: 2 | AI8: 1 | AJ8: 0 | AK8: 0 | AL8: 0 | AM8: 0 | AN8: 0 | AO8: 0 | AP8: 0 | AQ8: 0 | AR8: 0 | AS8: 0 | AT8: 0 | AU8: 0 | AV8: 0 | AW8: 0 | AX8: 0 | AY8: 0 | AZ8: 0 | BA8: 0 | BB8: 0 | BC8: 0 | BD8: 0 | BE8: 0 | BF8: 0 | BG8: 0 | BH8: 1 | BI8: 5 | BJ8: 0 | BK8: 0 | BL8: 0 | BM8: 0 | BN8: 0 | BO8: 0 | BP8: 0 | BQ8: 0 | BR8: 0 | BS8: 0 | BT8: 0 | BU8: 0
A9: 12C | B9: 0 | C9: 0 | D9: 0 | E9: 0 | F9: 0 | G9: 0 | H9: 0 | I9: 0 | J9: 0 | K9: 0 | L9: 0 | M9: 0 | N9: 1 | O9: 0 | P9: 0 | Q9: 0 | R9: 0 | S9: 0 | T9: 0 | U9: 0 | V9: 1 | W9: 0 | X9: 1 | Y9: 0 | Z9: 0 | AA9: 0 | AB9: 0 | AC9: 0 | AD9: 0 | AE9: 0 | AF9: 0 | AG9: 0 | AH9: 1 | AI9: 1 | AJ9: 0 | AK9: 0 | AL9: 0 | AM9: 0 | AN9: 0 | AO9: 0 | AP9: 0 | AQ9: 0 | AR9: 0 | AS9: 0 | AT9: 0 | AU9: 0 | AV9: 0 | AW9: 1 | AX9: 0 | AY9: 0 | AZ9: 0 | BA9: 0 | BB9: 0 | BC9: 0 | BD9: 0 | BE9: 0 | BF9: 1 | BG9: 0 | BH9: 0 | BI9: 1 | BJ9: 0 | BK9: 0 | BL9: 0 | BM9: 0 | BN9: 0 | BO9: 0 | BP9: 0 | BQ9: 0 | BR9: 0 | BS9: 0 | BT9: 0 | BU9: 0
A10: 12D | B10: 0 | C10: 0 | D10: 0 | E10: 0 | F10: 0 | G10: 0 | H10: 0 | I10: 0 | J10: 0 | K10: 0 | L10: 0 | M10: 0 | N10: 1 | O10: 0 | P10: 0 | Q10: 0 | R10: 0 | S10: 1 | T10: 0 | U10: 0 | V10: 0 | W10: 0 | X10: 2 | Y10: 1 | Z10: 0 | AA10: 0 | AB10: 0 | AC10: 0 | AD10: 0 | AE10: 1 | AF10: 0 | AG10: 0 | AH10: 0 | AI10: 0 | AJ10: 0 | AK10: 0 | AL10: 0 | AM10: 0 | AN10: 0 | AO10: 0 | AP10: 0 | AQ10: 0 | AR10: 0 | AS10: 0 | AT10: 0 | AU10: 0 | AV10: 0 | AW10: 0 | AX10: 0 | AY10: 0 | AZ10: 0 | BA10: 0 | BB10: 0 | BC10: 1 | BD10: 0 | BE10: 0 | BF10: 0 | BG10: 0 | BH10: 0 | BI10: 5 | BJ10: 0 | BK10: 0 | BL10: 0 | BM10: 0 | BN10: 0 | BO10: 0 | BP10: 0 | BQ10: 0 | BR10: 0 | BS10: 0 | BT10: 0 | BU10: 0
A11: 12E | B11: 0 | C11: 0 | D11: 0 | E11: 0 | F11: 0 | G11: 0 | H11: 0 | I11: 0 | J11: 0 | K11: 0 | L11: 0 | M11: 0 | N11: 0 | O11: 0 | P11: 0 | Q11: 0 | R11: 0 | S11: 0 | T11: 0 | U11: 0 | V11: 0 | W11: 0 | X11: 1 | Y11: 0 | Z11: 0 | AA11: 0 | AB11: 0 | AC11: 0 | AD11: 0 | AE11: 0 | AF11: 0 | AG11: 0 | AH11: 1 | AI11: 0 | AJ11: 0 | AK11: 0 | AL11: 0 | AM11: 0 | AN11: 0 | AO11: 0 | AP11: 0 | AQ11: 0 | AR11: 0 | AS11: 0 | AT11: 0 | AU11: 0 | AV11: 0 | AW11: 0 | AX11: 0 | AY11: 0 | AZ11: 0 | BA11: 0 | BB11: 0 | BC11: 0 | BD11: 0 | BE11: 0 | BF11: 0 | BG11: 0 | BH11: 0 | BI11: 0 | BJ11: 0 | BK11: 0 | BL11: 0 | BM11: 0 | BN11: 0 | BO11: 0 | BP11: 0 | BQ11: 0 | BR11: 0 | BS11: 0 | BT11: 0 | BU11: 0
A12: 12F | B12: 0 | C12: 0 | D12: 0 | E12: 0 | F12: 0 | G12: 0 | H12: 0 | I12: 1 | J12: 0 | K12: 0 | L12: 0 | M12: 0 | N12: 0 | O12: 1 | P12: 0 | Q12: 0 | R12: 1 | S12: 0 | T12: 0 | U12: 0 | V12: 0 | W12: 0 | X12: 2 | Y12: 0 | Z12: 0 | AA12: 0 | AB12: 0 | AC12: 0 | AD12: 0 | AE12: 2 | AF12: 0 | AG12: 0 | AH12: 0 | AI12: 0 | AJ12: 0 | AK12: 0 | AL12: 0 | AM12: 0 | AN12: 0 | AO12: 1 | AP12: 0 | AQ12: 0 | AR12: 0 | AS12: 0 | AT12: 0 | AU12: 3 | AV12: 0 | AW12: 0 | AX12: 0 | AY12: 0 | AZ12: 1 | BA12: 0 | BB12: 0 | BC12: 0 | BD12: 0 | BE12: 0 | BF12: 0 | BG12: 0 | BH12: 4 | BI12: 31 | BJ12: 0 | BK12: 0 | BL12: 0 | BM12: 0 | BN12: 0 | BO12: 0 | BP12: 3 | BQ12: 0 | BR12: 0 | BS12: 0 | BT12: 0 | BU12: 0
A13: 13B | B13: 0 | C13: 0 | D13: 0 | E13: 0 | F13: 0 | G13: 0 | H13: 0 | I13: 0 | J13: 0 | K13: 0 | L13: 0 | M13: 0 | N13: 0 | O13: 0 | P13: 0 | Q13: 0 | R13: 1 | S13: 0 | T13: 0 | U13: 0 | V13: 0 | W13: 0 | X13: 0 | Y13: 0 | Z13: 0 | AA13: 0 | AB13: 0 | AC13: 0 | AD13: 0 | AE13: 0 | AF13: 0 | AG13: 0 | AH13: 0 | AI13: 2 | AJ13: 0 | AK13: 0 | AL13: 0 | AM13: 0 | AN13: 0 | AO13: 0 | AP13: 0 | AQ13: 0 | AR13: 0 | AS13: 0 | AT13: 0 | AU13: 0 | AV13: 0 | AW13: 0 | AX13: 0 | AY13: 0 | AZ13: 0 | BA13: 0 | BB13: 0 | BC13: 0 | BD13: 0 | BE13: 0 | BF13: 1 | BG13: 0 | BH13: 0 | BI13: 3 | BJ13: 0 | BK13: 0 | BL13: 0 | BM13: 1 | BN13: 0 | BO13: 0 | BP13: 0 | BQ13: 0 | BR13: 0 | BS13: 0 | BT13: 0 | BU13: 0
... A58: B8 | B58: 0 | C58: 2 | D58: 0 | E58: 0 | F58: 0 | G58: 0 | H58: 0 | I58: 0 | J58: 0 | K58: 0 | L58: 0 | M58: 0 | N58: 0 | O58: 0 | P58: 0 | Q58: 0 | R58: 0 | S58: 0 | T58: 0 | U58: 0 | V58: 0 | W58: 0 | X58: 0 | Y58: 0 | Z58: 0 | AA58: 0 | AB58: 0 | AC58: 0 | AD58: 0 | AE58: 0 | AF58: 0 | AG58: 0 | AH58: 0 | AI58: 1 | AJ58: 0 | AK58: 0 | AL58: 0 | AM58: 0 | AN58: 0 | AO58: 0 | AP58: 1 | AQ58: 0 | AR58: 0 | AS58: 0 | AT58: 0 | AU58: 0 | AV58: 0 | AW58: 0 | AX58: 0 | AY58: 0 | AZ58: 1 | BA58: 0 | BB58: 0 | BC58: 0 | BD58: 0 | BE58: 0 | BF58: 0 | BG58: 1 | BH58: 0 | BI58: 0 | BJ58: 0 | BK58: 0 | BL58: 0 | BM58: 0 | BN58: 0 | BO58: 0 | BP58: 0 | BQ58: 0 | BR58: 0 | BS58: 0 | BT58: 0 | BU58: 0
A59: (blank)
A60: Grand Total | B60: 1 | C60: 4 | D60: 10 | E60: 2 | F60: 4 | G60: 6 | H60: 1 | I60: 13 | J60: 1 | K60: 1 | L60: 0 | M60: 1 | N60: 31 | O60: 14 | P60: 0 | Q60: 5 | R60: 43 | S60: 17 | T60: 1 | U60: 1 | V60: 46 | W60: 1 | X60: 98 | Y60: 4 | Z60: 5 | AA60: 1 | AB60: 2 | AC60: 5 | AD60: 3 | AE60: 23 | AF60: 1 | AG60: 2 | AH60: 52 | AI60: 63 | AJ60: 1 | AK60: 1 | AL60: 0 | AM60: 1 | AN60: 1 | AO60: 3 | AP60: 2 | AQ60: 0 | AR60: 1 | AS60: 2 | AT60: 1 | AU60: 10 | AV60: 1 | AW60: 1 | AX60: 1 | AY60: 0 | AZ60: 24 | BA60: 0 | BB60: 1 | BC60: 8 | BD60: 4 | BE60: 2 | BF60: 39 | BG60: 4 | BH60: 35 | BI60: 215 | BJ60: 1 | BK60: 1 | BL60: 1 | BM60: 5 | BN60: 0 | BO60: 1 | BP60: 15 | BQ60: 0 | BR60: 4 | BS60: 1 | BT60: 1 | BU60: 1

Sheet Pivot table values
A1: Row Labels | B1: Sum of Dendryphantini (jumping spiders) | C1: Sum of Thomisidae | D1: Sum of Chauliognathus | E1: Sum of Cerambycidae | F1: Sum of Chrysomelidae | G1: Sum of Curculionidae | H1: Sum of Lampyridae | I1: Sum of Mordellidae | J1: Sum of Scarabaeoidea | K1: Sum of Diptera | L1: Sum of Anthomyiidae | M1: Sum of Bombyliidae | N1: Sum of Calliphoridae | O1: Sum of Conopidae | P1: Sum of Cecidomyiidae | Q1: Sum of Culicidae | R1: Sum of Dolichopodidae | S1: Sum of Drosophilidae | T1: Sum of Empididae | U1: Sum of Lonchaeidae | V1: Sum of Muscidae | W1: Sum of Polleniidae | X1: Sum of Syrphidae (total) | Y1: Sum of Allograpta | Z1: Sum of Helophilus | AA1: Sum of Ocyptamus | AB1: Sum of Orthonevra | AC1: Sum of Parhelophilus | AD1: Sum of Parhelophilus integer | AE1: Sum of Syrphidae | AF1: Sum of Syrphini | AG1: Sum of Syrphus | AH1: Sum of Toxomerus | AI1: Sum of Tachinidae | AJ1: Sum of Tipulidae | AK1: Sum of Ulidiidae | AL1: Sum of Hemiptera | AM1: Sum of Aphidinae | AN1: Sum of Cicadellidae | AO1: Sum of Miridae | AP1: Sum of Reduviidae | AQ1: Sum of Hymenoptera | AR1: Sum of Andrena | AS1: Sum of Pseudopanurgus | AT1: Sum of Apis | AU1: Sum of Ceratina | AV1: Sum of Melissodes | AW1: Sum of Triepeolus | AX1: Sum of Astata | AY1: Sum of Elampus | AZ1: Sum of Hylaeus | BA1: Sum of Oxybelus | BB1: Sum of Halictidae | BC1: Sum of Agapostemon | BD1: Sum of Augochloropsis | BE1: Sum of Augochlora OR Augochlorella | BF1: Sum of Augochlora | BG1: Sum of Augochlorella | BH1: Sum of Halictus | BI1: Sum of Lasioglossum | BJ1: Sum of Symmorphus | BK1: Sum of Eurytoma | BL1: Sum of Braconidae | BM1: Sum of Ichneumonidae | BN1: Sum of Scolia | BO1: Sum of Sphex pensylvanicus | BP1: Sum of Vespidae | BQ1: Sum of Ancistrocerus | BR1: Sum of Dolichovespula | BS1: Sum of Polistes | BT1: Sum of Hesperiidae | BU1: Sum of Limniphilidae
A2: 10C | B2: 0 | C2: 0 | D2: 0 | E2: 0 | F2: 0 | G2: 0 | H2: 0 | I2: 0 | J2: 0 | K2: 0 | L2: 0 | M2: 0 | N2: 0 | O2: 0 | P2: 0 | Q2: 0 | R2: 0 | S2: 0 | T2: 0 | U2: 0 | V2: 0 | W2: 0 | X2: 1 | Y2: 0 | Z2: 0 | AA2: 0 | AB2: 0 | AC2: 0 | AD2: 1 | AE2: 0 | AF2: 0 | AG2: 0 | AH2: 0 | AI2: 2 | AJ2: 0 | AK2: 0 | AL2: 0 | AM2: 1 | AN2: 0 | AO2: 0 | AP2: 0 | AQ2: 0 | AR2: 0 | AS2: 0 | AT2: 0 | AU2: 0 | AV2: 0 | AW2: 0 | AX2: 0 | AY2: 0 | AZ2: 0 | BA2: 0 | BB2: 0 | BC2: 0 | BD2: 0 | BE2: 0 | BF2: 0 | BG2: 0 | BH2: 0 | BI2: 2 | BJ2: 0 | BK2: 0 | BL2: 0 | BM2: 0 | BN2: 0 | BO2: 0 | BP2: 0 | BQ2: 0 | BR2: 0 | BS2: 0 | BT2: 0 | BU2: 0
A3: 10D | B3: 0 | C3: 0 | D3: 0 | E3: 0 | F3: 0 | G3: 0 | H3: 0 | I3: 0 | J3: 0 | K3: 0 | L3: 0 | M3: 0 | N3: 0 | O3: 0 | P3: 0 | Q3: 0 | R3: 0 | S3: 0 | T3: 0 | U3: 0 | V3: 0 | W3: 0 | X3: 3 | Y3: 0 | Z3: 0 | AA3: 0 | AB3: 0 | AC3: 2 | AD3: 0 | AE3: 0 | AF3: 0 | AG3: 0 | AH3: 1 | AI3: 1 | AJ3: 0 | AK3: 0 | AL3: 0 | AM3: 0 | AN3: 0 | AO3: 0 | AP3: 0 | AQ3: 0 | AR3: 0 | AS3: 0 | AT3: 0 | AU3: 0 | AV3: 0 | AW3: 0 | AX3: 0 | AY3: 0 | AZ3: 1 | BA3: 0 | BB3: 0 | BC3: 0 | BD3: 0 | BE3: 0 | BF3: 1 | BG3: 0 | BH3: 0 | BI3: 1 | BJ3: 0 | BK3: 0 | BL3: 0 | BM3: 0 | BN3: 0 | BO3: 0 | BP3: 0 | BQ3: 0 | BR3: 0 | BS3: 0 | BT3: 0 | BU3: 0
A4: 11C | B4: 0 | C4: 0 | D4: 0 | E4: 0 | F4: 0 | G4: 0 | H4: 0 | I4: 0 | J4: 0 | K4: 0 | L4: 0 | M4: 0 | N4: 0 | O4: 0 | P4: 0 | Q4: 0 | R4: 0 | S4: 0 | T4: 0 | U4: 0 | V4: 1 | W4: 0 | X4: 1 | Y4: 0 | Z4: 0 | AA4: 0 | AB4: 0 | AC4: 0 | AD4: 0 | AE4: 0 | AF4: 0 | AG4: 0 | AH4: 1 | AI4: 5 | AJ4: 0 | AK4: 0 | AL4: 0 | AM4: 0 | AN4: 0 | AO4: 0 | AP4: 0 | AQ4: 0 | AR4: 0 | AS4: 0 | AT4: 0 | AU4: 0 | AV4: 0 | AW4: 0 | AX4: 0 | AY4: 0 | AZ4: 0 | BA4: 0 | BB4: 0 | BC4: 0 | BD4: 0 | BE4: 0 | BF4: 0 | BG4: 0 | BH4: 1 | BI4: 6 | BJ4: 0 | BK4: 0 | BL4: 0 | BM4: 0 | BN4: 0 | BO4: 0 | BP4: 0 | BQ4: 0 | BR4: 0 | BS4: 1 | BT4: 0 | BU4: 0
A5: 11D | B5: 0 | C5: 0 | D5: 0 | E5: 0 | F5: 0 | G5: 0 | H5: 0 | I5: 0 | J5: 0 | K5: 0 | L5: 0 | M5: 0 | N5: 2 | O5: 1 | P5: 0 | Q5: 1 | R5: 0 | S5: 0 | T5: 0 | U5: 0 | V5: 2 | W5: 0 | X5: 6 | Y5: 0 | Z5: 0 | AA5: 0 | AB5: 0 | AC5: 0 | AD5: 0 | AE5: 1 | AF5: 0 | AG5: 0 | AH5: 5 | AI5: 1 | AJ5: 0 | AK5: 0 | AL5: 0 | AM5: 0 | AN5: 0 | AO5: 0 | AP5: 0 | AQ5: 0 | AR5: 0 | AS5: 0 | AT5: 0 | AU5: 0 | AV5: 0 | AW5: 0 | AX5: 0 | AY5: 0 | AZ5: 2 | BA5: 0 | BB5: 0 | BC5: 0 | BD5: 0 | BE5: 0 | BF5: 0 | BG5: 0 | BH5: 0 | BI5: 4 | BJ5: 0 | BK5: 0 | BL5: 0 | BM5: 0 | BN5: 0 | BO5: 0 | BP5: 0 | BQ5: 0 | BR5: 0 | BS5: 0 | BT5: 0 | BU5: 0
A6: 11E | B6: 0 | C6: 0 | D6: 0 | E6: 0 | F6: 0 | G6: 0 | H6: 0 | I6: 0 | J6: 0 | K6: 0 | L6: 0 | M6: 0 | N6: 0 | O6: 0 | P6: 0 | Q6: 0 | R6: 0 | S6: 0 | T6: 0 | U6: 0 | V6: 0 | W6: 0 | X6: 1 | Y6: 0 | Z6: 0 | AA6: 0 | AB6: 0 | AC6: 0 | AD6: 0 | AE6: 1 | AF6: 0 | AG6: 0 | AH6: 0 | AI6: 1 | AJ6: 0 | AK6: 0 | AL6: 0 | AM6: 0 | AN6: 0 | AO6: 0 | AP6: 0 | AQ6: 0 | AR6: 0 | AS6: 0 | AT6: 0 | AU6: 0 | AV6: 0 | AW6: 0 | AX6: 0 | AY6: 0 | AZ6: 0 | BA6: 0 | BB6: 0 | BC6: 0 | BD6: 0 | BE6: 0 | BF6: 0 | BG6: 0 | BH6: 0 | BI6: 9 | BJ6: 0 | BK6: 0 | BL6: 0 | BM6: 0 | BN6: 0 | BO6: 0 | BP6: 0 | BQ6: 0 | BR6: 0 | BS6: 0 | BT6: 0 | BU6: 0
A7: 11F | B7: 0 | C7: 0 | D7: 0 | E7: 0 | F7: 0 | G7: 0 | H7: 0 | I7: 0 | J7: 0 | K7: 0 | L7: 0 | M7: 0 | N7: 0 | O7: 0 | P7: 0 | Q7: 1 | R7: 2 | S7: 0 | T7: 0 | U7: 0 | V7: 0 | W7: 0 | X7: 1 | Y7: 0 | Z7: 0 | AA7: 1 | AB7: 0 | AC7: 0 | AD7: 0 | AE7: 0 | AF7: 0 | AG7: 0 | AH7: 0 | AI7: 0 | AJ7: 0 | AK7: 0 | AL7: 0 | AM7: 0 | AN7: 0 | AO7: 0 | AP7: 0 | AQ7: 0 | AR7: 0 | AS7: 0 | AT7: 0 | AU7: 0 | AV7: 0 | AW7: 0 | AX7: 0 | AY7: 0 | AZ7: 0 | BA7: 0 | BB7: 0 | BC7: 0 | BD7: 0 | BE7: 0 | BF7: 0 | BG7: 0 | BH7: 0 | BI7: 2 | BJ7: 0 | BK7: 0 | BL7: 0 | BM7: 0 | BN7: 0 | BO7: 0 | BP7: 0 | BQ7: 0 | BR7: 0 | BS7: 0 | BT7: 0 | BU7: 0
A8: 12A | B8: 0 | C8: 0 | D8: 0 | E8: 0 | F8: 0 | G8: 0 | H8: 0 | I8: 3 | J8: 0 | K8: 0 | L8: 0 | M8: 0 | N8: 0 | O8: 0 | P8: 0 | Q8: 0 | R8: 0 | S8: 0 | T8: 0 | U8: 0 | V8: 1 | W8: 0 | X8: 3 | Y8: 0 | Z8: 0 | AA8: 0 | AB8: 0 | AC8: 0 | AD8: 0 | AE8: 1 | AF8: 0 | AG8: 0 | AH8: 2 | AI8: 1 | AJ8: 0 | AK8: 0 | AL8: 0 | AM8: 0 | AN8: 0 | AO8: 0 | AP8: 0 | AQ8: 0 | AR8: 0 | AS8: 0 | AT8: 0 | AU8: 0 | AV8: 0 | AW8: 0 | AX8: 0 | AY8: 0 | AZ8: 0 | BA8: 0 | BB8: 0 | BC8: 0 | BD8: 0 | BE8: 0 | BF8: 0 | BG8: 0 | BH8: 1 | BI8: 5 | BJ8: 0 | BK8: 0 | BL8: 0 | BM8: 0 | BN8: 0 | BO8: 0 | BP8: 0 | BQ8: 0 | BR8: 0 | BS8: 0 | BT8: 0 | BU8: 0
A9: 12C | B9: 0 | C9: 0 | D9: 0 | E9: 0 | F9: 0 | G9: 0 | H9: 0 | I9: 0 | J9: 0 | K9: 0 | L9: 0 | M9: 0 | N9: 1 | O9: 0 | P9: 0 | Q9: 0 | R9: 0 | S9: 0 | T9: 0 | U9: 0 | V9: 1 | W9: 0 | X9: 1 | Y9: 0 | Z9: 0 | AA9: 0 | AB9: 0 | AC9: 0 | AD9: 0 | AE9: 0 | AF9: 0 | AG9: 0 | AH9: 1 | AI9: 1 | AJ9: 0 | AK9: 0 | AL9: 0 | AM9: 0 | AN9: 0 | AO9: 0 | AP9: 0 | AQ9: 0 | AR9: 0 | AS9: 0 | AT9: 0 | AU9: 0 | AV9: 0 | AW9: 1 | AX9: 0 | AY9: 0 | AZ9: 0 | BA9: 0 | BB9: 0 | BC9: 0 | BD9: 0 | BE9: 0 | BF9: 1 | BG9: 0 | BH9: 0 | BI9: 1 | BJ9: 0 | BK9: 0 | BL9: 0 | BM9: 0 | BN9: 0 | BO9: 0 | BP9: 0 | BQ9: 0 | BR9: 0 | BS9: 0 | BT9: 0 | BU9: 0
A10: 12D | B10: 0 | C10: 0 | D10: 0 | E10: 0 | F10: 0 | G10: 0 | H10: 0 | I10: 0 | J10: 0 | K10: 0 | L10: 0 | M10: 0 | N10: 1 | O10: 0 | P10: 0 | Q10: 0 | R10: 0 | S10: 1 | T10: 0 | U10: 0 | V10: 0 | W10: 0 | X10: 2 | Y10: 1 | Z10: 0 | AA10: 0 | AB10: 0 | AC10: 0 | AD10: 0 | AE10: 1 | AF10: 0 | AG10: 0 | AH10: 0 | AI10: 0 | AJ10: 0 | AK10: 0 | AL10: 0 | AM10: 0 | AN10: 0 | AO10: 0 | AP10: 0 | AQ10: 0 | AR10: 0 | AS10: 0 | AT10: 0 | AU10: 0 | AV10: 0 | AW10: 0 | AX10: 0 | AY10: 0 | AZ10: 0 | BA10: 0 | BB10: 0 | BC10: 1 | BD10: 0 | BE10: 0 | BF10: 0 | BG10: 0 | BH10: 0 | BI10: 5 | BJ10: 0 | BK10: 0 | BL10: 0 | BM10: 0 | BN10: 0 | BO10: 0 | BP10: 0 | BQ10: 0 | BR10: 0 | BS10: 0 | BT10: 0 | BU10: 0
A11: 12E | B11: 0 | C11: 0 | D11: 0 | E11: 0 | F11: 0 | G11: 0 | H11: 0 | I11: 0 | J11: 0 | K11: 0 | L11: 0 | M11: 0 | N11: 0 | O11: 0 | P11: 0 | Q11: 0 | R11: 0 | S11: 0 | T11: 0 | U11: 0 | V11: 0 | W11: 0 | X11: 1 | Y11: 0 | Z11: 0 | AA11: 0 | AB11: 0 | AC11: 0 | AD11: 0 | AE11: 0 | AF11: 0 | AG11: 0 | AH11: 1 | AI11: 0 | AJ11: 0 | AK11: 0 | AL11: 0 | AM11: 0 | AN11: 0 | AO11: 0 | AP11: 0 | AQ11: 0 | AR11: 0 | AS11: 0 | AT11: 0 | AU11: 0 | AV11: 0 | AW11: 0 | AX11: 0 | AY11: 0 | AZ11: 0 | BA11: 0 | BB11: 0 | BC11: 0 | BD11: 0 | BE11: 0 | BF11: 0 | BG11: 0 | BH11: 0 | BI11: 0 | BJ11: 0 | BK11: 0 | BL11: 0 | BM11: 0 | BN11: 0 | BO11: 0 | BP11: 0 | BQ11: 0 | BR11: 0 | BS11: 0 | BT11: 0 | BU11: 0
A12: 12F | B12: 0 | C12: 0 | D12: 0 | E12: 0 | F12: 0 | G12: 0 | H12: 0 | I12: 1 | J12: 0 | K12: 0 | L12: 0 | M12: 0 | N12: 0 | O12: 1 | P12: 0 | Q12: 0 | R12: 1 | S12: 0 | T12: 0 | U12: 0 | V12: 0 | W12: 0 | X12: 2 | Y12: 0 | Z12: 0 | AA12: 0 | AB12: 0 | AC12: 0 | AD12: 0 | AE12: 2 | AF12: 0 | AG12: 0 | AH12: 0 | AI12: 0 | AJ12: 0 | AK12: 0 | AL12: 0 | AM12: 0 | AN12: 0 | AO12: 1 | AP12: 0 | AQ12: 0 | AR12: 0 | AS12: 0 | AT12: 0 | AU12: 3 | AV12: 0 | AW12: 0 | AX12: 0 | AY12: 0 | AZ12: 1 | BA12: 0 | BB12: 0 | BC12: 0 | BD12: 0 | BE12: 0 | BF12: 0 | BG12: 0 | BH12: 4 | BI12: 31 | BJ12: 0 | BK12: 0 | BL12: 0 | BM12: 0 | BN12: 0 | BO12: 0 | BP12: 3 | BQ12: 0 | BR12: 0 | BS12: 0 | BT12: 0 | BU12: 0
A13: 13B | B13: 0 | C13: 0 | D13: 0 | E13: 0 | F13: 0 | G13: 0 | H13: 0 | I13: 0 | J13: 0 | K13: 0 | L13: 0 | M13: 0 | N13: 0 | O13: 0 | P13: 0 | Q13: 0 | R13: 1 | S13: 0 | T13: 0 | U13: 0 | V13: 0 | W13: 0 | X13: 0 | Y13: 0 | Z13: 0 | AA13: 0 | AB13: 0 | AC13: 0 | AD13: 0 | AE13: 0 | AF13: 0 | AG13: 0 | AH13: 0 | AI13: 2 | AJ13: 0 | AK13: 0 | AL13: 0 | AM13: 0 | AN13: 0 | AO13: 0 | AP13: 0 | AQ13: 0 | AR13: 0 | AS13: 0 | AT13: 0 | AU13: 0 | AV13: 0 | AW13: 0 | AX13: 0 | AY13: 0 | AZ13: 0 | BA13: 0 | BB13: 0 | BC13: 0 | BD13: 0 | BE13: 0 | BF13: 1 | BG13: 0 | BH13: 0 | BI13: 3 | BJ13: 0 | BK13: 0 | BL13: 0 | BM13: 1 | BN13: 0 | BO13: 0 | BP13: 0 | BQ13: 0 | BR13: 0 | BS13: 0 | BT13: 0 | BU13: 0
... A58: B8 | B58: 0 | C58: 2 | D58: 0 | E58: 0 | F58: 0 | G58: 0 | H58: 0 | I58: 0 | J58: 0 | K58: 0 | L58: 0 | M58: 0 | N58: 0 | O58: 0 | P58: 0 | Q58: 0 | R58: 0 | S58: 0 | T58: 0 | U58: 0 | V58: 0 | W58: 0 | X58: 0 | Y58: 0 | Z58: 0 | AA58: 0 | AB58: 0 | AC58: 0 | AD58: 0 | AE58: 0 | AF58: 0 | AG58: 0 | AH58: 0 | AI58: 1 | AJ58: 0 | AK58: 0 | AL58: 0 | AM58: 0 | AN58: 0 | AO58: 0 | AP58: 1 | AQ58: 0 | AR58: 0 | AS58: 0 | AT58: 0 | AU58: 0 | AV58: 0 | AW58: 0 | AX58: 0 | AY58: 0 | AZ58: 1 | BA58: 0 | BB58: 0 | BC58: 0 | BD58: 0 | BE58: 0 | BF58: 0 | BG58: 1 | BH58: 0 | BI58: 0 | BJ58: 0 | BK58: 0 | BL58: 0 | BM58: 0 | BN58: 0 | BO58: 0 | BP58: 0 | BQ58: 0 | BR58: 0 | BS58: 0 | BT58: 0 | BU58: 0
A59: (blank)
A60: Grand Total | B60: 1 | C60: 4 | D60: 10 | E60: 2 | F60: 4 | G60: 6 | H60: 1 | I60: 13 | J60: 1 | K60: 1 | L60: 0 | M60: 1 | N60: 31 | O60: 14 | P60: 0 | Q60: 5 | R60: 43 | S60: 17 | T60: 1 | U60: 1 | V60: 46 | W60: 1 | X60: 98 | Y60: 4 | Z60: 5 | AA60: 1 | AB60: 2 | AC60: 5 | AD60: 3 | AE60: 23 | AF60: 1 | AG60: 2 | AH60: 52 | AI60: 63 | AJ60: 1 | AK60: 1 | AL60: 0 | AM60: 1 | AN60: 1 | AO60: 3 | AP60: 2 | AQ60: 0 | AR60: 1 | AS60: 2 | AT60: 1 | AU60: 10 | AV60: 1 | AW60: 1 | AX60: 1 | AY60: 0 | AZ60: 24 | BA60: 0 | BB60: 1 | BC60: 8 | BD60: 4 | BE60: 2 | BF60: 39 | BG60: 4 | BH60: 35 | BI60: 215 | BJ60: 1 | BK60: 1 | BL60: 1 | BM60: 5 | BN60: 0 | BO60: 1 | BP60: 15 | BQ60: 0 | BR60: 4 | BS60: 1 | BT60: 1 | BU60: 1

Sheet Raw Data duplicates removed
A1: Date | B1: jday | C1: Tag Number | D1: Who Collected | E1: Dendryphantini (jumping spiders) | F1: Thomisidae | G1: Chauliognathus | H1: Cerambycidae | I1: Chrysomelidae | J1: Curculionidae | K1: Lampyridae | L1: Mordellidae | M1: Scarabaeoidea | N1: Diptera | O1: Anthomyiidae | P1: Bombyliidae | Q1: Calliphoridae | R1: Conopidae | S1: Cecidomyiidae | T1: Culicidae | U1: Dolichopodidae | V1: Drosophilidae | W1: Empididae | X1: Lonchaeidae | Y1: Muscidae | Z1: Polleniidae | AA1: Syrphidae (total) | AB1: Allograpta | AC1: Helophilus | AD1: Ocyptamus | AE1: Orthonevra | AF1: Parhelophilus | AG1: Parhelophilus integer | AH1: Syrphidae | AI1: Syrphini | AJ1: Syrphus | AK1: Toxomerus | AL1: Tachinidae | AM1: Tipulidae | AN1: Ulidiidae | AO1: Hemiptera | AP1: Aphidinae | AQ1: Cicadellidae | AR1: Miridae | AS1: Reduviidae | AT1: Hymenoptera | AU1: Andrena | AV1: Pseudopanurgus | AW1: Apis | AX1: Ceratina | AY1: Melissodes | AZ1: Triepeolus | BA1: Astata | BB1: Elampus | BC1: Hylaeus | BD1: Oxybelus | BE1: Halictidae | BF1: Agapostemon | BG1: Augochloropsis | BH1: Augochlora OR Augochlorella | BI1: Augochlora | BJ1: Augochlorella | BK1: Halictus | BL1: Lasioglossum | BM1: Symmorphus | BN1: Eurytoma | BO1: Formicidae | BP1: Braconidae | BQ1: Ichneumonidae | BR1: Scolia | BS1: Sphex pensylvanicus | BT1: Vespidae | BU1: Ancistrocerus | BV1: Dolichovespula | BW1: Polistes | BX1: Hesperiidae | BY1: Limniphilidae
A2: 45490 | B2: 199 | C2: 10C | D2: E. Braatz | E2: 0 | F2: 0 | G2: 0 | H2: 0 | I2: 0 | J2: 0 | K2: 0 | L2: 0 | M2: 0 | N2: 0 | O2: 0 | P2: 0 | Q2: 0 | R2: 0 | S2: 0 | T2: 0 | U2: 0 | V2: 0 | W2: 0 | X2: 0 | Y2: 0 | Z2: 0 | AA2: 0 | AB2: 0 | AC2: 0 | AD2: 0 | AE2: 0 | AF2: 0 | AG2: 0 | AH2: 0 | AI2: 0 | AJ2: 0 | AK2: 0 | AL2: 0 | AM2: 0 | AN2: 0 | AO2: 0 | AP2: 0 | AQ2: 0 | AR2: 0 | AS2: 0 | AT2: 0 | AU2: 0 | AV2: 0 | AW2: 0 | AX2: 0 | AY2: 0 | AZ2: 0 | BA2: 0 | BB2: 0 | BC2: 0 | BD2: 0 | BE2: 0 | BF2: 0 | BG2: 0 | BH2: 0 | BI2: 0 | BJ2: 0 | BK2: 0 | BL2: 1 | BM2: 0 | BN2: 0 | BO2: 0 | BP2: 0 | BQ2: 0 | BR2: 0 | BS2: 0 | BT2: 0 | BU2: 0 | BV2: 0 | BW2: 0 | BX2: 0 | BY2: 0
A3: 45502 | B3: 211 | C3: 10C | D3: E. Braatz | E3: 0 | F3: 0 | G3: 0 | H3: 0 | I3: 0 | J3: 0 | K3: 0 | L3: 0 | M3: 0 | N3: 0 | O3: 0 | P3: 0 | Q3: 0 | R3: 0 | S3: 0 | T3: 0 | U3: 0 | V3: 0 | W3: 0 | X3: 0 | Y3: 0 | Z3: 0 | AA3: 0 | AB3: 0 | AC3: 0 | AD3: 0 | AE3: 0 | AF3: 0 | AG3: 0 | AH3: 0 | AI3: 0 | AJ3: 0 | AK3: 0 | AL3: 2 | AM3: 0 | AN3: 0 | AO3: 0 | AP3: 1 | AQ3: 0 | AR3: 0 | AS3: 0 | AT3: 0 | AU3: 0 | AV3: 0 | AW3: 0 | AX3: 0 | AY3: 0 | AZ3: 0 | BA3: 0 | BB3: 0 | BC3: 0 | BD3: 0 | BE3: 0 | BF3: 0 | BG3: 0 | BH3: 0 | BI3: 0 | BJ3: 0 | BK3: 0 | BL3: 1 | BM3: 0 | BN3: 0 | BO3: 0 | BP3: 0 | BQ3: 0 | BR3: 0 | BS3: 0 | BT3: 0 | BU3: 0 | BV3: 0 | BW3: 0 | BX3: 0 | BY3: 0
A4: 45512 | B4: 221 | C4: 10C | D4: J. Goldsby | E4: 0 | F4: 0 | G4: 0 | H4: 0 | I4: 0 | J4: 0 | K4: 0 | L4: 0 | M4: 0 | N4: 0 | O4: 0 | P4: 0 | Q4: 0 | R4: 0 | S4: 0 | T4: 0 | U4: 0 | V4: 0 | W4: 0 | X4: 0 | Y4: 0 | Z4: 0 | AA4: 1 | AB4: 0 | AC4: 0 | AD4: 0 | AE4: 0 | AF4: 0 | AG4: 1 | AH4: 0 | AI4: 0 | AJ4: 0 | AK4: 0 | AL4: 0 | AM4: 0 | AN4: 0 | AO4: 0 | AP4: 0 | AQ4: 0 | AR4: 0 | AS4: 0 | AT4: 0 | AU4: 0 | AV4: 0 | AW4: 0 | AX4: 0 | AY4: 0 | AZ4: 0 | BA4: 0 | BB4: 0 | BC4: 0 | BD4: 0 | BE4: 0 | BF4: 0 | BG4: 0 | BH4: 0 | BI4: 0 | BJ4: 0 | BK4: 0 | BL4: 0 | BM4: 0 | BN4: 0 | BO4: 0 | BP4: 0 | BQ4: 0 | BR4: 0 | BS4: 0 | BT4: 0 | BU4: 0 | BV4: 0 | BW4: 0 | BX4: 0 | BY4: 0
A5: 45490 | B5: 199 | C5: 10D | D5: E. Braatz | E5: 0 | F5: 0 | G5: 0 | H5: 0 | I5: 0 | J5: 0 | K5: 0 | L5: 0 | M5: 0 | N5: 0 | O5: 0 | P5: 0 | Q5: 0 | R5: 0 | S5: 0 | T5: 0 | U5: 0 | V5: 0 | W5: 0 | X5: 0 | Y5: 0 | Z5: 0 | AA5: 1 | AB5: 0 | AC5: 0 | AD5: 0 | AE5: 0 | AF5: 0 | AG5: 0 | AH5: 0 | AI5: 0 | AJ5: 0 | AK5: 1 | AL5: 0 | AM5: 0 | AN5: 0 | AO5: 0 | AP5: 0 | AQ5: 0 | AR5: 0 | AS5: 0 | AT5: 0 | AU5: 0 | AV5: 0 | AW5: 0 | AX5: 0 | AY5: 0 | AZ5: 0 | BA5: 0 | BB5: 0 | BC5: 0 | BD5: 0 | BE5: 0 | BF5: 0 | BG5: 0 | BH5: 0 | BI5: 0 | BJ5: 0 | BK5: 0 | BL5: 1 | BM5: 0 | BN5: 0 | BO5: 0 | BP5: 0 | BQ5: 0 | BR5: 0 | BS5: 0 | BT5: 0 | BU5: 0 | BV5: 0 | BW5: 0 | BX5: 0 | BY5: 0
