Workbook

Sheet DAgg4
A1: Cultivar | B1: Insect Richness | C1: Species | D1: Flower Type | E1: Inflorescence Type
A2: Annabelle | B2: 2 | C2: =VLOOKUP($A2,VLookUp!$A$2:$D$65,2,0) -> Hydrangea arborescens | D2: =VLOOKUP($A2,VLookUp!$A$2:$D$65,3,0) -> Mop | E2: =VLOOKUP($A2,VLookUp!$A$2:$D$65,4,0) -> Dense
A3: Baby Lace | B3: 4 | C3: =VLOOKUP($A3,VLookUp!$A$2:$D$65,2,0) -> Hydrangea paniculata | D3: =VLOOKUP($A3,VLookUp!$A$2:$D$65,3,0) -> Lacy panicle | E3: =VLOOKUP($A3,VLookUp!$A$2:$D$65,4,0) -> Open
A4: Bella Anna | B4: 3 | C4: =VLOOKUP($A4,VLookUp!$A$2:$D$65,2,0) -> Hydrangea arborescens | D4: =VLOOKUP($A4,VLookUp!$A$2:$D$65,3,0) -> Mop | E4: =VLOOKUP($A4,VLookUp!$A$2:$D$65,4,0) -> Half-open
A5: Berry White | B5: 2 | C5: =VLOOKUP($A5,VLookUp!$A$2:$D$65,2,0) -> Hydrangea paniculata | D5: =VLOOKUP($A5,VLookUp!$A$2:$D$65,3,0) -> Mop-like panicle | E5: =VLOOKUP($A5,VLookUp!$A$2:$D$65,4,0) -> Half-open
A6: Big Ben | B6: 1 | C6: =VLOOKUP($A6,VLookUp!$A$2:$D$65,2,0) -> Hydrangea paniculata | D6: =VLOOKUP($A6,VLookUp!$A$2:$D$65,3,0) -> Lacy panicle | E6: =VLOOKUP($A6,VLookUp!$A$2:$D$65,4,0) -> Dense
A7: Bobo | B7: 5 | C7: =VLOOKUP($A7,VLookUp!$A$2:$D$65,2,0) -> Hydrangea paniculata | D7: =VLOOKUP($A7,VLookUp!$A$2:$D$65,3,0) -> Mop-like panicle | E7: =VLOOKUP($A7,VLookUp!$A$2:$D$65,4,0) -> Half-open
A8: Bounty | B8: 3 | C8: =VLOOKUP($A8,VLookUp!$A$2:$D$65,2,0) -> Hydrangea arborescens | D8: =VLOOKUP($A8,VLookUp!$A$2:$D$65,3,0) -> Mop | E8: =VLOOKUP($A8,VLookUp!$A$2:$D$65,4,0) -> Half-open
A9: Brussels Lace | B9: 5 | C9: =VLOOKUP($A9,VLookUp!$A$2:$D$65,2,0) -> Hydrangea paniculata | D9: =VLOOKUP($A9,VLookUp!$A$2:$D$65,3,0) -> Lacy panicle | E9: =VLOOKUP($A9,VLookUp!$A$2:$D$65,4,0) -> Open
A10: Candy Apple | B10: 8 | C10: =VLOOKUP($A10,VLookUp!$A$2:$D$65,2,0) -> Hydrangea paniculata | D10: =VLOOKUP($A10,VLookUp!$A$2:$D$65,3,0) -> Mop-like panicle | E10: =VLOOKUP($A10,VLookUp!$A$2:$D$65,4,0) -> Dense
A11: Daimond Rogue | B11: 4 | C11: =VLOOKUP($A11,VLookUp!$A$2:$D$65,2,0) -> Hydrangea paniculata | D11: =VLOOKUP($A11,VLookUp!$A$2:$D$65,3,0) -> Mop-like panicle | E11: =VLOOKUP($A11,VLookUp!$A$2:$D$65,4,0) -> Half-open
A12: Dharuma | B12: 8 | C12: =VLOOKUP($A12,VLookUp!$A$2:$D$65,2,0) -> Hydrangea paniculata | D12: =VLOOKUP($A12,VLookUp!$A$2:$D$65,3,0) -> Lacy panicle | E12: =VLOOKUP($A12,VLookUp!$A$2:$D$65,4,0) -> Open
A13: Dolly | B13: 3 | C13: =VLOOKUP($A13,VLookUp!$A$2:$D$65,2,0) -> Hydrangea paniculata | D13: =VLOOKUP($A13,VLookUp!$A$2:$D$65,3,0) -> Lacy panicle | E13: =VLOOKUP($A13,VLookUp!$A$2:$D$65,4,0) -> Dense
... A60: Zinfin Doll | B60: 3 | C60: =VLOOKUP($A60,VLookUp!$A$2:$D$65,2,0) -> Hydrangea paniculata | D60: =VLOOKUP($A60,VLookUp!$A$2:$D$65,3,0) -> Mop-like panicle | E60: =VLOOKUP($A60,VLookUp!$A$2:$D$65,4,0) -> Half-open

Sheet VLookUp
A1: Cultivar | B1: Species | C1: Flower Type | D1: Inflorescence Type
A2: Strawberry Shake | B2: Hydrangea paniculata | C2: Mop-like panicle | D2: Very dense
A3: Baby Lace | B3: Hydrangea paniculata | C3: Lacy panicle | D3: Open
A4: Sweet Summer | B4: Hydrangea paniculata | C4: Mop-like panicle | D4: Dense
A5: White Diamonds | B5: Hydrangea paniculata | C5: Mop-like panicle | D5: Half-open
A6: Quick Fire | B6: Hydrangea paniculata | C6: Lacy panicle | D6: Open
A7: Honey Comb | B7: Hydrangea paniculata | C7: Lacy panicle | D7: Open
A8: Tickled Pink | B8: Hydrangea paniculata | C8: Lacy panicle | D8: Half-open
A9: Mega Pearl | B9: Hydrangea paniculata | C9: Mop-like panicle | D9: Dense
A10: Fire & Ice | B10: Hydrangea paniculata | C10: Lacy panicle | D10: Open
A11: Pinky Winky | B11: Hydrangea paniculata | C11: Lacy panicle | D11: Half-open
A12: Dharuma | B12: Hydrangea paniculata | C12: Lacy panicle | D12: Open
... A65: WHITE DOME | B65: Hydrangea arborescens | C65: Lacy | D65: Open

Sheet PivotTableCount
A3: Row Labels | B3: Count of InsectRichness
A4: Annabelle | B4: 2
A5: Baby Lace | B5: 4
A6: Bella Anna | B6: 3
A7: Berry White | B7: 2
A8: Big Ben | B8: 1
A9: Bobo | B9: 5
A10: Bounty | B10: 3
A11: Brussels Lace | B11: 5
A12: Candy Apple | B12: 8
A13: Daimond Rogue | B13: 4
A14: Dharuma | B14: 8
A15: Dolly | B15: 3
... A64: Grand Total | B64: 287

Sheet RawData
B1: Date | C1: Month | D1: Tag.Number | E1: Collector | F1: Cultivar | G1: Species | H1: AscensionNumber | I1: Inflorescence.Type | J1: False.Sepals | K1: Flower.Type | L1: PaniclesPerTransect | M1: TotalPaniclesA | N1: AvgInflorescencesPerPanicle | O1: transects_per_plant | P1: TotalPaniclesB | Q1: TotalInflorescences_A | R1: TotalInflorescences_B | S1: TotalInflorescences_AB | T1: Start.Time | U1: End.Time | V1: Rain | W1: Wind | X1: Cloud | Y1: TempF | Z1: InsectRichness | AA1: Araneae | AB1: Chauliognathus | AC1: Cerambycidae | AD1: Chrysomelidae | AE1: Curculionidae | AF1: Mordellidae | AG1: Scarabaeoidea | AH1: Diptera | AI1: Bombyliidae | AJ1: Calliphoridae | AK1: Conopidae | AL1: Cecidomyiidae | AM1: Culicidae | AN1: Dolichopodidae | AO1: Drosophilidae | AP1: Empididae | AQ1: Muscidae | AR1: Oestroidea | AS1: Syrphidae_total | AT1: Unknown_Bristly_Flies | AU1: Tipulidae | AV1: Ulidiidae | AW1: Hemiptera | AX1: Aphididae | AY1: Cicadellidae | AZ1: Miridae | BA1: Reduviidae | BB1: Hymenoptera | BC1: Xylocopa | BD1: Andrenidae | BE1: Protandrena | BF1: Apis.mellifera | BG1: Melissodes | BH1: Cerceris | BI1: Astata | BJ1: Chrysididae | BK1: Hylaeus | BL1: Halictidae | BM1: Agapostemon | BN1: Augochlora | BO1: Green.Sweatbee | BP1: Halictus | BQ1: Lasioglossum | BR1: Bombus affinis | BS1: Bombus auricomus | BT1: Bombus impatiens | BU1: Bombus bimaculatus | BV1: Bombus griseocollis | BW1: Bombus vagans | BX1: Symmorphus | BY1: Eurytoma | BZ1: Braconidae | CA1: Apocrita | CB1: Scolia | CC1: Sphecius speciosus | CD1: Sphex | CE1: Vespidae | CF1: Dolichovespula.maculata | CG1: Dolichovespula | CH1: Lepidoptera | CI1: Hesperiidae | CJ1: Celastrina ladon | CK1: Epargyreus clarus | CL1: Libythean carinenta | CM1: Pieris rapae | CN1: Polygonia comma | CO1: Vanessa atalanta | CP1: Notes
A2: 1 | B2: 45483 | C2: Jul | D2: 11A | E2: E. Braatz | F2: Dharuma | G2: Hydrangea paniculata | H2: 5026 | I2: Open | J2: 4 | K2: Lacy panicle | M2: NA | N2: NA | O2: #VALUE! | P2: #VALUE! | Q2: #VALUE! | R2: #VALUE! | S2: NA | T2: 0.52638889 | U2: 0.52986111 | V2: 0 | W2: 1 | X2: 40 | Y2: 73 | Z2: 5 | AA2: 0 | AB2: 0 | AC2: 0 | AD2: 0 | AE2: 0 | AF2: 0 | AG2: 0 | AH2: 0 | AI2: 0 | AJ2: 1 | AK2: 0 | AL2: 0 | AM2: 0 | AN2: 0 | AO2: 0 | AP2: 0 | AQ2: 0 | AR2: 0 | AS2: 1 | AT2: 0 | AU2: 0 | AV2: 0 | AW2: 0 | AX2: 0 | AY2: 0 | AZ2: 0 | BA2: 0 | BB2: 0 | BC2: 0 | BD2: 0 | BE2: 0 | BF2: 0 | BG2: 0 | BH2: 0 | BI2: 0 | BJ2: 0 | BK2: 0 | BL2: 0 | BM2: 0 | BN2: 0 | BO2: 0 | BP2: 1 | BQ2: 1 | BR2: 0 | BS2: 0 | BT2: 0 | BU2: 0 | BV2: 0 | BW2: 0 | BX2: 0 | BY2: 0 | BZ2: 0 | CA2: 0 | CB2: 0 | CC2: 0 | CD2: 0 | CE2: 0 | CF2: 0 | CG2: 0 | CH2: 0 | CI2: 0 | CJ2: 0 | CK2: 0 | CL2: 0 | CM2: 0 | CN2: 0 | CO2: 1
A3: 2 | B3: 45483 | C3: Jul | D3: 11E | E3: E. Braatz | F3: Seaside Serenade Bar | G3: Hydrangea arborescens | H3: 19008B | I3: Dense | J3: 4 | K3: Mop | M3: NA | N3: 388.8 | O3: 8.3053 | P3: 0 | Q3: 0 | R3: 0 | S3: NA | T3: 0.58263889 | U3: 0.58611111 | V3: 0 | W3: 2 | X3: 40 | Y3: 75 | Z3: 2 | AA3: 0 | AB3: 0 | AC3: 0 | AD3: 0 | AE3: 0 | AF3: 0 | AG3: 0 | AH3: 0 | AI3: 0 | AJ3: 0 | AK3: 0 | AL3: 0 | AM3: 0 | AN3: 0 | AO3: 0 | AP3: 0 | AQ3: 0 | AR3: 0 | AS3: 1 | AT3: 0 | AU3: 0 | AV3: 0 | AW3: 0 | AX3: 0 | AY3: 0 | AZ3: 0 | BA3: 0 | BB3: 0 | BC3: 0 | BD3: 0 | BE3: 0 | BF3: 0 | BG3: 0 | BH3: 0 | BI3: 0 | BJ3: 0 | BK3: 0 | BL3: 0 | BM3: 0 | BN3: 0 | BO3: 0 | BP3: 0 | BQ3: 1 | BR3: 0 | BS3: 0 | BT3: 0 | BU3: 0 | BV3: 0 | BW3: 0 | BX3: 0 | BY3: 0 | BZ3: 0 | CA3: 0 | CB3: 0 | CC3: 0 | CD3: 0 | CE3: 0 | CF3: 0 | CG3: 0 | CH3: 0 | CI3: 0 | CJ3: 0 | CK3: 0 | CL3: 0 | CM3: 0 | CN3: 0 | CO3: 0
A4: 3 | B4: 45483 | C4: Jul | D4: 1A | E4: E. Braatz | F4: Strawberry Shake | G4: Hydrangea paniculata | H4: 18031B | I4: Very dense | J4: 4 | K4: Mop-like panicle | M4: NA | N4: 68.4 | O4: 4.1488433 | P4: 0 | Q4: 0 | R4: 0 | S4: NA | T4: 0.49722222 | U4: 0.50069444 | V4: 0 | W4: 1 | X4: 10 | Y4: 72 | Z4: 6 | AA4: 0 | AB4: 0 | AC4: 0 | AD4: 0 | AE4: 0 | AF4: 0 | AG4: 0 | AH4: 0 | AI4: 0 | AJ4: 1 | AK4: 0 | AL4: 0 | AM4: 0 | AN4: 1 | AO4: 0 | AP4: 0 | AQ4: 0 | AR4: 0 | AS4: 1 | AT4: 1 | AU4: 0 | AV4: 0 | AW4: 0 | AX4: 0 | AY4: 0 | AZ4: 0 | BA4: 0 | BB4: 0 | BC4: 0 | BD4: 0 | BE4: 0 | BF4: 0 | BG4: 0 | BH4: 0 | BI4: 0 | BJ4: 0 | BK4: 0 | BL4: 0 | BM4: 0 | BN4: 0 | BO4: 0 | BP4: 0 | BQ4: 1 | BR4: 0 | BS4: 0 | BT4: 0 | BU4: 0 | BV4: 0 | BW4: 0 | BX4: 0 | BY4: 0 | BZ4: 0 | CA4: 0 | CB4: 0 | CC4: 0 | CD4: 0 | CE4: 1 | CF4: 0 | CG4: 0 | CH4: 0 | CI4: 0 | CJ4: 0 | CK4: 0 | CL4: 0 | CM4: 0 | CN4: 0 | CO4: 0
A5: 4 | B5: 45483 | C5: Jul | D5: 4A | E5: E. Braatz | F5: White Diamonds | G5: Hydrangea paniculata | H5: 11045 | I5: Half-open | J5: 4 | K5: Mop-like panicle | M5: NA | N5: 31 | O5: 9.0432 | P5: 0 | Q5: 0 | R5: 0 | S5: NA | T5: 0.50833333 | U5: 0.51180556 | V5: 0 | W5: 1 | X5: 10 | Y5: 72 | Z5: 2 | AA5: 0 | AB5: 0 | AC5: 0 | AD5: 0 | AE5: 0 | AF5: 0 | AG5: 0 | AH5: 0 | AI5: 0 | AJ5: 0 | AK5: 0 | AL5: 0 | AM5: 0 | AN5: 0 | AO5: 0 | AP5: 0 | AQ5: 0 | AR5: 0 | AS5: 1 | AT5: 0 | AU5: 0 | AV5: 0 | AW5: 0 | AX5: 0 | AY5: 0 | AZ5: 0 | BA5: 0 | BB5: 0 | BC5: 0 | BD5: 0 | BE5: 0 | BF5: 0 | BG5: 0 | BH5: 0 | BI5: 0 | BJ5: 0 | BK5: 0 | BL5: 0 | BM5: 0 | BN5: 0 | BO5: 0 | BP5: 0 | BQ5: 0 | BR5: 0 | BS5: 0 | BT5: 0 | BU5: 0 | BV5: 0 | BW5: 0 | BX5: 0 | BY5: 0 | BZ5: 0 | CA5: 0 | CB5: 0 | CC5: 0 | CD5: 0 | CE5: 0 | CF5: 0 | CG5: 0 | CH5: 0 | CI5: 0 | CJ5: 0 | CK5: 1 | CL5: 0 | CM5: 0 | CN5: 0 | CO5: 0
A6: 5 | B6: 45483 | C6: Jul | D6: 5A | E6: E. Braatz | F6: Quick Fire | G6: Hydrangea paniculata | H6: 5079 | I6: Open | J6: 4 | K6: Lacy panicle | M6: NA | N6: 98.6 | O6: 14.13 | P6: 0 | Q6: 0 | R6: 0 | S6: NA | T6: 0.4875 | U6: 0.49097222 | V6: 0 | W6: 1 | X6: 10 | Y6: 72 | Z6: 7 | AA6: 0 | AB6: 0 | AC6: 0 | AD6: 0 | AE6: 0 | AF6: 0 | AG6: 0 | AH6: 0 | AI6: 1 | AJ6: 1 | AK6: 0 | AL6: 0 | AM6: 0 | AN6: 0 | AO6: 0 | AP6: 0 | AQ6: 0 | AR6: 0 | AS6: 1 | AT6: 1 | AU6: 0 | AV6: 0 | AW6: 0 | AX6: 0 | AY6: 0 | AZ6: 0 | BA6: 0 | BB6: 0 | BC6: 0 | BD6: 0 | BE6: 0 | BF6: 1 | BG6: 0 | BH6: 0 | BI6: 0 | BJ6: 0 | BK6: 0 | BL6: 0 | BM6: 0 | BN6: 0 | BO6: 0 | BP6: 1 | BQ6: 1 | BR6: 0 | BS6: 0 | BT6: 0 | BU6: 0 | BV6: 0 | BW6: 0 | BX6: 0 | BY6: 0 | BZ6: 0 | CA6: 0 | CB6: 0 | CC6: 0 | CD6: 0 | CE6: 0 | CF6: 0 | CG6: 0 | CH6: 0 | CI6: 0 | CJ6: 0 | CK6: 0 | CL6: 0 | CM6: 0 | CN6: 0 | CO6: 0
A7: 6 | B7: 45483 | C7: Jul | D7: 8A | E7: E. Braatz | F7: Mega Pearl | G7: Hydrangea paniculata | H7: 1128 | I7: Dense | J7: 4 | K7: Mop-like panicle | M7: NA | N7: 36.1 | O7: 8.3053 | P7: 0 | Q7: 0 | R7: 0 | S7: NA | T7: 0.51805556 | U7: 0.52152778 | V7: 0 | W7: 1 | X7: 40 | Y7: 73 | Z7: 1 | AA7: 0 | AB7: 0 | AC7: 0 | AD7: 0 | AE7: 0 | AF7: 0 | AG7: 0 | AH7: 0 | AI7: 0 | AJ7: 0 | AK7: 0 | AL7: 0 | AM7: 0 | AN7: 0 | AO7: 0 | AP7: 0 | AQ7: 0 | AR7: 0 | AS7: 1 | AT7: 0 | AU7: 0 | AV7: 0 | AW7: 0 | AX7: 0 | AY7: 0 | AZ7: 0 | BA7: 0 | BB7: 0 | BC7: 0 | BD7: 0 | BE7: 0 | BF7: 0 | BG7: 0 | BH7: 0 | BI7: 0 | BJ7: 0 | BK7: 0 | BL7: 0 | BM7: 0 | BN7: 0 | BO7: 0 | BP7: 0 | BQ7: 0 | BR7: 0 | BS7: 0 | BT7: 0 | BU7: 0 | BV7: 0 | BW7: 0 | BX7: 0 | BY7: 0 | BZ7: 0 | CA7: 0 | CB7: 0 | CC7: 0 | CD7: 0 | CE7: 0 | CF7: 0 | CG7: 0 | CH7: 0 | CI7: 0 | CJ7: 0 | CK7: 0 | CL7: 0 | CM7: 0 | CN7: 0 | CO7: 0
A8: 7 | B8: 45483 | C8: Jul | D8: 9A | E8: E. Braatz | F8: Fire & Ice | G8: Hydrangea paniculata | H8: 12021 | I8: Open | J8: 4 | K8: Lacy panicle | M8: NA | N8: 97.8 | O8: 6.28 | P8: 0 | Q8: 0 | R8: 0 | S8: NA | T8: 0.47777778 | U8: 0.49097222 | V8: 0 | W8: 1 | X8: 10 | Y8: 72 | Z8: 7 | AA8: 0 | AB8: 0 | AC8: 0 | AD8: 0 | AE8: 0 | AF8: 0 | AG8: 0 | AH8: 0 | AI8: 0 | AJ8: 0 | AK8: 0 | AL8: 0 | AM8: 0 | AN8: 0 | AO8: 0 | AP8: 0 | AQ8: 0 | AR8: 0 | AS8: 1 | AT8: 1 | AU8: 0 | AV8: 0 | AW8: 0 | AX8: 0 | AY8: 0 | AZ8: 0 | BA8: 0 | BB8: 0 | BC8: 0 | BD8: 0 | BE8: 0 | BF8: 0 | BG8: 0 | BH8: 0 | BI8: 0 | BJ8: 0 | BK8: 1 | BL8: 0 | BM8: 0 | BN8: 0 | BO8: 0 | BP8: 1 | BQ8: 1 | BR8: 0 | BS8: 0 | BT8: 0 | BU8: 0 | BV8: 0 | BW8: 0 | BX8: 0 | BY8: 0 | BZ8: 0 | CA8: 0 | CB8: 0 | CC8: 0 | CD8: 0 | CE8: 1 | CF8: 0 | CG8: 0 | CH8: 0 | CI8: 0 | CJ8: 0 | CK8: 0 | CL8: 0 | CM8: 0 | CN8: 0 | CO8: 1
A9: 8 | B9: 45486 | C9: Jul | D9: 12F | E9: E. Braatz | F9: White Dome | G9: Hydrangea arborescens | H9: 2068 | I9: Open | J9: 4 | K9: Lacy | M9: NA | N9: 278.5 | O9: #VALUE! | T9: NA | U9: NA | V9: NA | W9: NA | X9: NA | Y9: NA | Z9: 9 | AA9: 0 | AB9: 0 | AC9: 0 | AD9: 0 | AE9: 0 | AF9: 1 | AG9: 0 | AH9: 0 | AI9: 0 | AJ9: 0 | AK9: 1 | AL9: 0 | AM9: 0 | AN9: 1 | AO9: 0 | AP9: 0 | AQ9: 0 | AR9: 0 | AS9: 1 | AT9: 0 | AU9: 0 | AV9: 0 | AW9: 0 | AX9: 0 | AY9: 0 | AZ9: 1 | BA9: 0 | BB9: 0 | BC9: 0 | BD9: 0 | BE9: 0 | BF9: 0 | BG9: 0 | BH9: 0 | BI9: 0 | BJ9: 0 | BK9: 1 | BL9: 0 | BM9: 0 | BN9: 0 | BO9: 0 | BP9: 1 | BQ9: 1 | BR9: 0 | BS9: 0 | BT9: 0 | BU9: 0 | BV9: 0 | BW9: 0 | BX9: 0 | BY9: 0 | BZ9: 0 | CA9: 0 | CB9: 0 | CC9: 0 | CD9: 0 | CE9: 1 | CF9: 0 | CG9: 0 | CH9: 0 | CI9: 0 | CJ9: 0 | CK9: 0 | CL9: 0 | CM9: 0 | CN9: 0 | CO9: 0
A10: 9 | B10: 45490 | C10: Jul | D10: 10C | E10: E. Braatz | F10: Fire Light | G10: Hydrangea paniculata | H10: 14026 | I10: Dense | J10: 4 | K10: Mop-like panicle | M10: NA | N10: 76.5 | O10: 8.5731958 | P10: 0 | Q10: 0 | R10: 0 | S10: NA | T10: 0.43541667 | U10: 0.43888889 | V10: 0 | W10: 2 | X10: 0 | Y10: 71 | Z10: 1 | AA10: 0 | AB10: 0 | AC10: 0 | AD10: 0 | AE10: 0 | AF10: 0 | AG10: 0 | AH10: 0 | AI10: 0 | AJ10: 0 | AK10: 0 | AL10: 0 | AM10: 0 | AN10: 0 | AO10: 0 | AP10: 0 | AQ10: 0 | AR10: 0 | AS10: 0 | AT10: 0 | AU10: 0 | AV10: 0 | AW10: 0 | AX10: 0 | AY10: 0 | AZ10: 0 | BA10: 0 | BB10: 0 | BC10: 0 | BD10: 0 | BE10: 0 | BF10: 0 | BG10: 0 | BH10: 0 | BI10: 0 | BJ10: 0 | BK10: 0 | BL10: 0 | BM10: 0 | BN10: 0 | BO10: 0 | BP10: 0 | BQ10: 1 | BR10: 0 | BS10: 0 | BT10: 0 | BU10: 0 | BV10: 0 | BW10: 0 | BX10: 0 | BY10: 0 | BZ10: 0 | CA10: 0 | CB10: 0 | CC10: 0 | CD10: 0 | CE10: 0 | CF10: 0 | CG10: 0 | CH10: 0 | CI10: 0 | CJ10: 0 | CK10: 0 | CL10: 0 | CM10: 0 | CN10: 0 | CO10: 0
A11: 10 | B11: 45490 | C11: Jul | D11: 10D | E11: E. Braatz | F11: Daimond Rogue | G11: Hydrangea paniculata | H11: 17047 | I11: Half-open | J11: 4 | K11: Mop-like panicle | M11: NA | N11: 109 | O11: 9.3348975 | P11: 0 | Q11: 0 | R11: 0 | S11: NA | T11: 0.65833333 | U11: 0.66180556 | V11: 0 | W11: 2 | X11: 40 | Y11: 77 | Z11: 2 | AA11: 0 | AB11: 0 | AC11: 0 | AD11: 0 | AE11: 0 | AF11: 0 | AG11: 0 | AH11: 0 | AI11: 0 | AJ11: 0 | AK11: 0 | AL11: 0 | AM11: 0 | AN11: 0 | AO11: 0 | AP11: 0 | AQ11: 0 | AR11: 0 | AS11: 1 | AT11: 0 | AU11: 0 | AV11: 0 | AW11: 0 | AX11: 0 | AY11: 0 | AZ11: 0 | BA11: 0 | BB11: 0 | BC11: 0 | BD11: 0 | BE11: 0 | BF11: 0 | BG11: 0 | BH11: 0 | BI11: 0 | BJ11: 0 | BK11: 0 | BL11: 0 | BM11: 0 | BN11: 0 | BO11: 0 | BP11: 0 | BQ11: 1 | BR11: 0 | BS11: 0 | BT11: 0 | BU11: 0 | BV11: 0 | BW11: 0 | BX11: 0 | BY11: 0 | BZ11: 0 | CA11: 0 | CB11: 0 | CC11: 0 | CD11: 0 | CE11: 0 | CF11: 0 | CG11: 0 | CH11: 0 | CI11: 0 | CJ11: 0 | CK11: 0 | CL11: 0 | CM11: 0 | CN11: 0 | CO11: 0
A12: 11 | B12: 45490 | C12: Jul | D12: 10D | E12: E. Braatz | F12: Daimond Rogue | G12: Hydrangea paniculata | H12: 17047 | I12: Half-open | J12: 4 | K12: Mop-like panicle | M12: NA | N12: 109 | O12: 9.3348975 | P12: 0 | Q12: 0 | R12: 0 | S12: NA | T12: 0.65833333 | U12: 0.66180556 | V12: 0 | W12: 2 | X12: 40 | Y12: 77 | Z12: 1 | AA12: 0 | AB12: 0 | AC12: 0 | AD12: 0 | AE12: 0 | AF12: 0 | AG12: 0 | AH12: 0 | AI12: 0 | AJ12: 0 | AK12: 0 | AL12: 0 | AM12: 0 | AN12: 0 | AO12: 0 | AP12: 0 | AQ12: 0 | AR12: 0 | AS12: 0 | AT12: 1 | AU12: 0 | AV12: 0 | AW12: 0 | AX12: 0 | AY12: 0 | AZ12: 0 | BA12: 0 | BB12: 0 | BC12: 0 | BD12: 0 | BE12: 0 | BF12: 0 | BG12: 0 | BH12: 0 | BI12: 0 | BJ12: 0 | BK12: 0 | BL12: 0 | BM12: 0 | BN12: 0 | BO12: 0 | BP12: 0 | BQ12: 0 | BR12: 0 | BS12: 0 | BT12: 0 | BU12: 0 | BV12: 0 | BW12: 0 | BX12: 0 | BY12: 0 | BZ12: 0 | CA12: 0 | CB12: 0 | CC12: 0 | CD12: 0 | CE12: 0 | CF12: 0 | CG12: 0 | CH12: 0 | CI12: 0 | CJ12: 0 | CK12: 0 | CL12: 0 | CM12: 0 | CN12: 0 | CO12: 0
A13: 12 | B13: 45490 | C13: Jul | D13: 11C | E13: E. Braatz | F13: Little Quick Fire | G13: Hydrangea paniculata | H13: 14010 | I13: Open | J13: 4 | K13: Lacy panicle | M13: NA | N13: 59.7 | O13: 5.546647 | P13: 0 | Q13: 0 | R13: 0 | S13: NA | T13: 0.42361111 | U13: 0.42708333 | V13: 0 | W13: 2 | X13: 0 | Y13: 71 | Z13: 4 | AA13: 0 | AB13: 0 | AC13: 0 | AD13: 0 | AE13: 0 | AF13: 0 | AG13: 0 | AH13: 0 | AI13: 0 | AJ13: 0 | AK13: 0 | AL13: 0 | AM13: 0 | AN13: 0 | AO13: 0 | AP13: 0 | AQ13: 0 | AR13: 0 | AS13: 0 | AT13: 1 | AU13: 0 | AV13: 0 | AW13: 0 | AX13: 0 | AY13: 0 | AZ13: 0 | BA13: 0 | BB13: 0 | BC13: 0 | BD13: 0 | BE13: 0 | BF13: 0 | BG13: 0 | BH13: 0 | BI13: 0 | BJ13: 0 | BK13: 0 | BL13: 0 | BM13: 0 | BN13: 0 | BO13: 0 | BP13: 1 | BQ13: 1 | BR13: 0 | BS13: 0 | BT13: 0 | BU13: 0 | BV13: 0 | BW13: 0 | BX13: 0 | BY13: 0 | BZ13: 0 | CA13: 0 | CB13: 0 | CC13: 0 | CD13: 0 | CE13: 0 | CF13: 0 | CG13: 1 | CH13: 0 | CI13: 0 | CJ13: 0 | CK13: 0 | CL13: 0 | CM13: 0 | CN13: 0 | CO13: 0
A14: 13 | B14: 45490 | C14: Jul | D14: 12F | E14: E. Braatz | F14: White Dome | G14: Hydrangea arborescens | H14: 2068 | I14: Open | J14: 4 | K14: Lacy | M14: NA | N14: 278.5 | O14: #VALUE! | P14: #VALUE! | Q14: 0 | R14: #VALUE! | S14: NA | T14: 0.49652778 | U14: 0.5 | V14: 0 | W14: 1 | X14: 20 | Y14: 73 | Z14: 2 | AA14: 0 | AB14: 0 | AC14: 0 | AD14: 0 | AE14: 0 | AF14: 0 | AG14: 0 | AH14: 0 | AI14: 0 | AJ14: 0 | AK14: 0 | AL14: 0 | AM14: 0 | AN14: 0 | AO14: 0 | AP14: 0 | AQ14: 0 | AR14: 0 | AS14: 0 | AT14: 0 | AU14: 0 | AV14: 0 | AW14: 0 | AX14: 0 | AY14: 0 | AZ14: 0 | BA14: 0 | BB14: 0 | BC14: 0 | BD14: 0 | BE14: 0 | BF14: 0 | BG14: 0 | BH14: 0 | BI14: 0 | BJ14: 0 | BK14: 0 | BL14: 0 | BM14: 0 | BN14: 0 | BO14: 0 | BP14: 0 | BQ14: 1 | BR14: 0 | BS14: 0 | BT14: 1 | BU14: 0 | BV14: 0 | BW14: 0 | BX14: 0 | BY14: 0 | BZ14: 0 | CA14: 0 | CB14: 0 | CC14: 0 | CD14: 0 | CE14: 0 | CF14: 0 | CG14: 0 | CH14: 0 | CI14: 0 | CJ14: 0 | CK14: 0 | CL14: 0 | CM14: 0 | CN14: 0 | CO14: 0
A15: 14 | B15: 45490 | C15: Jul | D15: 13C | E15: E. Braatz | F15: Fire Light | G15: Hydrangea paniculata | H15: 18008B | I15: Very dense | J15: NA | K15: Mop-like panicle | M15: NA | N15: 71.4 | O15: 8.949995 | P15: 0 | Q15: 0 | R15: 0 | S15: NA | T15: 0.39652778 | U15: 0.4 | V15: 0 | W15: 2 | X15: 0 | Y15: 71 | Z15: 5 | AA15: 0 | AB15: 0 | AC15: 0 | AD15: 0 | AE15: 0 | AF15: 0 | AG15: 0 | AH15: 0 | AI15: 0 | AJ15: 1 | AK15: 0 | AL15: 0 | AM15: 0 | AN15: 1 | AO15: 0 | AP15: 0 | AQ15: 0 | AR15: 0 | AS15: 0 | AT15: 1 | AU15: 0 | AV15: 0 | AW15: 0 | AX15: 0 | AY15: 0 | AZ15: 0 | BA15: 0 | BB15: 0 | BC15: 0 | BD15: 0 | BE15: 0 | BF15: 1 | BG15: 0 | BH15: 0 | BI15: 0 | BJ15: 0 | BK15: 0 | BL15: 0 | BM15: 0 | BN15: 0 | BO15: 0 | BP15: 0 | BQ15: 1 | BR15: 0 | BS15: 0 | BT15: 0 | BU15: 0 | BV15: 0 | BW15: 0 | BX15: 0 | BY15: 0 | BZ15: 0 | CA15: 0 | CB15: 0 | CC15: 0 | CD15: 0 | CE15: 0 | CF15: 0 | CG15: 0 | CH15: 0 | CI15: 0 | CJ15: 0 | CK15: 0 | CL15: 0 | CM15: 0 | CN15: 0 | CO15: 0
A16: 15 | B16: 45490 | C16: Jul | D16: 14C | E16: E. Braatz | F16: Fire Light | G16: Hydrangea paniculata | H16: 18008A | I16: Dense | J16: 4 | K16: Mop-like panicle | M16: NA | N16: 94.3 | O16: 8.5731958 | P16: 0 | Q16: 0 | R16: 0 | S16: NA | T16: 0.40625 | U16: 0.40972222 | V16: 0 | W16: 2 | X16: 0 | Y16: 71 | Z16: 4 | AA16: 0 | AB16: 0 | AC16: 0 | AD16: 0 | AE16: 0 | AF16: 0 | AG16: 0 | AH16: 0 | AI16: 0 | AJ16: 0 | AK16: 0 | AL16: 0 | AM16: 0 | AN16: 1 | AO16: 0 | AP16: 0 | AQ16: 0 | AR16: 0 | AS16: 0 | AT16: 0 | AU16: 0 | AV16: 0 | AW16: 0 | AX16: 0 | AY16: 1 | AZ16: 0 | BA16: 0 | BB16: 0 | BC16: 0 | BD16: 0 | BE16: 0 | BF16: 0 | BG16: 0 | BH16: 0 | BI16: 0 | BJ16: 0 | BK16: 0 | BL16: 0 | BM16: 0 | BN16: 0 | BO16: 0 | BP16: 0 | BQ16: 1 | BR16: 0 | BS16: 0 | BT16: 0 | BU16: 0 | BV16: 0 | BW16: 0 | BX16: 0 | BY16: 0 | BZ16: 0 | CA16: 0 | CB16: 0 | CC16: 0 | CD16: 0 | CE16: 0 | CF16: 0 | CG16: 1 | CH16: 0 | CI16: 0 | CJ16: 0 | CK16: 0 | CL16: 0 | CM16: 0 | CN16: 0 | CO16: 0
A17: 16 | B17: 45490 | C17: Jul | D17: 16C | E17: E. Braatz | F17: Quick Fire | G17: Hydrangea paniculata | H17: 14001 | I17: Open | J17: 4 | K17: Lacy panicle | M17: NA | N17: 25.9 | O17: 8.2044997 | P17: 0 | Q17: 0 | R17: 0 | S17: NA | T17: 0.64652778 | U17: 0.65 | V17: 0 | W17: 2 | X17: 25 | Y17: 73 | Z17: 3 | AA17: 0 | AB17: 0 | AC17: 0 | AD17: 0 | AE17: 0 | AF17: 0 | AG17: 0 | AH17: 0 | AI17: 0 | AJ17: 1 | AK17: 0 | AL17: 0 | AM17: 0 | AN17: 0 | AO17: 0 | AP17: 0 | AQ17: 0 | AR17: 0 | AS17: 1 | AT17: 1 | AU17: 0 | AV17: 0 | AW17: 0 | AX17: 0 | AY17: 0 | AZ17: 0 | BA17: 0 | BB17: 0 | BC17: 0 | BD17: 0 | BE17: 0 | BF17: 0 | BG17: 0 | BH17: 0 | BI17: 0 | BJ17: 0 | BK17: 0 | BL17: 0 | BM17: 0 | BN17: 0 | BO17: 0 | BP17: 0 | BQ17: 0 | BR17: 0 | BS17: 0 | BT17: 0 | BU17: 0 | BV17: 0 | BW17: 0 | BX17: 0 | BY17: 0 | BZ17: 0 | CA17: 0 | CB17: 0 | CC17: 0 | CD17: 0 | CE17: 0 | CF17: 0 | CG17: 0 | CH17: 0 | CI17: 0 | CJ17: 0 | CK17: 0 | CL17: 0 | CM17: 0 | CN17: 0 | CO17: 0
A18: 17 | B18: 45490 | C18: Jul | D18: 16C | E18: E. Braatz | F18: Quick Fire | G18: Hydrangea paniculata | H18: 14001 | I18: Open | J18: 4 | K18: Lacy panicle | M18: NA | N18: 25.9 | O18: 8.2044997 | P18: 0 | Q18: 0 | R18: 0 | S18: NA | T18: 0.46805556 | U18: 0.47152778 | V18: 0 | W18: 2 | X18: 5 | Y18: 73 | Z18: 3 | AA18: 0 | AB18: 0 | AC18: 0 | AD18: 0 | AE18: 0 | AF18: 0 | AG18: 0 | AH18: 0 | AI18: 0 | AJ18: 1 | AK18: 0 | AL18: 0 | AM18: 0 | AN18: 0 | AO18: 0 | AP18: 0 | AQ18: 0 | AR18: 0 | AS18: 1 | AT18: 1 | AU18: 0 | AV18: 0 | AW18: 0 | AX18: 0 | AY18: 0 | AZ18: 0 | BA18: 0 | BB18: 0 | BC18: 0 | BD18: 0 | BE18: 0 | BF18: 0 | BG18: 0 | BH18: 0 | BI18: 0 | BJ18: 0 | BK18: 0 | BL18: 0 | BM18: 0 | BN18: 0 | BO18: 0 | BP18: 0 | BQ18: 0 | BR18: 0 | BS18: 0 | BT18: 0 | BU18: 0 | BV18: 0 | BW18: 0 | BX18: 0 | BY18: 0 | BZ18: 0 | CA18: 0 | CB18: 0 | CC18: 0 | CD18: 0 | CE18: 0 | CF18: 0 | CG18: 0 | CH18: 0 | CI18: 0 | CJ18: 0 | CK18: 0 | CL18: 0 | CM18: 0 | CN18: 0 | CO18: 0 | CP18: Goldenrod soldier beetles
A19: 18 | B19: 45490 | C19: Jul | D19: 18D | E19: E. Braatz | F19: Bobo | G19: Hydrangea paniculata | H19: 12031B | I19: Half-open | J19: 4 | K19: Mop-like panicle | M19: NA | N19: 72.1 | O19: 6.1624909 | P19: 0 | Q19: 0 | R19: 0 | S19: NA | T19: 0.67638889 | U19: 0.67986111 | V19: 0 | W19: 2 | X19: 40 | Y19: 77 | Z19: 2 | AA19: 0 | AB19: 0 | AC19: 0 | AD19: 0 | AE19: 0 | AF19: 0 | AG19: 0 | AH19: 0 | AI19: 0 | AJ19: 1 | AK19: 0 | AL19: 0 | AM19: 0 | AN19: 1 | AO19: 0 | AP19: 0 | AQ19: 0 | AR19: 0 | AS19: 0 | AT19: 0 | AU19: 0 | AV19: 0 | AW19: 0 | AX19: 0 | AY19: 0 | AZ19: 0 | BA19: 0 | BB19: 0 | BC19: 0 | BD19: 0 | BE19: 0 | BF19: 0 | BG19: 0 | BH19: 0 | BI19: 0 | BJ19: 0 | BK19: 0 | BL19: 0 | BM19: 0 | BN19: 0 | BO19: 0 | BP19: 0 | BQ19: 0 | BR19: 0 | BS19: 0 | BT19: 0 | BU19: 0 | BV19: 0 | BW19: 0 | BX19: 0 | BY19: 0 | BZ19: 0 | CA19: 0 | CB19: 0 | CC19: 0 | CD19: 0 | CE19: 0 | CF19: 0 | CG19: 0 | CH19: 0 | CI19: 0 | CJ19: 0 | CK19: 0 | CL19: 0 | CM19: 0 | CN19: 0 | CO19: 0
A20: 19 | B20: 45490 | C20: Jul | D20: 2C | E20: E. Braatz | F20: Pinky Winky | G20: Hydrangea paniculata | H20: 14022 | I20: Half-open | J20: 4 | K20: Mop-like panicle | M20: NA | N20: 47.1 | O20: 5.546647 | P20: 0 | Q20: 0 | R20: 0 | S20: NA | T20: 0.48055556 | U20: 0.48402778 | V20: 0 | W20: 2 | X20: 5 | Y20: 73 | Z20: 4 | AA20: 0 | AB20: 0 | AC20: 0 | AD20: 0 | AE20: 0 | AF20: 0 | AG20: 0 | AH20: 0 | AI20: 0 | AJ20: 1 | AK20: 0 | AL20: 0 | AM20: 0 | AN20: 0 | AO20: 0 | AP20: 0 | AQ20: 0 | AR20: 0 | AS20: 1 | AT20: 0 | AU20: 0 | AV20: 0 | AW20: 0 | AX20: 0 | AY20: 0 | AZ20: 0 | BA20: 0 | BB20: 0 | BC20: 0 | BD20: 0 | BE20: 0 | BF20: 0 | BG20: 0 | BH20: 0 | BI20: 0 | BJ20: 0 | BK20: 0 | BL20: 0 | BM20: 0 | BN20: 0 | BO20: 0 | BP20: 0 | BQ20: 1 | BR20: 0 | BS20: 0 | BT20: 1 | BU20: 0 | BV20: 0 | BW20: 0 | BX20: 0 | BY20: 0 | BZ20: 0 | CA20: 0 | CB20: 0 | CC20: 0 | CD20: 0 | CE20: 0 | CF20: 0 | CG20: 0 | CH20: 0 | CI20: 0 | CJ20: 0 | CK20: 0 | CL20: 0 | CM20: 0 | CN20: 0 | CO20: 0
A21: 20 | B21: 45490 | C21: Jul | D21: 2F | E21: E. Braatz | F21: Silver Leaf | G21: Hydrangea arborescens | H21: Unknown | I21: Open | J21: 4 | K21: Lacy | M21: NA | N21: 390.5 | O21: 3.6464443 | P21: 0 | Q21: 0 | R21: 0 | S21: NA | T21: 0.55625 | U21: 0.55972222 | V21: 0 | W21: 2 | X21: 25 | Y21: 75 | Z21: 5 | AA21: 0 | AB21: 0 | AC21: 0 | AD21: 0 | AE21: 0 | AF21: 0 | AG21: 0 | AH21: 0 | AI21: 0 | AJ21: 0 | AK21: 0 | AL21: 0 | AM21: 0 | AN21: 0 | AO21: 0 | AP21: 0 | AQ21: 0 | AR21: 0 | AS21: 0 | AT21: 0 | AU21: 0 | AV21: 0 | AW21: 0 | AX21: 0 | AY21: 0 | AZ21: 0 | BA21: 0 | BB21: 0 | BC21: 0 | BD21: 0 | BE21: 0 | BF21: 0 | BG21: 0 | BH21: 0 | BI21: 0 | BJ21: 0 | BK21: 0 | BL21: 0 | BM21: 0 | BN21: 0 | BO21: 0 | BP21: 1 | BQ21: 1 | BR21: 0 | BS21: 0 | BT21: 1 | BU21: 0 | BV21: 0 | BW21: 0 | BX21: 0 | BY21: 0 | BZ21: 0 | CA21: 1 | CB21: 0 | CC21: 0 | CD21: 0 | CE21: 1 | CF21: 0 | CG21: 0 | CH21: 0 | CI21: 0 | CJ21: 0 | CK21: 0 | CL21: 0 | CM21: 0 | CN21: 0 | CO21: 0 | CP21: Syrphid fly escaped
A22: 21 | B22: 45490 | C22: Jul | D22: 2F | E22: E. Braatz | F22: Silver Leaf | G22: Hydrangea arborescens | H22: Unknown | I22: Open | J22: 4 | K22: Lacy | M22: NA | N22: 390.5 | O22: 3.6464443 | P22: 0 | Q22: 0 | R22: 0 | S22: NA | T22: 0.55625 | U22: 0.55972222 | V22: 0 | W22: 2 | X22: 25 | Y22: 75 | Z22: 6 | AA22: 0 | AB22: 0 | AC22: 0 | AD22: 0 | AE22: 0 | AF22: 0 | AG22: 0 | AH22: 0 | AI22: 0 | AJ22: 0 | AK22: 0 | AL22: 0 | AM22: 0 | AN22: 1 | AO22: 0 | AP22: 0 | AQ22: 1 | AR22: 0 | AS22: 0 | AT22: 0 | AU22: 0 | AV22: 0 | AW22: 0 | AX22: 0 | AY22: 0 | AZ22: 0 | BA22: 0 | BB22: 0 | BC22: 0 | BD22: 0 | BE22: 0 | BF22: 0 | BG22: 0 | BH22: 0 | BI22: 0 | BJ22: 0 | BK22: 1 | BL22: 0 | BM22: 0 | BN22: 1 | BO22: 0 | BP22: 0 | BQ22: 1 | BR22: 0 | BS22: 0 | BT22: 1 | BU22: 0 | BV22: 0 | BW22: 0 | BX22: 0 | BY22: 0 | BZ22: 0 | CA22: 0 | CB22: 0 | CC22: 0 | CD22: 0 | CE22: 0 | CF22: 0 | CG22: 0 | CH22: 0 | CI22: 0 | CJ22: 0 | CK22: 0 | CL22: 0 | CM22: 0 | CN22: 0 | CO22: 0 | CP22: Syrphid fly escaped
A23: 22 | B23: 45490 | C23: Jul | D23: 4C | E23: E. Braatz | F23: Little Lamb | G23: Hydrangea paniculata | H23: 4054 | I23: Very dense | J23: 4 | K23: Mop-like panicle | M23: NA | N23: 50 | O23: 9.7279031 | P23: 0 | Q23: 0 | R23: 0 | S23: NA | T23: 0.45416667 | U23: 0.45763889 | V23: 0 | W23: 2 | X23: 5 | Y23: 73 | Z23: 5 | AA23: 0 | AB23: 0 | AC23: 0 | AD23: 0 | AE23: 0 | AF23: 0 | AG23: 0 | AH23: 0 | AI23: 0 | AJ23: 0 | AK23: 0 | AL23: 0 | AM23: 0 | AN23: 0 | AO23: 0 | AP23: 0 | AQ23: 0 | AR23: 0 | AS23: 0 | AT23: 1 | AU23: 0 | AV23: 0 | AW23: 0 | AX23: 0 | AY23: 0 | AZ23: 0 | BA23: 0 | BB23: 0 | BC23: 0 | BD23: 0 | BE23: 0 | BF23: 1 | BG23: 0 | BH23: 0 | BI23: 0 | BJ23: 0 | BK23: 1 | BL23: 1 | BM23: 0 | BN23: 0 | BO23: 0 | BP23: 0 | BQ23: 1 | BR23: 0 | BS23: 0 | BT23: 0 | BU23: 0 | BV23: 0 | BW23: 0 | BX23: 0 | BY23: 0 | BZ23: 0 | CA23: 0 | CB23: 0 | CC23: 0 | CD23: 0 | CE23: 0 | CF23: 0 | CG23: 0 | CH23: 0 | CI23: 0 | CJ23: 0 | CK23: 0 | CL23: 0 | CM23: 0 | CN23: 0 | CO23: 0
A24: 23 | B24: 45490 | C24: Jul | D24: 4F | E24: E. Braatz | F24: Haas Halo | G24: Hydrangea arborescens | H24: 18022 | I24: Open | J24: 3 | K24: Lacy | M24: NA | N24: 563.42857 | O24: 9.3348975 | P24: 0 | Q24: 0 | R24: 0 | S24: NA | T24: 0.58055556 | U24: 0.58402778 | V24: 0 | W24: 2 | X24: 25 | Y24: 75 | Z24: 5 | AA24: 0 | AB24: 0 | AC24: 1 | AD24: 0 | AE24: 0 | AF24: 0 | AG24: 0 | AH24: 0 | AI24: 0 | AJ24: 0 | AK24: 0 | AL24: 0 | AM24: 0 | AN24: 0 | AO24: 0 | AP24: 0 | AQ24: 0 | AR24: 0 | AS24: 1 | AT24: 0 | AU24: 0 | AV24: 0 | AW24: 0 | AX24: 0 | AY24: 0 | AZ24: 0 | BA24: 0 | BB24: 0 | BC24: 0 | BD24: 0 | BE24: 0 | BF24: 0 | BG24: 0 | BH24: 0 | BI24: 0 | BJ24: 0 | BK24: 1 | BL24: 1 | BM24: 0 | BN24: 0 | BO24: 0 | BP24: 1 | BQ24: 0 | BR24: 0 | BS24: 0 | BT24: 0 | BU24: 0 | BV24: 0 | BW24: 0 | BX24: 0 | BY24: 0 | BZ24: 0 | CA24: 0 | CB24: 0 | CC24: 0 | CD24: 0 | CE24: 0 | CF24: 0 | CG24: 0 | CH24: 0 | CI24: 0 | CJ24: 0 | CK24: 0 | CL24: 0 | CM24: 0 | CN24: 0 | CO24: 0
A25: 24 | B25: 45490 | C25: Jul | D25: 5F | E25: E. Braatz | F25: Bella Anna | G25: Hydrangea arborescens | H25: 10067 | I25: Half-open | J25: 4 | K25: Mop | M25: NA | N25: 88 | O25: 3.4073996 | P25: 0 | Q25: 0 | R25: 0 | S25: NA | T25: 0.59583333 | U25: 0.59930556 | V25: 0 | W25: 2 | X25: 25 | Y25: 75 | Z25: 1 | AA25: 0 | AB25: 0 | AC25: 0 | AD25: 0 | AE25: 0 | AF25: 0 | AG25: 0 | AH25: 0 | AI25: 0 | AJ25: 0 | AK25: 0 | AL25: 0 | AM25: 0 | AN25: 0 | AO25: 0 | AP25: 0 | AQ25: 0 | AR25: 0 | AS25: 1 | AT25: 0 | AU25: 0 | AV25: 0 | AW25: 0 | AX25: 0 | AY25: 0 | AZ25: 0 | BA25: 0 | BB25: 0 | BC25: 0 | BD25: 0 | BE25: 0 | BF25: 0 | BG25: 0 | BH25: 0 | BI25: 0 | BJ25: 0 | BK25: 0 | BL25: 0 | BM25: 0 | BN25: 0 | BO25: 0 | BP25: 0 | BQ25: 0 | BR25: 0 | BS25: 0 | BT25: 0 | BU25: 0 | BV25: 0 | BW25: 0 | BX25: 0 | BY25: 0 | BZ25: 0 | CA25: 0 | CB25: 0 | CC25: 0 | CD25: 0 | CE25: 0 | CF25: 0 | CG25: 0 | CH25: 0 | CI25: 0 | CJ25: 0 | CK25: 0 | CL25: 0 | CM25: 0 | CN25: 0 | CO25: 0
A26: 25 | B26: 45490 | C26: Jul | D26: 8C | E26: E. Braatz | F26: Strawberry Shake | G26: Hydrangea paniculata | H26: 18031A | I26: Very dense | J26: 4 | K26: Mop-like panicle | M26: NA | N26: 27.1 | O26: 5.2508798 | P26: 0 | Q26: 0 | R26: 0 | S26: NA | T26: 0.44583333 | U26: 0.45625 | V26: 0 | W26: 2 | X26: 5 | Y26: 73 | Z26: 2 | AA26: 0 | AB26: 0 | AC26: 0 | AD26: 0 | AE26: 0 | AF26: 0 | AG26: 0 | AH26: 0 | AI26: 0 | AJ26: 0 | AK26: 0 | AL26: 0 | AM26: 0 | AN26: 1 | AO26: 0 | AP26: 0 | AQ26: 0 | AR26: 0 | AS26: 0 | AT26: 0 | AU26: 0 | AV26: 0 | AW26: 0 | AX26: 0 | AY26: 0 | AZ26: 0 | BA26: 0 | BB26: 0 | BC26: 0 | BD26: 0 | BE26: 0 | BF26: 1 | BG26: 0 | BH26: 0 | BI26: 0 | BJ26: 0 | BK26: 0 | BL26: 0 | BM26: 0 | BN26: 0 | BO26: 0 | BP26: 0 | BQ26: 0 | BR26: 0 | BS26: 0 | BT26: 0 | BU26: 0 | BV26: 0 | BW26: 0 | BX26: 0 | BY26: 0 | BZ26: 0 | CA26: 0 | CB26: 0 | CC26: 0 | CD26: 0 | CE26: 0 | CF26: 0 | CG26: 0 | CH26: 0 | CI26: 0 | CJ26: 0 | CK26: 0 | CL26: 0 | CM26: 0 | CN26: 0 | CO26: 0 | CP26: Syrphid
A27: 26 | B27: 45490 | C27: Jul | D27: 9F | E27: E. Braatz | F27: Incrediball | G27: Hydrangea arborescens | H27: 9050 | I27: Dense | J27: 3 | K27: Mop | M27: NA | N27: 557.4 | O27: 13.163664 | P27: 0 | Q27: 0 | R27: 0 | S27: NA | T27: 0.60486111 | U27: 0.60902778 | V27: 0 | W27: 2 | X27: 25 | Y27: 75 | Z27: 4 | AA27: 0 | AB27: 0 | AC27: 0 | AD27: 0 | AE27: 0 | AF27: 0 | AG27: 0 | AH27: 0 | AI27: 0 | AJ27: 0 | AK27: 0 | AL27: 0 | AM27: 0 | AN27: 0 | AO27: 0 | AP27: 0 | AQ27: 1 | AR27: 0 | AS27: 1 | AT27: 0 | AU27: 0 | AV27: 0 | AW27: 0 | AX27: 0 | AY27: 0 | AZ27: 0 | BA27: 0 | BB27: 0 | BC27: 0 | BD27: 0 | BE27: 0 | BF27: 0 | BG27: 0 | BH27: 0 | BI27: 0 | BJ27: 0 | BK27: 0 | BL27: 0 | BM27: 0 | BN27: 0 | BO27: 0 | BP27: 0 | BQ27: 1 | BR27: 0 | BS27: 0 | BT27: 0 | BU27: 1 | BV27: 0 | BW27: 0 | BX27: 0 | BY27: 0 | BZ27: 0 | CA27: 0 | CB27: 0 | CC27: 0 | CD27: 0 | CE27: 0 | CF27: 0 | CG27: 0 | CH27: 0 | CI27: 0 | CJ27: 0 | CK27: 0 | CL27: 0 | CM27: 0 | CN27: 0 | CO27: 0
A28: 27 | B28: 45491 | C28: Jul | D28: 11D | E28: E. Braatz | F28: Kyushu | G28: Hydrangea paniculata | H28: 93021 | I28: Open | J28: NA | K28: Lacy panicle | M28: NA | N28: 404.7 | O28: 9.3348975 | P28: 0 | Q28: 0 | R28: 0 | S28: NA | T28: 0.51458333 | U28: 0.51805556 | V28: 0 | W28: 2 | X28: 65 | Y28: 70 | Z28: 5 | AA28: 0 | AB28: 0 | AC28: 0 | AD28: 0 | AE28: 0 | AF28: 0 | AG28: 0 | AH28: 0 | AI28: 0 | AJ28: 0 | AK28: 0 | AL28: 0 | AM28: 0 | AN28: 0 | AO28: 0 | AP28: 0 | AQ28: 1 | AR28: 0 | AS28: 1 | AT28: 1 | AU28: 0 | AV28: 0 | AW28: 0 | AX28: 0 | AY28: 0 | AZ28: 0 | BA28: 0 | BB28: 0 | BC28: 0 | BD28: 0 | BE28: 0 | BF28: 1 | BG28: 0 | BH28: 0 | BI28: 0 | BJ28: 0 | BK28: 0 | BL28: 0 | BM28: 0 | BN28: 0 | BO28: 0 | BP28: 0 | BQ28: 1 | BR28: 0 | BS28: 0 | BT28: 0 | BU28: 0 | BV28: 0 | BW28: 0 | BX28: 0 | BY28: 0 | BZ28: 0 | CA28: 0 | CB28: 0 | CC28: 0 | CD28: 0 | CE28: 0 | CF28: 0 | CG28: 0 | CH28: 0 | CI28: 0 | CJ28: 0 | CK28: 0 | CL28: 0 | CM28: 0 | CN28: 0 | CO28: 0
A29: 28 | B29: 45491 | C29: Jul | D29: 19D | E29: E. Braatz | F29: Puffer Fish | G29: Hydrangea paniculata | H29: 2023-030 | I29: Half-open | J29: 4 | K29: Mop-like panicle | M29: NA | N29: 55.8 | O29: 2.3337244 | P29: 0 | Q29: 0 | R29: 0 | S29: NA | T29: 0.54236111 | U29: 0.54583333 | V29: 0 | W29: 2 | X29: 65 | Y29: 70 | Z29: 2 | AA29: 0 | AB29: 0 | AC29: 0 | AD29: 0 | AE29: 0 | AF29: 0 | AG29: 0 | AH29: 0 | AI29: 0 | AJ29: 0 | AK29: 0 | AL29: 0 | AM29: 0 | AN29: 0 | AO29: 0 | AP29: 0 | AQ29: 0 | AR29: 0 | AS29: 1 | AT29: 0 | AU29: 0 | AV29: 0 | AW29: 0 | AX29: 0 | AY29: 0 | AZ29: 0 | BA29: 0 | BB29: 0 | BC29: 0 | BD29: 0 | BE29: 0 | BF29: 0 | BG29: 0 | BH29: 0 | BI29: 0 | BJ29: 0 | BK29: 0 | BL29: 0 | BM29: 0 | BN29: 0 | BO29: 1 | BP29: 0 | BQ29: 0 | BR29: 0 | BS29: 0 | BT29: 0 | BU29: 0 | BV29: 0 | BW29: 0 | BX29: 0 | BY29: 0 | BZ29: 0 | CA29: 0 | CB29: 0 | CC29: 0 | CD29: 0 | CE29: 0 | CF29: 0 | CG29: 0 | CH29: 0 | CI29: 0 | CJ29: 0 | CK29: 0 | CL29: 0 | CM29: 0 | CN29: 0 | CO29: 0 | CP29: 2 Golden digger waps
A30: 29 | B30: 45491 | C30: Jul | D30: 20D | E30: E. Braatz | F30: Early Evolution | G30: Hydrangea paniculata | H30: 2023-026A | I30: Open | J30: 4 | K30: Lacy panicle | M30: NA | N30: NA | O30: 1.0372108 | P30: 0 | Q30: #VALUE! | R30: #VALUE! | S30: NA | T30: 0.525 | U30: 0.52847222 | V30: 0 | W30: 2 | X30: 65 | Y30: 70 | Z30: 2 | AA30: 0 | AB30: 0 | AC30: 0 | AD30: 0 | AE30: 0 | AF30: 0 | AG30: 0 | AH30: 0 | AI30: 0 | AJ30: 0 | AK30: 0 | AL30: 0 | AM30: 0 | AN30: 1 | AO30: 0 | AP30: 0 | AQ30: 0 | AR30: 0 | AS30: 0 | AT30: 1 | AU30: 0 | AV30: 0 | AW30: 0 | AX30: 0 | AY30: 0 | AZ30: 0 | BA30: 0 | BB30: 0 | BC30: 0 | BD30: 0 | BE30: 0 | BF30: 0 | BG30: 0 | BH30: 0 | BI30: 0 | BJ30: 0 | BK30: 0 | BL30: 0 | BM30: 0 | BN30: 0 | BO30: 0 | BP30: 0 | BQ30: 0 | BR30: 0 | BS30: 0 | BT30: 0 | BU30: 0 | BV30: 0 | BW30: 0 | BX30: 0 | BY30: 0 | BZ30: 0 | CA30: 0 | CB30: 0 | CC30: 0 | CD30: 0 | CE30: 0 | CF30: 0 | CG30: 0 | CH30: 0 | CI30: 0 | CJ30: 0 | CK30: 0 | CL30: 0 | CM30: 0 | CN30: 0 | CO30: 0
A31: 30 | B31: 45491 | C31: Jul | D31: 5B | E31: E. Braatz | F31: Dharuma | G31: Hydrangea paniculata | H31: 5026 | I31: Open | J31: 4 | K31: Lacy panicle | M31: NA | N31: 5.5 | O31: 0.906832 | P31: 0 | Q31: 0 | R31: 0 | S31: NA | T31: 0.54236111 | U31: 0.54583333 | V31: 0 | W31: 2 | X31: 35 | Y31: 73 | Z31: 1 | AA31: 0 | AB31: 0 | AC31: 0 | AD31: 0 | AE31: 0 | AF31: 0 | AG31: 0 | AH31: 0 | AI31: 0 | AJ31: 0 | AK31: 0 | AL31: 0 | AM31: 0 | AN31: 0 | AO31: 0 | AP31: 0 | AQ31: 0 | AR31: 0 | AS31: 0 | AT31: 0 | AU31: 0 | AV31: 0 | AW31: 0 | AX31: 0 | AY31: 0 | AZ31: 0 | BA31: 0 | BB31: 0 | BC31: 0 | BD31: 0 | BE31: 0 | BF31: 0 | BG31: 0 | BH31: 0 | BI31: 0 | BJ31: 0 | BK31: 0 | BL31: 1 | BM31: 0 | BN31: 0 | BO31: 0 | BP31: 0 | BQ31: 0 | BR31: 0 | BS31: 0 | BT31: 0 | BU31: 0 | BV31: 0 | BW31: 0 | BX31: 0 | BY31: 0 | BZ31: 0 | CA31: 0 | CB31: 0 | CC31: 0 | CD31: 0 | CE31: 0 | CF31: 0 | CG31: 0 | CH31: 0 | CI31: 0 | CJ31: 0 | CK31: 0 | CL31: 0 | CM31: 0 | CN31: 0 | CO31: 0
A32: 31 | B32: 45491 | C32: Jul | D32: 6D | E32: E. Braatz | F32: Strawberry Sundae | G32: Hydrangea paniculata | H32: 15055 | I32: Dense | J32: 4 | K32: Mop-like panicle | M32: NA | N32: 42.8 | O32: 11.81448 | P32: 0 | Q32: 0 | R32: 0 | S32: NA | T32: 0.53541667 | U32: 0.53888889 | V32: 0 | W32: 2 | X32: 65 | Y32: 70 | Z32: 6 | AA32: 0 | AB32: 0 | AC32: 0 | AD32: 0 | AE32: 0 | AF32: 0 | AG32: 0 | AH32: 0 | AI32: 0 | AJ32: 0 | AK32: 0 | AL32: 0 | AM32: 0 | AN32: 1 | AO32: 0 | AP32: 0 | AQ32: 0 | AR32: 0 | AS32: 1 | AT32: 1 | AU32: 0 | AV32: 0 | AW32: 0 | AX32: 0 | AY32: 0 | AZ32: 0 | BA32: 0 | BB32: 0 | BC32: 0 | BD32: 0 | BE32: 0 | BF32: 1 | BG32: 0 | BH32: 0 | BI32: 0 | BJ32: 0 | BK32: 0 | BL32: 0 | BM32: 0 | BN32: 1 | BO32: 0 | BP32: 0 | BQ32: 1 | BR32: 0 | BS32: 0 | BT32: 0 | BU32: 0 | BV32: 0 | BW32: 0 | BX32: 0 | BY32: 0 | BZ32: 0 | CA32: 0 | CB32: 0 | CC32: 0 | CD32: 0 | CE32: 0 | CF32: 0 | CG32: 0 | CH32: 0 | CI32: 0 | CJ32: 0 | CK32: 0 | CL32: 0 | CM32: 0 | CN32: 0 | CO32: 0
A33: 32 | B33: 45493 | C33: Jul | D33: 4A | E33: E. Braatz | F33: White Diamonds | G33: Hydrangea paniculata | H33: 11045 | I33: Half-open | J33: 4 | K33: Mop-like panicle | M33: NA | N33: 31 | O33: 9.0432 | T33: NA | U33: NA | V33: NA | W33: NA | X33: NA | Y33: NA | Z33: 9 | AA33: 0 | AB33: 0 | AC33: 0 | AD33: 1 | AE33: 0 | AF33: 1 | AG33: 0 | AH33: 0 | AI33: 0 | AJ33: 1 | AK33: 0 | AL33: 0 | AM33: 0 | AN33: 1 | AO33: 0 | AP33: 1 | AQ33: 1 | AR33: 0 | AS33: 0 | AT33: 0 | AU33: 0 | AV33: 0 | AW33: 0 | AX33: 0 | AY33: 0 | AZ33: 0 | BA33: 0 | BB33: 0 | BC33: 0 | BD33: 0 | BE33: 0 | BF33: 0 | BG33: 0 | BH33: 0 | BI33: 0 | BJ33: 0 | BK33: 0 | BL33: 0 | BM33: 0 | BN33: 1 | BO33: 0 | BP33: 1 | BQ33: 1 | BR33: 0 | BS33: 0 | BT33: 0 | BU33: 0 | BV33: 0 | BW33: 0 | BX33: 0 | BY33: 0 | BZ33: 0 | CA33: 0 | CB33: 0 | CC33: 0 | CD33: 0 | CE33: 0 | CF33: 0 | CG33: 0 | CH33: 0 | CI33: 0 | CJ33: 0 | CK33: 0 | CL33: 0 | CM33: 0 | CN33: 0 | CO33: 0
A34: 33 | B34: 45495 | C34: Jul | D34: 10E | E34: E. Braatz | F34: Incrediball | G34: Hydrangea arborescens | H34: 9050 | I34: Dense | J34: 4 | K34: Mop | L34: 9.33 | M34: NA | N34: 1180.7 | O34: 9.0432 | P34: 84.373056 | Q34: 0 | R34: 99619.267 | S34: 99619.267 | T34: 0.46875 | U34: 0.47222222 | V34: 0 | W34: 1 | X34: 5 | Y34: 78 | Z34: 5 | AA34: 0 | AB34: 0 | AC34: 0 | AD34: 0 | AE34: 0 | AF34: 1 | AG34: 0 | AH34: 0 | AI34: 0 | AJ34: 0 | AK34: 0 | AL34: 0 | AM34: 0 | AN34: 0 | AO34: 1 | AP34: 0 | AQ34: 1 | AR34: 0 | AS34: 0 | AT34: 0 | AU34: 0 | AV34: 0 | AW34: 0 | AX34: 0 | AY34: 0 | AZ34: 0 | BA34: 0 | BB34: 0 | BC34: 0 | BD34: 0 | BE34: 0 | BF34: 0 | BG34: 0 | BH34: 0 | BI34: 0 | BJ34: 0 | BK34: 0 | BL34: 0 | BM34: 0 | BN34: 0 | BO34: 0 | BP34: 0 | BQ34: 1 | BR34: 0 | BS34: 0 | BT34: 1 | BU34: 0 | BV34: 0 | BW34: 0 | BX34: 0 | BY34: 0 | BZ34: 0 | CA34: 0 | CB34: 0 | CC34: 0 | CD34: 0 | CE34: 0 | CF34: 0 | CG34: 0 | CH34: 0 | CI34: 0 | CJ34: 0 | CK34: 0 | CL34: 0 | CM34: 0 | CN34: 0 | CO34: 0 | CP34: Vespidae
A35: 34 | B35: 45495 | C35: Jul | D35: 9A | E35: G. Meneses | F35: Fire & Ice | G35: Hydrangea paniculata | H35: 12021 | I35: Open | J35: 4 | K35: Lacy panicle | L35: 12.3 | M35: NA | N35: 97.8 | O35: 6.28 | P35: 77.244 | Q35: 0 | R35: 7554.4632 | S35: 7554.4632 | T35: 0.66527778 | U35: 0.66875 | V35: 0 | W35: 1 | X35: 75 | Y35: 79 | Z35: 7 | AA35: 0 | AB35: 0 | AC35: 0 | AD35: 0 | AE35: 0 | AF35: 1 | AG35: 0 | AH35: 0 | AI35: 0 | AJ35: 1 | AK35: 0 | AL35: 0 | AM35: 0 | AN35: 0 | AO35: 1 | AP35: 0 | AQ35: 1 | AR35: 0 | AS35: 1 | AT35: 1 | AU35: 0 | AV35: 0 | AW35: 0 | AX35: 0 | AY35: 0 | AZ35: 0 | BA35: 0 | BB35: 0 | BC35: 0 | BD35: 0 | BE35: 0 | BF35: 1 | BG35: 0 | BH35: 0 | BI35: 0 | BJ35: 0 | BK35: 0 | BL35: 0 | BM35: 0 | BN35: 0 | BO35: 0 | BP35: 0 | BQ35: 0 | BR35: 0 | BS35: 0 | BT35: 0 | BU35: 0 | BV35: 0 | BW35: 0 | BX35: 0 | BY35: 0 | BZ35: 0 | CA35: 0 | CB35: 0 | CC35: 0 | CD35: 0 | CE35: 0 | CF35: 0 | CG35: 0 | CH35: 0 | CI35: 0 | CJ35: 0 | CK35: 0 | CL35: 0 | CM35: 0 | CN35: 0 | CO35: 0
A36: 35 | B36: 45496 | C36: Jul | D36: 3E | E36: E. Braatz | F36: Bounty | G36: Hydrangea arborescens | H36: 12019 | I36: Half-open | J36: 4 | K36: Mop | L36: 5.6 | M36: NA | N36: 528.4 | O36: 17.0973 | P36: 95.74488 | Q36: 0 | R36: 50591.595 | S36: 50591.595 | T36: 0.5625 | U36: 0.56597222 | V36: 0 | W36: 1 | X36: 100 | Y36: 77 | Z36: 3 | AA36: 0 | AB36: 0 | AC36: 0 | AD36: 0 | AE36: 0 | AF36: 0 | AG36: 0 | AH36: 0 | AI36: 0 | AJ36: 0 | AK36: 0 | AL36: 0 | AM36: 0 | AN36: 0 | AO36: 0 | AP36: 0 | AQ36: 0 | AR36: 0 | AS36: 0 | AT36: 0 | AU36: 0 | AV36: 0 | AW36: 0 | AX36: 0 | AY36: 0 | AZ36: 1 | BA36: 0 | BB36: 0 | BC36: 0 | BD36: 0 | BE36: 0 | BF36: 0 | BG36: 0 | BH36: 0 | BI36: 0 | BJ36: 0 | BK36: 0 | BL36: 0 | BM36: 0 | BN36: 0 | BO36: 0 | BP36: 1 | BQ36: 1 | BR36: 0 | BS36: 0 | BT36: 0 | BU36: 0 | BV36: 0 | BW36: 0 | BX36: 0 | BY36: 0 | BZ36: 0 | CA36: 0 | CB36: 0 | CC36: 0 | CD36: 0 | CE36: 0 | CF36: 0 | CG36: 0 | CH36: 0 | CI36: 0 | CJ36: 0 | CK36: 0 | CL36: 0 | CM36: 0 | CN36: 0 | CO36: 0
A37: 36 | B37: 45496 | C37: Jul | D37: 4E | E37: E. Braatz | F37: Hayes Starburst | G37: Hydrangea arborescens | H37: 7027 | I37: Very dense | J37: 8 | K37: Mop | L37: 5 | M37: NA | N37: 0 | O37: 6.28 | P37: 31.4 | Q37: 0 | R37: 0 | S37: 0 | T37: 0.55347222 | U37: 0.55694444 | V37: 0 | W37: 1 | X37: 100 | Y37: 77 | Z37: 1 | AA37: 0 | AB37: 0 | AC37: 0 | AD37: 0 | AE37: 0 | AF37: 0 | AG37: 0 | AH37: 0 | AI37: 0 | AJ37: 0 | AK37: 0 | AL37: 0 | AM37: 0 | AN37: 1 | AO37: 0 | AP37: 0 | AQ37: 0 | AR37: 0 | AS37: 0 | AT37: 0 | AU37: 0 | AV37: 0 | AW37: 0 | AX37: 0 | AY37: 0 | AZ37: 0 | BA37: 0 | BB37: 0 | BC37: 0 | BD37: 0 | BE37: 0 | BF37: 0 | BG37: 0 | BH37: 0 | BI37: 0 | BJ37: 0 | BK37: 0 | BL37: 0 | BM37: 0 | BN37: 0 | BO37: 0 | BP37: 0 | BQ37: 0 | BR37: 0 | BS37: 0 | BT37: 0 | BU37: 0 | BV37: 0 | BW37: 0 | BX37: 0 | BY37: 0 | BZ37: 0 | CA37: 0 | CB37: 0 | CC37: 0 | CD37: 0 | CE37: 0 | CF37: 0 | CG37: 0 | CH37: 0 | CI37: 0 | CJ37: 0 | CK37: 0 | CL37: 0 | CM37: 0 | CN37: 0 | CO37: 0
A38: 37 | B38: 45496 | C38: Jul | D38: 5E | E38: E. Braatz | F38: Annabelle | G38: Hydrangea arborescens | H38: 65169 | I38: Dense | J38: 4 | K38: Mop | L38: 7 | M38: NA | N38: 478.5 | O38: 36.1728 | P38: 253.2096 | Q38: 0 | R38: 121160.79 | S38: 121160.79 | T38: 0.58263889 | U38: 0.58611111 | V38: 0 | W38: 1 | X38: 100 | Y38: 77 | Z38: 2 | AA38: 0 | AB38: 0 | AC38: 0 | AD38: 0 | AE38: 0 | AF38: 0 | AG38: 0 | AH38: 0 | AI38: 0 | AJ38: 0 | AK38: 0 | AL38: 0 | AM38: 0 | AN38: 1 | AO38: 0 | AP38: 0 | AQ38: 1 | AR38: 0 | AS38: 0 | AT38: 0 | AU38: 0 | AV38: 0 | AW38: 0 | AX38: 0 | AY38: 0 | AZ38: 0 | BA38: 0 | BB38: 0 | BC38: 0 | BD38: 0 | BE38: 0 | BF38: 0 | BG38: 0 | BH38: 0 | BI38: 0 | BJ38: 0 | BK38: 0 | BL38: 0 | BM38: 0 | BN38: 0 | BO38: 0 | BP38: 0 | BQ38: 0 | BR38: 0 | BS38: 0 | BT38: 0 | BU38: 0 | BV38: 0 | BW38: 0 | BX38: 0 | BY38: 0 | BZ38: 0 | CA38: 0 | CB38: 0 | CC38: 0 | CD38: 0 | CE38: 0 | CF38: 0 | CG38: 0 | CH38: 0 | CI38: 0 | CJ38: 0 | CK38: 0 | CL38: 0 | CM38: 0 | CN38: 0 | CO38: 0
A39: 38 | B39: 45496 | C39: Jul | D39: 6E | E39: E. Braatz | F39: Riven Lace | G39: Hydrangea arborescens | H39: 8036 | I39: Half-open | J39: 4 | K39: Lacy | L39: 8.33 | M39: NA | N39: 97.5 | O39: 12.3088 | P39: 102.5323 | Q39: 0 | R39: 9996.8996 | S39: 9996.8996 | T39: 0.48055556 | U39: 0.48402778 | V39: 0 | W39: 1 | X39: 100 | Y39: 74 | Z39: 3 | AA39: 0 | AB39: 0 | AC39: 0 | AD39: 0 | AE39: 0 | AF39: 0 | AG39: 0 | AH39: 0 | AI39: 0 | AJ39: 0 | AK39: 0 | AL39: 0 | AM39: 0 | AN39: 1 | AO39: 1 | AP39: 0 | AQ39: 1 | AR39: 0 | AS39: 0 | AT39: 0 | AU39: 0 | AV39: 0 | AW39: 0 | AX39: 0 | AY39: 0 | AZ39: 0 | BA39: 0 | BB39: 0 | BC39: 0 | BD39: 0 | BE39: 0 | BF39: 0 | BG39: 0 | BH39: 0 | BI39: 0 | BJ39: 0 | BK39: 0 | BL39: 0 | BM39: 0 | BN39: 0 | BO39: 0 | BP39: 0 | BQ39: 0 | BR39: 0 | BS39: 0 | BT39: 0 | BU39: 0 | BV39: 0 | BW39: 0 | BX39: 0 | BY39: 0 | BZ39: 0 | CA39: 0 | CB39: 0 | CC39: 0 | CD39: 0 | CE39: 0 | CF39: 0 | CG39: 0 | CH39: 0 | CI39: 0 | CJ39: 0 | CK39: 0 | CL39: 0 | CM39: 0 | CN39: 0 | CO39: 0
A40: 39 | B40: 45496 | C40: Jul | D40: 6E | E40: E. Braatz | F40: Riven Lace | G40: Hydrangea arborescens | H40: 8036 | I40: Half-open | J40: 4 | K40: Lacy | L40: 8.33 | M40: NA | N40: 97.5 | O40: 12.3088 | P40: 102.5323 | Q40: 0 | R40: 9996.8996 | S40: 9996.8996 | T40: 0.48055556 | U40: 0.48402778 | V40: 0 | W40: 1 | X40: 100 | Y40: 74 | Z40: 3 | AA40: 0 | AB40: 0 | AC40: 0 | AD40: 0 | AE40: 0 | AF40: 0 | AG40: 0 | AH40: 0 | AI40: 0 | AJ40: 0 | AK40: 0 | AL40: 0 | AM40: 0 | AN40: 1 | AO40: 0 | AP40: 0 | AQ40: 1 | AR40: 0 | AS40: 0 | AT40: 0 | AU40: 0 | AV40: 0 | AW40: 0 | AX40: 0 | AY40: 0 | AZ40: 1 | BA40: 0 | BB40: 0 | BC40: 0 | BD40: 0 | BE40: 0 | BF40: 0 | BG40: 0 | BH40: 0 | BI40: 0 | BJ40: 0 | BK40: 0 | BL40: 0 | BM40: 0 | BN40: 0 | BO40: 0 | BP40: 0 | BQ40: 0 | BR40: 0 | BS40: 0 | BT40: 0 | BU40: 0 | BV40: 0 | BW40: 0 | BX40: 0 | BY40: 0 | BZ40: 0 | CA40: 0 | CB40: 0 | CC40: 0 | CD40: 0 | CE40: 0 | CF40: 0 | CG40: 0 | CH40: 0 | CI40: 0 | CJ40: 0 | CK40: 0 | CL40: 0 | CM40: 0 | CN40: 0 | CO40: 0
...

Sheet SpecAccum
A1: NumSurveys | B1: NewSpp | C1: CumulativeSpp | D1: InsectRichness | E1: Araneae | F1: Chauliognathus | G1: Cerambycidae | H1: Chrysomelidae | I1: Curculionidae | J1: Mordellidae | K1: Scarabaeoidea | L1: Diptera | M1: Bombyliidae | N1: Calliphoridae | O1: Conopidae | P1: Cecidomyiidae | Q1: Culicidae | R1: Dolichopodidae | S1: Drosophilidae | T1: Empididae | U1: Muscidae | V1: Oestroidea | W1: Syrphidae_total | X1: Unknown_Bristly_Flies | Y1: Tipulidae | Z1: Ulidiidae | AA1: Hemiptera | AB1: Aphididae | AC1: Cicadellidae | AD1: Miridae | AE1: Reduviidae | AF1: Hymenoptera | AG1: Xylocopa | AH1: Andrenidae | AI1: Protandrena | AJ1: Apis.mellifera | AK1: Melissodes | AL1: Cerceris | AM1: Astata | AN1: Chrysididae | AO1: Hylaeus | AP1: Halictidae | AQ1: Agapostemon | AR1: Augochlora | AS1: Green.Sweatbee | AT1: Halictus | AU1: Lasioglossum | AV1: Bombus affinis | AW1: Bombus auricomus | AX1: Bombus impatiens | AY1: Bombus bimaculatus | AZ1: Bombus griseocollis | BA1: Bombus vagans | BB1: Symmorphus | BC1: Eurytoma | BD1: Braconidae | BE1: Apocrita | BF1: Scolia | BG1: Sphecius speciosus | BH1: Sphex | BI1: Vespidae | BJ1: Dolichovespula.maculata | BK1: Dolichovespula | BL1: Lepidoptera | BM1: Hesperiidae | BN1: Celastrina ladon | BO1: Epargyreus clarus | BP1: Libythean carinenta | BQ1: Pieris rapae | BR1: Polygonia comma | BS1: Vanessa atalanta
A2: 1 | B2: 5 | C2: =SUM(B2) -> 5 | D2: 5 | E2: 0 | F2: 0 | G2: 0 | H2: 0 | I2: 0 | J2: 0 | K2: 0 | L2: 0 | M2: 0 | N2: 1 | O2: 0 | P2: 0 | Q2: 0 | R2: 0 | S2: 0 | T2: 0 | U2: 0 | V2: 0 | W2: 1 | X2: 0 | Y2: 0 | Z2: 0 | AA2: 0 | AB2: 0 | AC2: 0 | AD2: 0 | AE2: 0 | AF2: 0 | AG2: 0 | AH2: 0 | AI2: 0 | AJ2: 0 | AK2: 0 | AL2: 0 | AM2: 0 | AN2: 0 | AO2: 0 | AP2: 0 | AQ2: 0 | AR2: 0 | AS2: 0 | AT2: 1 | AU2: 1 | AV2: 0 | AW2: 0 | AX2: 0 | AY2: 0 | AZ2: 0 | BA2: 0 | BB2: 0 | BC2: 0 | BD2: 0 | BE2: 0 | BF2: 0 | BG2: 0 | BH2: 0 | BI2: 0 | BJ2: 0 | BK2: 0 | BL2: 0 | BM2: 0 | BN2: 0 | BO2: 0 | BP2: 0 | BQ2: 0 | BR2: 0 | BS2: 1
A3: 2 | B3: 0 | C3: =SUM($B$2:$B3) -> 5 | D3: 2 | E3: 0 | F3: 0 | G3: 0 | H3: 0 | I3: 0 | J3: 0 | K3: 0 | L3: 0 | M3: 0 | N3: 0 | O3: 0 | P3: 0 | Q3: 0 | R3: 0 | S3: 0 | T3: 0 | U3: 0 | V3: 0 | W3: 1 | X3: 0 | Y3: 0 | Z3: 0 | AA3: 0 | AB3: 0 | AC3: 0 | AD3: 0 | AE3: 0 | AF3: 0 | AG3: 0 | AH3: 0 | AI3: 0 | AJ3: 0 | AK3: 0 | AL3: 0 | AM3: 0 | AN3: 0 | AO3: 0 | AP3: 0 | AQ3: 0 | AR3: 0 | AS3: 0 | AT3: 0 | AU3: 1 | AV3: 0 | AW3: 0 | AX3: 0 | AY3: 0 | AZ3: 0 | BA3: 0 | BB3: 0 | BC3: 0 | BD3: 0 | BE3: 0 | BF3: 0 | BG3: 0 | BH3: 0 | BI3: 0 | BJ3: 0 | BK3: 0 | BL3: 0 | BM3: 0 | BN3: 0 | BO3: 0 | BP3: 0 | BQ3: 0 | BR3: 0 | BS3: 0
A4: 3 | B4: 3 | C4: =SUM($B$2:$B4) -> 8 | D4: 6 | E4: 0 | F4: 0 | G4: 0 | H4: 0 | I4: 0 | J4: 0 | K4: 0 | L4: 0 | M4: 0 | N4: 1 | O4: 0 | P4: 0 | Q4: 0 | R4: 1 | S4: 0 | T4: 0 | U4: 0 | V4: 0 | W4: 1 | X4: 1 | Y4: 0 | Z4: 0 | AA4: 0 | AB4: 0 | AC4: 0 | AD4: 0 | AE4: 0 | AF4: 0 | AG4: 0 | AH4: 0 | AI4: 0 | AJ4: 0 | AK4: 0 | AL4: 0 | AM4: 0 | AN4: 0 | AO4: 0 | AP4: 0 | AQ4: 0 | AR4: 0 | AS4: 0 | AT4: 0 | AU4: 1 | AV4: 0 | AW4: 0 | AX4: 0 | AY4: 0 | AZ4: 0 | BA4: 0 | BB4: 0 | BC4: 0 | BD4: 0 | BE4: 0 | BF4: 0 | BG4: 0 | BH4: 0 | BI4: 1 | BJ4: 0 | BK4: 0 | BL4: 0 | BM4: 0 | BN4: 0 | BO4: 0 | BP4: 0 | BQ4: 0 | BR4: 0 | BS4: 0
A5: 4 | B5: 1 | C5: =SUM($B$2:$B5) -> 9 | D5: 2 | E5: 0 | F5: 0 | G5: 0 | H5: 0 | I5: 0 | J5: 0 | K5: 0 | L5: 0 | M5: 0 | N5: 0 | O5: 0 | P5: 0 | Q5: 0 | R5: 0 | S5: 0 | T5: 0 | U5: 0 | V5: 0 | W5: 1 | X5: 0 | Y5: 0 | Z5: 0 | AA5: 0 | AB5: 0 | AC5: 0 | AD5: 0 | AE5: 0 | AF5: 0 | AG5: 0 | AH5: 0 | AI5: 0 | AJ5: 0 | AK5: 0 | AL5: 0 | AM5: 0 | AN5: 0 | AO5: 0 | AP5: 0 | AQ5: 0 | AR5: 0 | AS5: 0 | AT5: 0 | AU5: 0 | AV5: 0 | AW5: 0 | AX5: 0 | AY5: 0 | AZ5: 0 | BA5: 0 | BB5: 0 | BC5: 0 | BD5: 0 | BE5: 0 | BF5: 0 | BG5: 0 | BH5: 0 | BI5: 0 | BJ5: 0 | BK5: 0 | BL5: 0 | BM5: 0 | BN5: 0 | BO5: 1 | BP5: 0 | BQ5: 0 | BR5: 0 | BS5: 0
A6: 5 | B6: 2 | C6: =SUM($B$2:$B6) -> 11 | D6: 7 | E6: 0 | F6: 0 | G6: 0 | H6: 0 | I6: 0 | J6: 0 | K6: 0 | L6: 0 | M6: 1 | N6: 1 | O6: 0 | P6: 0 | Q6: 0 | R6: 0 | S6: 0 | T6: 0 | U6: 0 | V6: 0 | W6: 1 | X6: 1 | Y6: 0 | Z6: 0 | AA6: 0 | AB6: 0 | AC6: 0 | AD6: 0 | AE6: 0 | AF6: 0 | AG6: 0 | AH6: 0 | AI6: 0 | AJ6: 1 | AK6: 0 | AL6: 0 | AM6: 0 | AN6: 0 | AO6: 0 | AP6: 0 | AQ6: 0 | AR6: 0 | AS6: 0 | AT6: 1 | AU6: 1 | AV6: 0 | AW6: 0 | AX6: 0 | AY6: 0 | AZ6: 0 | BA6: 0 | BB6: 0 | BC6: 0 | BD6: 0 | BE6: 0 | BF6: 0 | BG6: 0 | BH6: 0 | BI6: 0 | BJ6: 0 | BK6: 0 | BL6: 0 | BM6: 0 | BN6: 0 | BO6: 0 | BP6: 0 | BQ6: 0 | BR6: 0 | BS6: 0
A7: 6 | B7: 0 | C7: =SUM($B$2:$B7) -> 11 | D7: 1 | E7: 0 | F7: 0 | G7: 0 | H7: 0 | I7: 0 | J7: 0 | K7: 0 | L7: 0 | M7: 0 | N7: 0 | O7: 0 | P7: 0 | Q7: 0 | R7: 0 | S7: 0 | T7: 0 | U7: 0 | V7: 0 | W7: 1 | X7: 0 | Y7: 0 | Z7: 0 | AA7: 0 | AB7: 0 | AC7: 0 | AD7: 0 | AE7: 0 | AF7: 0 | AG7: 0 | AH7: 0 | AI7: 0 | AJ7: 0 | AK7: 0 | AL7: 0 | AM7: 0 | AN7: 0 | AO7: 0 | AP7: 0 | AQ7: 0 | AR7: 0 | AS7: 0 | AT7: 0 | AU7: 0 | AV7: 0 | AW7: 0 | AX7: 0 | AY7: 0 | AZ7: 0 | BA7: 0 | BB7: 0 | BC7: 0 | BD7: 0 | BE7: 0 | BF7: 0 | BG7: 0 | BH7: 0 | BI7: 0 | BJ7: 0 | BK7: 0 | BL7: 0 | BM7: 0 | BN7: 0 | BO7: 0 | BP7: 0 | BQ7: 0 | BR7: 0 | BS7: 0
A8: 7 | B8: 1 | C8: =SUM($B$2:$B8) -> 12 | D8: 7 | E8: 0 | F8: 0 | G8: 0 | H8: 0 | I8: 0 | J8: 0 | K8: 0 | L8: 0 | M8: 0 | N8: 0 | O8: 0 | P8: 0 | Q8: 0 | R8: 0 | S8: 0 | T8: 0 | U8: 0 | V8: 0 | W8: 1 | X8: 1 | Y8: 0 | Z8: 0 | AA8: 0 | AB8: 0 | AC8: 0 | AD8: 0 | AE8: 0 | AF8: 0 | AG8: 0 | AH8: 0 | AI8: 0 | AJ8: 0 | AK8: 0 | AL8: 0 | AM8: 0 | AN8: 0 | AO8: 1 | AP8: 0 | AQ8: 0 | AR8: 0 | AS8: 0 | AT8: 1 | AU8: 1 | AV8: 0 | AW8: 0 | AX8: 0 | AY8: 0 | AZ8: 0 | BA8: 0 | BB8: 0 | BC8: 0 | BD8: 0 | BE8: 0 | BF8: 0 | BG8: 0 | BH8: 0 | BI8: 1 | BJ8: 0 | BK8: 0 | BL8: 0 | BM8: 0 | BN8: 0 | BO8: 0 | BP8: 0 | BQ8: 0 | BR8: 0 | BS8: 1
A9: 8 | B9: 3 | C9: =SUM($B$2:$B9) -> 15 | D9: 9 | E9: 0 | F9: 0 | G9: 0 | H9: 0 | I9: 0 | J9: 1 | K9: 0 | L9: 0 | M9: 0 | N9: 0 | O9: 1 | P9: 0 | Q9: 0 | R9: 1 | S9: 0 | T9: 0 | U9: 0 | V9: 0 | W9: 1 | X9: 0 | Y9: 0 | Z9: 0 | AA9: 0 | AB9: 0 | AC9: 0 | AD9: 1 | AE9: 0 | AF9: 0 | AG9: 0 | AH9: 0 | AI9: 0 | AJ9: 0 | AK9: 0 | AL9: 0 | AM9: 0 | AN9: 0 | AO9: 1 | AP9: 0 | AQ9: 0 | AR9: 0 | AS9: 0 | AT9: 1 | AU9: 1 | AV9: 0 | AW9: 0 | AX9: 0 | AY9: 0 | AZ9: 0 | BA9: 0 | BB9: 0 | BC9: 0 | BD9: 0 | BE9: 0 | BF9: 0 | BG9: 0 | BH9: 0 | BI9: 1 | BJ9: 0 | BK9: 0 | BL9: 0 | BM9: 0 | BN9: 0 | BO9: 0 | BP9: 0 | BQ9: 0 | BR9: 0 | BS9: 0
A10: 9 | B10: 0 | C10: =SUM($B$2:$B10) -> 15 | D10: 1 | E10: 0 | F10: 0 | G10: 0 | H10: 0 | I10: 0 | J10: 0 | K10: 0 | L10: 0 | M10: 0 | N10: 0 | O10: 0 | P10: 0 | Q10: 0 | R10: 0 | S10: 0 | T10: 0 | U10: 0 | V10: 0 | W10: 0 | X10: 0 | Y10: 0 | Z10: 0 | AA10: 0 | AB10: 0 | AC10: 0 | AD10: 0 | AE10: 0 | AF10: 0 | AG10: 0 | AH10: 0 | AI10: 0 | AJ10: 0 | AK10: 0 | AL10: 0 | AM10: 0 | AN10: 0 | AO10: 0 | AP10: 0 | AQ10: 0 | AR10: 0 | AS10: 0 | AT10: 0 | AU10: 1 | AV10: 0 | AW10: 0 | AX10: 0 | AY10: 0 | AZ10: 0 | BA10: 0 | BB10: 0 | BC10: 0 | BD10: 0 | BE10: 0 | BF10: 0 | BG10: 0 | BH10: 0 | BI10: 0 | BJ10: 0 | BK10: 0 | BL10: 0 | BM10: 0 | BN10: 0 | BO10: 0 | BP10: 0 | BQ10: 0 | BR10: 0 | BS10: 0
A11: 10 | B11: 0 | C11: =SUM($B$2:$B11) -> 15 | D11: 2 | E11: 0 | F11: 0 | G11: 0 | H11: 0 | I11: 0 | J11: 0 | K11: 0 | L11: 0 | M11: 0 | N11: 0 | O11: 0 | P11: 0 | Q11: 0 | R11: 0 | S11: 0 | T11: 0 | U11: 0 | V11: 0 | W11: 1 | X11: 0 | Y11: 0 | Z11: 0 | AA11: 0 | AB11: 0 | AC11: 0 | AD11: 0 | AE11: 0 | AF11: 0 | AG11: 0 | AH11: 0 | AI11: 0 | AJ11: 0 | AK11: 0 | AL11: 0 | AM11: 0 | AN11: 0 | AO11: 0 | AP11: 0 | AQ11: 0 | AR11: 0 | AS11: 0 | AT11: 0 | AU11: 1 | AV11: 0 | AW11: 0 | AX11: 0 | AY11: 0 | AZ11: 0 | BA11: 0 | BB11: 0 | BC11: 0 | BD11: 0 | BE11: 0 | BF11: 0 | BG11: 0 | BH11: 0 | BI11: 0 | BJ11: 0 | BK11: 0 | BL11: 0 | BM11: 0 | BN11: 0 | BO11: 0 | BP11: 0 | BQ11: 0 | BR11: 0 | BS11: 0
A12: 11 | B12: 0 | C12: =SUM($B$2:$B12) -> 15 | D12: 1 | E12: 0 | F12: 0 | G12: 0 | H12: 0 | I12: 0 | J12: 0 | K12: 0 | L12: 0 | M12: 0 | N12: 0 | O12: 0 | P12: 0 | Q12: 0 | R12: 0 | S12: 0 | T12: 0 | U12: 0 | V12: 0 | W12: 0 | X12: 1 | Y12: 0 | Z12: 0 | AA12: 0 | AB12: 0 | AC12: 0 | AD12: 0 | AE12: 0 | AF12: 0 | AG12: 0 | AH12: 0 | AI12: 0 | AJ12: 0 | AK12: 0 | AL12: 0 | AM12: 0 | AN12: 0 | AO12: 0 | AP12: 0 | AQ12: 0 | AR12: 0 | AS12: 0 | AT12: 0 | AU12: 0 | AV12: 0 | AW12: 0 | AX12: 0 | AY12: 0 | AZ12: 0 | BA12: 0 | BB12: 0 | BC12: 0 | BD12: 0 | BE12: 0 | BF12: 0 | BG12: 0 | BH12: 0 | BI12: 0 | BJ12: 0 | BK12: 0 | BL12: 0 | BM12: 0 | BN12: 0 | BO12: 0 | BP12: 0 | BQ12: 0 | BR12: 0 | BS12: 0
A13: 12 | B13: 1 | C13: =SUM($B$2:$B13) -> 16 | D13: 4 | E13: 0 | F13: 0 | G13: 0 | H13: 0 | I13: 0 | J13: 0 | K13: 0 | L13: 0 | M13: 0 | N13: 0 | O13: 0 | P13: 0 | Q13: 0 | R13: 0 | S13: 0 | T13: 0 | U13: 0 | V13: 0 | W13: 0 | X13: 1 | Y13: 0 | Z13: 0 | AA13: 0 | AB13: 0 | AC13: 0 | AD13: 0 | AE13: 0 | AF13: 0 | AG13: 0 | AH13: 0 | AI13: 0 | AJ13: 0 | AK13: 0 | AL13: 0 | AM13: 0 | AN13: 0 | AO13: 0 | AP13: 0 | AQ13: 0 | AR13: 0 | AS13: 0 | AT13: 1 | AU13: 1 | AV13: 0 | AW13: 0 | AX13: 0 | AY13: 0 | AZ13: 0 | BA13: 0 | BB13: 0 | BC13: 0 | BD13: 0 | BE13: 0 | BF13: 0 | BG13: 0 | BH13: 0 | BI13: 0 | BJ13: 0 | BK13: 1 | BL13: 0 | BM13: 0 | BN13: 0 | BO13: 0 | BP13: 0 | BQ13: 0 | BR13: 0 | BS13: 0
A14: 13 | B14: 1 | C14: =SUM($B$2:$B14) -> 17 | D14: 2 | E14: 0 | F14: 0 | G14: 0 | H14: 0 | I14: 0 | J14: 0 | K14: 0 | L14: 0 | M14: 0 | N14: 0 | O14: 0 | P14: 0 | Q14: 0 | R14: 0 | S14: 0 | T14: 0 | U14: 0 | V14: 0 | W14: 0 | X14: 0 | Y14: 0 | Z14: 0 | AA14: 0 | AB14: 0 | AC14: 0 | AD14: 0 | AE14: 0 | AF14: 0 | AG14: 0 | AH14: 0 | AI14: 0 | AJ14: 0 | AK14: 0 | AL14: 0 | AM14: 0 | AN14: 0 | AO14: 0 | AP14: 0 | AQ14: 0 | AR14: 0 | AS14: 0 | AT14: 0 | AU14: 1 | AV14: 0 | AW14: 0 | AX14: 1 | AY14: 0 | AZ14: 0 | BA14: 0 | BB14: 0 | BC14: 0 | BD14: 0 | BE14: 0 | BF14: 0 | BG14: 0 | BH14: 0 | BI14: 0 | BJ14: 0 | BK14: 0 | BL14: 0 | BM14: 0 | BN14: 0 | BO14: 0 | BP14: 0 | BQ14: 0 | BR14: 0 | BS14: 0
... A288: 287 | B288: 0 | C288: =SUM($B$2:$B288) -> 61 | D288: 1 | E288: 0 | F288: 0 | G288: 0 | H288: 0 | I288: 0 | J288: 0 | K288: 0 | L288: 0 | M288: 0 | N288: 0 | O288: 0 | P288: 0 | Q288: 0 | R288: 0 | S288: 0 | T288: 0 | U288: 0 | V288: 0 | W288: 0 | X288: 0 | Y288: 0 | Z288: 0 | AA288: 0 | AB288: 0 | AC288: 0 | AD288: 0 | AE288: 0 | AF288: 0 | AG288: 0 | AH288: 0 | AI288: 0 | AJ288: 0 | AK288: 0 | AL288: 0 | AM288: 0 | AN288: 0 | AO288: 0 | AP288: 0 | AQ288: 0 | AR288: 0 | AS288: 0 | AT288: 0 | AU288: 0 | AV288: 0 | AW288: 0 | AX288: 1 | AY288: 0 | AZ288: 0 | BA288: 0 | BB288: 0 | BC288: 0 | BD288: 0 | BE288: 0 | BF288: 0 | BG288: 0 | BH288: 0 | BI288: 0 | BJ288: 0 | BK288: 0 | BL288: 0 | BM288: 0 | BN288: 0 | BO288: 0 | BP288: 0 | BQ288: 0 | BR288: 0 | BS288: 0
