Workbook

Sheet README
A1: Sheet | B1: Description
A2: MockData | B2: What we need our data to eventually look like
A3: VLOOKUP_SPP | B3: the Vlookup Table. Lists all possible species from the picture data, what is actually feasible, and what taxa to change them into. If the taxa is likely impossible for this state, but there was a taxa of the same next level up of taxonomy, it was renamed to a higher level (example: Bombus vosenisski is not in Wisconsin but many Bombus genera were found, so it would be renamed to Bombus). If taxa is likely impossible for this state, and there were no related taxa found, it was left blank (example: Unicornus unicornus, not possible in WI and a similar species not found, left blank)
A4: d_barchart_pics | B4: Copied from the aggregated dataframe d_barchart_pics generated in JO_EB_picdata.R
A5: Order_table | B5: Final table of spp richness and percentage by order. Created this by taking the columns from d_barchart_pics, filtering them by month, and then removing duplicates to count the unique number of taxa in each month and order

Sheet MockData
A1: TaxaGroup Month Percent
A2: 1 Hymenoptera July 1
A3: 2 Hymenoptera Aug 2
A4: 3 Hymenoptera Sept 3
A5: 4 Hymenoptera Oct 4
A6: 5 Diptera July 5
A7: 6 Diptera Aug 6
A8: 7 Diptera Sept 7
A9: 8 Diptera Oct 8
A10: 9 Lepidoptera July 9
A11: 10 Lepidoptera Aug 10
A12: 11 Lepidoptera Sept 11
A13: 12 Lepidoptera Oct 12

Sheet VLOOKUP_spp
A1: TaxaName | B1: days | C1: Feasible in WI? | D1: NewTaxaName | E1: Order | F1: Notes
B2: 1 | C2: No
A3: Agapostemon | B3: 1 | C3: Yes | D3: Agapostemon | E3: Hymenoptera
A4: Agapostemon_splendens | B4: 1 | C4: Yes | D4: Agapostemon_splendens | E4: Hymenoptera
A5: Andrena | B5: 3 | C5: Yes | D5: Andrena | E5: Hymenoptera
A6: Andrena_cineraria | B6: 1 | C6: No | D6: Andrena | E6: Hymenoptera | F6: Not native to USA
A7: Andrena_fulva | B7: 1 | C7: No | D7: Andrena | E7: Hymenoptera | F7: Not native to USA
A8: Andrena_milwaukeensis | B8: 3 | C8: Yes | D8: Andrena_milwaukeensis | E8: Hymenoptera
A9: Andrena_prunorum | B9: 1 | C9: Yes | D9: Andrena_prunorum | E9: Hymenoptera
A10: Andrena_ventralis | B10: 1 | C10: No | D10: Andrena | E10: Hymenoptera
A11: Anthidium | B11: 1 | C11: Yes | D11: Anthidium | E11: Hymenoptera | F11: Not native to USA but has expanded to around the world
A12: Anthidium_florentinum | B12: 1 | C12: No | D12: Anthidium | E12: Hymenoptera | F12: Not native to USA, introduced but found so far in Canadian area
A13: Anthidium_oblongatum | B13: 1 | C13: Yes | D13: Anthidium_oblongatum | E13: Hymenoptera | F13: Not native to USA but expanded to N. America
A14: Anthophora_abrupta | B14: 4 | C14: Yes | D14: Anthophora_abrupta | E14: Hymenoptera | F14: Not native to USA but introduced to N. America
A15: Anthophora_furcata | B15: 1 | C15: No | D15: Anthophora | E15: Hymenoptera | F15: Not native to USA and not known to be here
A16: Anthophora_plumipes | B16: 1 | C16: Yes | D16: Anthophora_plumipes | E16: Hymenoptera | F16: Not native to USA but introduced to N. America
A17: Apis_dorsata | B17: 6 | C17: No | D17: Apis_mellifera | E17: Hymenoptera | F17: Not native to USA and not known to be here
A18: Apis_florea | B18: 2 | C18: No | D18: Apis_mellifera | E18: Hymenoptera | F18: Not native to USA and not known to be here
A19: Apis_mellifera | B19: 63 | C19: Yes | D19: Apis_mellifera | E19: Hymenoptera
A20: Augochlora | B20: 15 | C20: Yes | D20: Augochlora | E20: Hymenoptera
A21: Augochlorella | B21: 9 | C21: Yes | D21: Augochlorella | E21: Hymenoptera
A22: Augochloropsis | B22: 11 | C22: Yes | D22: Augochloropsis | E22: Hymenoptera
A23: Bombus_affinis | B23: 16 | C23: Yes | D23: Bombus_affinis | E23: Hymenoptera
A24: Bombus_ardens | B24: 2 | C24: No | D24: Bombus | E24: Hymenoptera | F24: Not WI spp
A25: Bombus_bimaculatus | B25: 20 | C25: Yes | D25: Bombus_bimaculatus | E25: Hymenoptera
A26: Bombus_citrinus | B26: 11 | C26: Yes | D26: Bombus_citrinus | E26: Hymenoptera
A27: Bombus_consobrinus | B27: 1 | C27: No | D27: Bombus | E27: Hymenoptera | F27: Not WI spp
A28: Bombus_crotchii | B28: 2 | C28: No | D28: Bombus | E28: Hymenoptera | F28: Not WI spp
A29: Bombus_diversus | B29: 1 | C29: No | D29: Bombus | E29: Hymenoptera | F29: Not WI spp
A30: Bombus_ephippiatus | B30: 1 | C30: No | D30: Bombus | E30: Hymenoptera | F30: Not WI spp
A31: Bombus_flavidus | B31: 2 | C31: Yes | D31: Bombus_flavidus | E31: Hymenoptera
A32: Bombus_funebris | B32: 1 | C32: No | D32: Bombus | E32: Hymenoptera | F32: Not WI spp
A33: Bombus_griseocollis | B33: 12 | C33: Yes | D33: Bombus_griseocollis | E33: Hymenoptera
A34: Bombus_hypocrita | B34: 1 | C34: No | D34: Bombus | E34: Hymenoptera | F34: Not WI spp
A35: Bombus_impatiens | B35: 41 | C35: Yes | D35: Bombus_impatiens | E35: Hymenoptera
A36: Bombus_melanopygus | B36: 2 | C36: No | D36: Bombus | E36: Hymenoptera | F36: Not a WI spp
A37: Bombus_mixtus | B37: 2 | C37: No | D37: Bombus | E37: Hymenoptera | F37: Not a WI spp
A38: Bombus_occidentalis | B38: 1 | C38: No | D38: Bombus | E38: Hymenoptera | F38: Not a WI spp
A39: Bombus_pauloensis | B39: 2 | C39: No | D39: Bombus | E39: Hymenoptera | F39: Not a WI spp
A40: Bombus_pensylvanicus | B40: 2 | C40: Yes | D40: Bombus_pensylvanicus | E40: Hymenoptera
...

Sheet d_barchart_pics
B1: Date | C1: species1 | D1: Trademark.Cultivar | E1: det_num | F1: NewTaxaName | G1: Order | H1: Month | I1: Richness
A2: 1 | B2: 43657 | C2: Augochlora | D2: Dharuma | E2: 1 | F2: =VLOOKUP($C2,VLOOKUP_spp!$A$2:$D$103,4,1) -> Augochlora | G2: =VLOOKUP($F2,VLOOKUP_spp!$A$2:$E$102,5,1) -> Hymenoptera | H2: =TEXT(B2, "mmm") -> Jul | I2: 1
A3: 2 | B3: 43657 | C3: Coleoptera | D3: Dharuma | E3: 4 | F3: =VLOOKUP($C3,VLOOKUP_spp!$A$2:$D$103,4,1) -> Coleoptera | G3: =VLOOKUP($F3,VLOOKUP_spp!$A$2:$E$102,5,1) -> Coleoptera | H3: =TEXT(B3, "mmm") -> Jul | I3: 1
A4: 3 | B4: 43657 | C4: Hylaeus | D4: Dharuma | E4: 1 | F4: =VLOOKUP($C4,VLOOKUP_spp!$A$2:$D$103,4,1) -> Hylaeus | G4: =VLOOKUP($F4,VLOOKUP_spp!$A$2:$E$102,5,1) -> Hymenoptera | H4: =TEXT(B4, "mmm") -> Jul | I4: 1
A5: 4 | B5: 43657 | C5: Lasioglossum | D5: Dharuma | E5: 1 | F5: =VLOOKUP($C5,VLOOKUP_spp!$A$2:$D$103,4,1) -> Lasioglossum | G5: =VLOOKUP($F5,VLOOKUP_spp!$A$2:$E$102,5,1) -> Hymenoptera | H5: =TEXT(B5, "mmm") -> Jul | I5: 1
A6: 5 | B6: 43657 | C6: Perdita | D6: Dharuma | E6: 1 | F6: =VLOOKUP($C6,VLOOKUP_spp!$A$2:$D$103,4,1) -> Perdita | G6: =VLOOKUP($F6,VLOOKUP_spp!$A$2:$E$102,5,1) -> Hymenoptera | H6: =TEXT(B6, "mmm") -> Jul | I6: 1
A7: 6 | B7: 43658 | C7: Apis_mellifera | D7: Dharuma | E7: 5 | F7: =VLOOKUP($C7,VLOOKUP_spp!$A$2:$D$103,4,1) -> Apis_mellifera | G7: =VLOOKUP($F7,VLOOKUP_spp!$A$2:$E$102,5,1) -> Hymenoptera | H7: =TEXT(B7, "mmm") -> Jul | I7: 1
A8: 7 | B8: 43658 | C8: Chelostoma | D8: Dharuma | E8: 1 | F8: =VLOOKUP($C8,VLOOKUP_spp!$A$2:$D$103,4,1) -> Chelostoma | G8: =VLOOKUP($F8,VLOOKUP_spp!$A$2:$E$102,5,1) -> Hymenoptera | H8: =TEXT(B8, "mmm") -> Jul | I8: 1
A9: 8 | B9: 43658 | C9: Coleoptera | D9: Dharuma | E9: 2 | F9: =VLOOKUP($C9,VLOOKUP_spp!$A$2:$D$103,4,1) -> Coleoptera | G9: =VLOOKUP($F9,VLOOKUP_spp!$A$2:$E$102,5,1) -> Coleoptera | H9: =TEXT(B9, "mmm") -> Jul | I9: 1
A10: 9 | B10: 43658 | C10: Coleoptera | D10: Quick Fire | E10: 2 | F10: =VLOOKUP($C10,VLOOKUP_spp!$A$2:$D$103,4,1) -> Coleoptera | G10: =VLOOKUP($F10,VLOOKUP_spp!$A$2:$E$102,5,1) -> Coleoptera | H10: =TEXT(B10, "mmm") -> Jul | I10: 1
A11: 10 | B11: 43658 | C11: Halictus_rubicundus | D11: Dharuma | E11: 1 | F11: =VLOOKUP($C11,VLOOKUP_spp!$A$2:$D$103,4,1) -> Halictus_rubicundus | G11: =VLOOKUP($F11,VLOOKUP_spp!$A$2:$E$102,5,1) -> Hymenoptera | H11: =TEXT(B11, "mmm") -> Jul | I11: 1
A12: 11 | B12: 43658 | C12: Halictus_tripartitus | D12: Dharuma | E12: 2 | F12: =VLOOKUP($C12,VLOOKUP_spp!$A$2:$D$103,4,1) -> Halictus_tripartitus | G12: =VLOOKUP($F12,VLOOKUP_spp!$A$2:$E$102,5,1) -> Hymenoptera | H12: =TEXT(B12, "mmm") -> Jul | I12: 1
A13: 12 | B13: 43658 | C13: Meliponini | D13: Dharuma | E13: 2 | F13: =VLOOKUP($C13,VLOOKUP_spp!$A$2:$D$103,4,1) -> 0 | G13: =VLOOKUP($F13,VLOOKUP_spp!$A$2:$E$102,5,1) -> #N/A | H13: =TEXT(B13, "mmm") -> Jul | I13: 1
... A1524: 1523 | B1524: 44427 | C1524: Wasp | D1524: Pinky Winky | E1524: 3 | F1524: =VLOOKUP($C1524,VLOOKUP_spp!$A$2:$D$103,4,1) -> Wasp | G1524: =VLOOKUP($F1524,VLOOKUP_spp!$A$2:$E$102,5,1) -> Hymenoptera | H1524: =TEXT(B1524, "mmm") -> Aug | I1524: 1

Sheet Order_table
A1: Taxa group | B1: Month | C1: Richness | D1: Total Richness | E1: Percent | G1: Notes
A2: Coleoptera | B2: July | C2: 1 | D2: 61 | E2: =C2/D2 -> 0.016393443 | G2: Problem: We have very similar percentages for each month, so I don't know if we're really learning much, and since the other ordres were only collected by order level their richness looks artificially low. Let's try this again by taxa.
A3: Diptera | B3: July | C3: 2 | D3: 61 | E3: =C3/D3 -> 0.032786885
A4: Hymenoptera | B4: July | C4: 34 | D4: 61 | E4: =C4/D4 -> 0.55737705
A5: Lepidoptera | B5: July | C5: 1 | D5: 61 | E5: =C5/D5 -> 0.016393443 | G5: Hymenoptera Taxa Richness by Month
A6: Coleoptera | B6: Aug | C6: 1 | D6: 61 | E6: =C6/D6 -> 0.016393443 | G6: July | H6: 34
A7: Diptera | B7: Aug | C7: 2 | D7: 61 | E7: =C7/D7 -> 0.032786885 | G7: August | H7: 35
A8: Hymenoptera | B8: Aug | C8: 35 | D8: 61 | E8: =C8/D8 -> 0.57377049 | G8: September | H8: 36
A9: Lepidoptera | B9: Aug | C9: 1 | D9: 61 | E9: =C9/D9 -> 0.016393443 | G9: October | H9: 26
A10: Coleoptera | B10: Sept | C10: 1 | D10: 61 | E10: =C10/D10 -> 0.016393443
A11: Diptera | B11: Sept | C11: 2 | D11: 61 | E11: =C11/D11 -> 0.032786885
A12: Hymenoptera | B12: Sept | C12: 36 | D12: 61 | E12: =C12/D12 -> 0.59016393
A13: Lepidoptera | B13: Sept | C13: 1 | D13: 61 | E13: =C13/D13 -> 0.016393443
A14: Coleoptera | B14: Oct | C14: 1 | D14: 61 | E14: =C14/D14 -> 0.016393443
A15: Diptera | B15: Oct | C15: 1 | D15: 61 | E15: =C15/D15 -> 0.016393443
A16: Hymenoptera | B16: Oct | C16: 26 | D16: 61 | E16: =C16/D16 -> 0.42622951
A17: Lepidoptera | B17: Oct | C17: 1 | D17: 61 | E17: =C17/D17 -> 0.016393443

Sheet Taxa_table
A1: Taxa group | B1: Month | C1: Richness | D1: Total Richness | E1: Percent
A2: Apis (family: Apidae) | B2: July | C2: Hmm, no same problem with richness, taxa table doesn't work
A3: Bombus (family: Apidae) | B3: July
A4: Wasp | B4: July
A5: Other Apidae | B5: July
A6: Megachilidae | B6: July
A7: Halictidae | B7: July
A8: Andrenidae | B8: July
A9: Colletidae | B9: July
A10: Melittidae | B10: July
A11: Stenotritidae | B11: July
A13: Apis (family: Apidae) | B13: Aug
A14: Bombus (family: Apidae) | B14: Aug
A15: Wasp | B15: Aug
... A44: Stenotritidae | B44: Oct

Sheet Filtered
A1: NewTaxaName | B1: Order | C1: Month | D1: Richness
A2: Coleoptera | B2: Coleoptera | C2: Aug | D2: 1
A3: Coleoptera | B3: Coleoptera | C3: Aug | D3: 1
A4: Coleoptera | B4: Coleoptera | C4: Aug | D4: 1
A5: Coleoptera | B5: Coleoptera | C5: Aug | D5: 1
A6: Coleoptera | B6: Coleoptera | C6: Aug | D6: 1
A7: Coleoptera | B7: Coleoptera | C7: Aug | D7: 1
A8: Coleoptera | B8: Coleoptera | C8: Aug | D8: 1
A9: Coleoptera | B9: Coleoptera | C9: Aug | D9: 1
A10: Coleoptera | B10: Coleoptera | C10: Aug | D10: 1
A11: Coleoptera | B11: Coleoptera | C11: Aug | D11: 1
A12: Coleoptera | B12: Coleoptera | C12: Aug | D12: 1
A13: Coleoptera | B13: Coleoptera | C13: Aug | D13: 1
... A549: Lepidoptera | B549: Lepidoptera | C549: Aug | D549: 1
A550: 0 | B550: #N/A | C550: Aug | D550: 1
A551: 0 | B551: #N/A | C551: Aug | D551: 1
A552: 0 | B552: #N/A | C552: Aug | D552: 1
A553: 0 | B553: #N/A | C553: Aug | D553: 1
A554: 0 | B554: #N/A | C554: Aug | D554: 1
A555: 0 | B555: #N/A | C555: Aug | D555: 1
A556: 0 | B556: #N/A | C556: Aug | D556: 1
A557: 0 | B557: #N/A | C557: Aug | D557: 1
A558: 0 | B558: #N/A | C558: Aug | D558: 1
A559: Coleoptera | B559: Coleoptera | C559: Jul | D559: 1
A560: Coleoptera | B560: Coleoptera | C560: Jul | D560: 1
A561: Coleoptera | B561: Coleoptera | C561: Jul | D561: 1
A562: Coleoptera | B562: Coleoptera | C562: Jul | D562: 1
A563: Coleoptera | B563: Coleoptera | C563: Jul | D563: 1
A564: Coleoptera | B564: Coleoptera | C564: Jul | D564: 1
A565: Coleoptera | B565: Coleoptera | C565: Jul | D565: 1
A566: Coleoptera | B566: Coleoptera | C566: Jul | D566: 1
A567: Coleoptera | B567: Coleoptera | C567: Jul | D567: 1
A568: Coleoptera | B568: Coleoptera | C568: Jul | D568: 1
A569: Coleoptera | B569: Coleoptera | C569: Jul | D569: 1
A570: Coleoptera | B570: Coleoptera | C570: Jul | D570: 1
... A792: Lepidoptera | B792: Lepidoptera | C792: Jul | D792: 1
A793: 0 | B793: #N/A | C793: Jul | D793: 1
A794: 0 | B794: #N/A | C794: Jul | D794: 1
A795: 0 | B795: #N/A | C795: Jul | D795: 1
A796: 0 | B796: #N/A | C796: Jul | D796: 1
...

Sheet Temp
A1: NewTaxaName
A2: Apis_mellifera
A3: Augochlora
A4: Augochlorella
A5: Augochloropsis
A6: Bombus_impatiens
A7: Halictus_rubicundus
A8: Halictus_tripartitus
A9: Hylaeus
A10: Lasioglossum
A11: Sphecodes
A12: Wasp
... A26: Pseudopanurgus
