Workbook

Sheet Sheet1
B1: Trademark.Cultivar | C1: Month | D1: DaysinMonth | E1: DaysRecordedInsectsPresent | F1: DaysRecordedBlooming | G1: FirstDay20197.17.2019 | H1: LastDay2019 | I1: DaysPossible2019 | J1: FirstDay2020 | K1: LastDay2020 | L1: DaysPossible2020 | M1: FirstDay2021 | N1: LastDay2021(only surveyed til8/19/2021) | O1: DaysPossible2021 | P1: Color | Q1: Flower type | R1: Notes
A2: 1 | B2: Baby Lace | C2: August | D2: =VLOOKUP($C2,Sheet2!$A$2:$B$5,2,0) -> 31 | E2: 4 | F2: =I2+L2+O2 -> 14 | I2: =_xlfn.DAYS(H2,G2) -> 0 | J2: 44069 | K2: 44074 | L2: =_xlfn.DAYS(K2,J2) -> 5 | M2: 44418 | N2: 44427 | O2: =_xlfn.DAYS(N2,M2) -> 9 | P2: White | Q2: Lacy panicle
A3: 2 | B3: Baby Lace | C3: September | D3: =VLOOKUP($C3,Sheet2!$A$2:$B$5,2,0) -> 30 | E3: 8 | F3: =I3+L3+O3 -> 35 | G3: 43727 | H3: 43738 | I3: =_xlfn.DAYS(H3,G3) -> 11 | J3: 44075 | K3: 44099 | L3: =_xlfn.DAYS(K3,J3) -> 24 | O3: =_xlfn.DAYS(N3,M3) -> 0 | P3: White | Q3: Lacy panicle
A4: 3 | B4: Baby Lace | C4: October | D4: =VLOOKUP($C4,Sheet2!$A$2:$B$5,2,0) -> 30 | E4: 1 | F4: =I4+L4+O4 -> 18 | G4: 43739 | H4: 43757 | I4: =_xlfn.DAYS(H4,G4) -> 18 | L4: =_xlfn.DAYS(K4,J4) -> 0 | O4: =_xlfn.DAYS(N4,M4) -> 0 | P4: White | Q4: Lacy panicle
A5: 4 | B5: Big Ben | C5: August | D5: =VLOOKUP($C5,Sheet2!$A$2:$B$5,2,0) -> 31 | E5: 1 | F5: =I5+L5+O5 -> 3 | I5: =_xlfn.DAYS(H5,G5) -> 0 | J5: 44071 | K5: 44074 | L5: =_xlfn.DAYS(K5,J5) -> 3 | O5: =_xlfn.DAYS(N5,M5) -> 0 | P5: White | Q5: Lacy panicle
A6: 5 | B6: Big Ben | C6: September | D6: =VLOOKUP($C6,Sheet2!$A$2:$B$5,2,0) -> 30 | E6: 12 | F6: =I6+L6+O6 -> 54 | G6: 43713 | H6: 43738 | I6: =_xlfn.DAYS(H6,G6) -> 25 | J6: 44075 | K6: 44104 | L6: =_xlfn.DAYS(K6,J6) -> 29 | O6: =_xlfn.DAYS(N6,M6) -> 0 | P6: White | Q6: Lacy panicle
A7: 6 | B7: Big Ben | C7: October | D7: =VLOOKUP($C7,Sheet2!$A$2:$B$5,2,0) -> 30 | E7: 7 | F7: =I7+L7+O7 -> 33 | G7: 43739 | H7: 43757 | I7: =_xlfn.DAYS(H7,G7) -> 18 | J7: 44105 | K7: 44120 | L7: =_xlfn.DAYS(K7,J7) -> 15 | O7: =_xlfn.DAYS(N7,M7) -> 0 | P7: White | Q7: Lacy panicle
A8: 7 | B8: Brussels Lace | C8: August | D8: =VLOOKUP($C8,Sheet2!$A$2:$B$5,2,0) -> 31 | E8: 11 | F8: =I8+L8+O8 -> 34 | G8: 43700 | H8: 43708 | I8: =_xlfn.DAYS(H8,G8) -> 8 | J8: 44062 | K8: 44074 | L8: =_xlfn.DAYS(K8,J8) -> 12 | M8: 44413 | N8: 44427 | O8: =_xlfn.DAYS(N8,M8) -> 14 | P8: White | Q8: Lacy panicle
A9: 8 | B9: Brussels Lace | C9: September | D9: =VLOOKUP($C9,Sheet2!$A$2:$B$5,2,0) -> 30 | E9: 6 | F9: =I9+L9+O9 -> 58 | G9: 43709 | H9: 43738 | I9: =_xlfn.DAYS(H9,G9) -> 29 | J9: 44075 | K9: 44104 | L9: =_xlfn.DAYS(K9,J9) -> 29 | O9: =_xlfn.DAYS(N9,M9) -> 0 | P9: White | Q9: Lacy panicle
A10: 9 | B10: Brussels Lace | C10: October | D10: =VLOOKUP($C10,Sheet2!$A$2:$B$5,2,0) -> 30 | E10: 2 | F10: =I10+L10+O10 -> 18 | G10: 43739 | H10: 43757 | I10: =_xlfn.DAYS(H10,G10) -> 18 | L10: =_xlfn.DAYS(K10,J10) -> 0 | O10: =_xlfn.DAYS(N10,M10) -> 0 | P10: White | Q10: Lacy panicle
A11: 10 | B11: Daimond Rogue | C11: July | D11: =VLOOKUP($C11,Sheet2!$A$2:$B$5,2,0) -> 31 | E11: 4 | F11: =I11+L11+O11 -> 35 | G11: 43663 | H11: 43677 | I11: =_xlfn.DAYS(H11,G11) -> 14 | J11: 44022 | K11: 44043 | L11: =_xlfn.DAYS(K11,J11) -> 21 | O11: =_xlfn.DAYS(N11,M11) -> 0 | P11: Pink-white | Q11: Mop-like panicle
A12: 11 | B12: Daimond Rogue | C12: August | D12: =VLOOKUP($C12,Sheet2!$A$2:$B$5,2,0) -> 31 | E12: 2 | F12: =I12+L12+O12 -> 50 | G12: 43678 | H12: 43708 | I12: =_xlfn.DAYS(H12,G12) -> 30 | J12: 44044 | K12: 44064 | L12: =_xlfn.DAYS(K12,J12) -> 20 | O12: =_xlfn.DAYS(N12,M12) -> 0 | P12: Pink-white | Q12: Mop-like panicle
B13: Daimond Rogue | C13: September | D13: =VLOOKUP($C13,Sheet2!$A$2:$B$5,2,0) -> 30 | E13: 0 | F13: =I13+L13+O13 -> 87 | G13: 43709 | H13: 43738 | I13: =_xlfn.DAYS(H13,G13) -> 29 | J13: 44075 | K13: 44104 | L13: =_xlfn.DAYS(K13,J13) -> 29 | M13: 44440 | N13: 44469 | O13: =_xlfn.DAYS(N13,M13) -> 29
A14: 12 | B14: Daimond Rogue | C14: October | D14: =VLOOKUP($C14,Sheet2!$A$2:$B$5,2,0) -> 30 | E14: 1 | F14: =I14+L14+O14 -> 14 | G14: 43739 | H14: 43753 | I14: =_xlfn.DAYS(H14,G14) -> 14 | L14: =_xlfn.DAYS(K14,J14) -> 0 | O14: =_xlfn.DAYS(N14,M14) -> 0 | P14: Pink-white | Q14: Mop-like panicle
A15: 13 | B15: Dharuma | C15: July | D15: =VLOOKUP($C15,Sheet2!$A$2:$B$5,2,0) -> 31 | E15: 11 | F15: =I15+L15+O15 -> 44 | G15: 43657 | H15: 43677 | I15: =_xlfn.DAYS(H15,G15) -> 20 | J15: 44022 | K15: 44039 | L15: =_xlfn.DAYS(K15,J15) -> 17 | M15: 44386 | N15: 44393 | O15: =_xlfn.DAYS(N15,M15) -> 7 | P15: White | Q15: Lacy panicle
A16: 14 | B16: Dharuma | C16: August | D16: =VLOOKUP($C16,Sheet2!$A$2:$B$5,2,0) -> 31 | E16: 1 | F16: =I16+L16+O16 -> 19 | G16: 43678 | H16: 43697 | I16: =_xlfn.DAYS(H16,G16) -> 19 | L16: =_xlfn.DAYS(K16,J16) -> 0 | O16: =_xlfn.DAYS(N16,M16) -> 0 | P16: White | Q16: Lacy panicle
A17: 15 | B17: Dolly | C17: July | D17: =VLOOKUP($C17,Sheet2!$A$2:$B$5,2,0) -> 31 | E17: 1 | F17: =I17+L17+O17 -> 15 | I17: =_xlfn.DAYS(H17,G17) -> 0 | L17: =_xlfn.DAYS(K17,J17) -> 0 | M17: 44393 | N17: 44408 | O17: =_xlfn.DAYS(N17,M17) -> 15 | P17: White | Q17: Lacy panicle
A18: 16 | B18: Dolly | C18: August | D18: =VLOOKUP($C18,Sheet2!$A$2:$B$5,2,0) -> 31 | E18: 3 | F18: =I18+L18+O18 -> 13 | G18: 43679 | H18: 43680 | I18: =_xlfn.DAYS(H18,G18) -> 1 | J18: 44071 | K18: 44074 | L18: =_xlfn.DAYS(K18,J18) -> 3 | M18: 44409 | N18: 44418 | O18: =_xlfn.DAYS(N18,M18) -> 9 | P18: White | Q18: Lacy panicle
A19: 17 | B19: Dolly | C19: September | D19: =VLOOKUP($C19,Sheet2!$A$2:$B$5,2,0) -> 30 | E19: 2 | F19: =I19+L19+O19 -> 28 | I19: =_xlfn.DAYS(H19,G19) -> 0 | J19: 44075 | K19: 44097 | L19: =_xlfn.DAYS(K19,J19) -> 22 | M19: 44386 | N19: 44392 | O19: =_xlfn.DAYS(N19,M19) -> 6 | P19: White | Q19: Lacy panicle
A20: 18 | B20: Fire & Ice | C20: July | D20: =VLOOKUP($C20,Sheet2!$A$2:$B$5,2,0) -> 31 | E20: 6 | F20: =I20+L20+O20 -> 19 | G20: 43665 | H20: 43677 | I20: =_xlfn.DAYS(H20,G20) -> 12 | J20: 44032 | K20: 44039 | L20: =_xlfn.DAYS(K20,J20) -> 7 | O20: =_xlfn.DAYS(N20,M20) -> 0 | P20: Pink-white | Q20: Lacy panicle
A21: 19 | B21: Fire & Ice | C21: August | D21: =VLOOKUP($C21,Sheet2!$A$2:$B$5,2,0) -> 31 | E21: 2 | F21: =I21+L21+O21 -> 6 | G21: 43678 | H21: 43684 | I21: =_xlfn.DAYS(H21,G21) -> 6 | L21: =_xlfn.DAYS(K21,J21) -> 0 | O21: =_xlfn.DAYS(N21,M21) -> 0 | P21: Pink-white | Q21: Lacy panicle
A22: 20 | B22: Fire Light | C22: August | D22: =VLOOKUP($C22,Sheet2!$A$2:$B$5,2,0) -> 31 | E22: 1 | F22: =I22+L22+O22 -> 8 | G22: 43700 | H22: 43708 | I22: =_xlfn.DAYS(H22,G22) -> 8 | L22: =_xlfn.DAYS(K22,J22) -> 0 | O22: =_xlfn.DAYS(N22,M22) -> 0 | P22: Pink | Q22: Mop-like panicle
A23: 21 | B23: Fire Light | C23: September | D23: =VLOOKUP($C23,Sheet2!$A$2:$B$5,2,0) -> 30 | E23: 2 | F23: =I23+L23+O23 -> 32 | G23: 43709 | H23: 43738 | I23: =_xlfn.DAYS(H23,G23) -> 29 | J23: 44095 | K23: 44097 | L23: =_xlfn.DAYS(K23,J23) -> 2 | M23: 44413 | N23: 44414 | O23: =_xlfn.DAYS(N23,M23) -> 1 | P23: Pink | Q23: Mop-like panicle
A24: 22 | B24: Fire Light | C24: October | D24: =VLOOKUP($C24,Sheet2!$A$2:$B$5,2,0) -> 30 | E24: 1 | F24: =I24+L24+O24 -> 9 | G24: 43739 | H24: 43748 | I24: =_xlfn.DAYS(H24,G24) -> 9 | L24: =_xlfn.DAYS(K24,J24) -> 0 | O24: =_xlfn.DAYS(N24,M24) -> 0 | P24: Pink | Q24: Mop-like panicle
A25: 23 | B25: Floribunda | C25: August | D25: =VLOOKUP($C25,Sheet2!$A$2:$B$5,2,0) -> 31 | E25: 8 | F25: =I25+L25+O25 -> 27 | G25: 43700 | H25: 43708 | I25: =_xlfn.DAYS(H25,G25) -> 8 | J25: 44064 | K25: 44074 | L25: =_xlfn.DAYS(K25,J25) -> 10 | M25: 44418 | N25: 44427 | O25: =_xlfn.DAYS(N25,M25) -> 9 | P25: White | Q25: Lacy panicle
A26: 24 | B26: Floribunda | C26: September | D26: =VLOOKUP($C26,Sheet2!$A$2:$B$5,2,0) -> 30 | E26: 8 | F26: =I26+L26+O26 -> 58 | G26: 43709 | H26: 43738 | I26: =_xlfn.DAYS(H26,G26) -> 29 | J26: 44075 | K26: 44104 | L26: =_xlfn.DAYS(K26,J26) -> 29 | O26: =_xlfn.DAYS(N26,M26) -> 0 | P26: White | Q26: Lacy panicle
A27: 25 | B27: Floribunda | C27: October | D27: =VLOOKUP($C27,Sheet2!$A$2:$B$5,2,0) -> 30 | E27: 3 | F27: =I27+L27+O27 -> 35 | G27: 43739 | H27: 43761 | I27: =_xlfn.DAYS(H27,G27) -> 22 | J27: 44105 | K27: 44118 | L27: =_xlfn.DAYS(K27,J27) -> 13 | O27: =_xlfn.DAYS(N27,M27) -> 0 | P27: White | Q27: Lacy panicle
A28: 26 | B28: Great Star | C28: August | D28: =VLOOKUP($C28,Sheet2!$A$2:$B$5,2,0) -> 31 | E28: 3 | F28: =I28+L28+O28 -> 23 | G28: 43705 | H28: 43708 | I28: =_xlfn.DAYS(H28,G28) -> 3 | J28: 44071 | K28: 44074 | L28: =_xlfn.DAYS(K28,J28) -> 3 | M28: 44410 | N28: 44427 | O28: =_xlfn.DAYS(N28,M28) -> 17 | P28: White | Q28: Lacy panicle
A29: 27 | B29: Great Star | C29: September | D29: =VLOOKUP($C29,Sheet2!$A$2:$B$5,2,0) -> 30 | E29: 9 | F29: =I29+L29+O29 -> 58 | G29: 43709 | H29: 43738 | I29: =_xlfn.DAYS(H29,G29) -> 29 | J29: 44075 | K29: 44104 | L29: =_xlfn.DAYS(K29,J29) -> 29 | O29: =_xlfn.DAYS(N29,M29) -> 0 | P29: White | Q29: Lacy panicle
A30: 28 | B30: Great Star | C30: October | D30: =VLOOKUP($C30,Sheet2!$A$2:$B$5,2,0) -> 30 | E30: 5 | F30: =I30+L30+O30 -> 34 | G30: 43739 | H30: 43753 | I30: =_xlfn.DAYS(H30,G30) -> 14 | J30: 44105 | K30: 44125 | L30: =_xlfn.DAYS(K30,J30) -> 20 | O30: =_xlfn.DAYS(N30,M30) -> 0 | P30: White | Q30: Lacy panicle
A31: 29 | B31: Green Spire | C31: August | D31: =VLOOKUP($C31,Sheet2!$A$2:$B$5,2,0) -> 31 | E31: 10 | F31: =I31+L31+O31 -> 24 | I31: =_xlfn.DAYS(H31,G31) -> 0 | J31: 44064 | K31: 44074 | L31: =_xlfn.DAYS(K31,J31) -> 10 | M31: 44413 | N31: 44427 | O31: =_xlfn.DAYS(N31,M31) -> 14 | P31: Green-white | Q31: Lacy panicle
A32: 30 | B32: Green Spire | C32: September | D32: =VLOOKUP($C32,Sheet2!$A$2:$B$5,2,0) -> 30 | E32: 10 | F32: =I32+L32+O32 -> 40 | G32: 43727 | H32: 43738 | I32: =_xlfn.DAYS(H32,G32) -> 11 | J32: 44075 | K32: 44104 | L32: =_xlfn.DAYS(K32,J32) -> 29 | O32: =_xlfn.DAYS(N32,M32) -> 0 | P32: Green-white | Q32: Lacy panicle
A33: 31 | B33: Green Spire | C33: October | D33: =VLOOKUP($C33,Sheet2!$A$2:$B$5,2,0) -> 30 | E33: 3 | F33: =I33+L33+O33 -> 36 | G33: 43739 | H33: 43757 | I33: =_xlfn.DAYS(H33,G33) -> 18 | J33: 44105 | K33: 44123 | L33: =_xlfn.DAYS(K33,J33) -> 18 | O33: =_xlfn.DAYS(N33,M33) -> 0 | P33: Green-white | Q33: Lacy panicle
A34: 32 | B34: Honey Comb | C34: August | D34: =VLOOKUP($C34,Sheet2!$A$2:$B$5,2,0) -> 31 | E34: 12 | F34: =I34+L34+O34 -> 32 | G34: 43696 | H34: 43707 | I34: =_xlfn.DAYS(H34,G34) -> 11 | J34: 44062 | K34: 44074 | L34: =_xlfn.DAYS(K34,J34) -> 12 | M34: 44418 | N34: 44427 | O34: =_xlfn.DAYS(N34,M34) -> 9 | P34: White | Q34: Lacy panicle
A35: 33 | B35: Honey Comb | C35: September | D35: =VLOOKUP($C35,Sheet2!$A$2:$B$5,2,0) -> 30 | E35: 3 | F35: =I35+L35+O35 -> 30 | G35: 43709 | H35: 43738 | I35: =_xlfn.DAYS(H35,G35) -> 29 | J35: 44075 | K35: 44076 | L35: =_xlfn.DAYS(K35,J35) -> 1 | O35: =_xlfn.DAYS(N35,M35) -> 0 | P35: White | Q35: Lacy panicle
A36: 34 | B36: Honey Comb | C36: October | D36: =VLOOKUP($C36,Sheet2!$A$2:$B$5,2,0) -> 30 | E36: 1 | F36: =I36+L36+O36 -> 18 | G36: 43739 | H36: 43757 | I36: =_xlfn.DAYS(H36,G36) -> 18 | L36: =_xlfn.DAYS(K36,J36) -> 0 | O36: =_xlfn.DAYS(N36,M36) -> 0 | P36: White | Q36: Lacy panicle
A37: 35 | B37: Kyushu | C37: August | D37: =VLOOKUP($C37,Sheet2!$A$2:$B$5,2,0) -> 31 | E37: 5 | F37: =I37+L37+O37 -> 13 | I37: =_xlfn.DAYS(H37,G37) -> 0 | J37: 44062 | K37: 44074 | L37: =_xlfn.DAYS(K37,J37) -> 12 | M37: 44413 | N37: 44414 | O37: =_xlfn.DAYS(N37,M37) -> 1 | P37: White | Q37: Lacy panicle
A38: 36 | B38: Kyushu | C38: September | D38: =VLOOKUP($C38,Sheet2!$A$2:$B$5,2,0) -> 30 | E38: 9 | F38: =I38+L38+O38 -> 40 | G38: 43727 | H38: 43738 | I38: =_xlfn.DAYS(H38,G38) -> 11 | J38: 44075 | K38: 44104 | L38: =_xlfn.DAYS(K38,J38) -> 29 | O38: =_xlfn.DAYS(N38,M38) -> 0 | P38: White | Q38: Lacy panicle
A39: 37 | B39: Kyushu | C39: October | D39: =VLOOKUP($C39,Sheet2!$A$2:$B$5,2,0) -> 30 | E39: 5 | F39: =I39+L39+O39 -> 38 | G39: 43739 | H39: 43757 | I39: =_xlfn.DAYS(H39,G39) -> 18 | J39: 44105 | K39: 44125 | L39: =_xlfn.DAYS(K39,J39) -> 20 | O39: =_xlfn.DAYS(N39,M39) -> 0 | P39: White | Q39: Lacy panicle
A40: 39 | B40: Late | C40: July | D40: =VLOOKUP($C40,Sheet2!$A$2:$B$5,2,0) -> 31 | E40: 3 | F40: =I40+L40+O40 -> 21 | I40: =_xlfn.DAYS(H40,G40) -> 0 | J40: 44022 | K40: 44043 | L40: =_xlfn.DAYS(K40,J40) -> 21 | O40: =_xlfn.DAYS(N40,M40) -> 0 | P40: White | Q40: Lacy panicle
...

Sheet Sheet2
A1: Month | B1: DaysInMonth
A2: July | B2: 31
A3: August | B3: 31
A4: September | B4: 30
A5: October | B5: 30
